Workbook

Sheet 使用说明
A1: 产品成本测算报价表 · 使用说明
A3: 怎么用 | B3: 首页【报价汇总】只填：产品信息、成品尺寸与单台净重、每箱件数、是否带散热器、是否带组装结构、是否含整托、物流产品、目的地、每票件数。包装费、装配费与运费全部自动算。黄色底=必填待填，填完后自动变绿。
A4: 包装费 | B4: 首页【报价汇总】分别填写【是否带散热器】与【是否带组装结构】：任一为「是」→大板（EPE上下垫片+四角护角+纸箱+托盘+缠绕膜+打包带）；两项均为「否」→小板（防静电气泡袋+隔板+纸箱+护角+托盘+缠绕膜）。如有组装结构，填写装配节拍(秒/台)和工时费，装配费=节拍÷3600×工时费。单价与系数在《参数》页改。
A5: 运费 | B5: 依据《跨越费率》（源自青岛国创VIP报价表）按 实重/体积重取大→起重→分段单价 计算单票运费，再摊到单件。目的地在首页下拉选择，产品可选次日达/特惠普运。
A6: 物料明细/制费明细 | B6: 沿用原模板，硬件/结构件/辅助材料与加工费、工装分摊在此填写。
A7: 成本与报价 | B7: 总成本=材料+加工+工装+包装+运费+利润；建议报价=总成本/(1-目标毛利率)。毛利率/税率在《参数》页改。
A8: 注意 | B8: 跨越费率为参考价，可在《跨越费率》页直接改；金额默认不含税；包装费按方案清单自动算。
A9: 制费明细：P01~P07工程报价表格式，蓝色单元格按项目填写（元件个数/工序个数/用量/张数/预计订单数），默认预填003小板参考数据；辅料与BOM辅助材料二选一，避免重复计费。
A10: • 商空大功率驱动板套表：物料明细已导入 硬件272/结构件32/散热器1/包装8/辅料16/客供料8 共337行；损耗率留空使金额=用量×单价，与源表精确对账（硬件358.4632/结构416.4798/包装63.7765/辅料37.9431）。
A11: • 加工成本明细：综合口径13项构成→126.4283元/台（含人工82.0882+SMT/机插+折旧+水电+管理），附52行人工工时定额、16行工装治具明细；报价汇总「加工成本」直接引用其合计。
A12: • 散热器：源表未含，按68元未税单列（参数B49），物料明细分类「散热器」，报价汇总独立成本行。
A13: • 一次性费用：工装48700+EPS泡沫模具29499.115=78199.115元，直接向客户收取，不计入单台成本（报价汇总六）。
A14: • 运费：目的地填「青岛市」时跨越费率未覆盖山东→自动按运费率(参数B51=1.16%)回退估算；覆盖城市则用跨越费率精算。毛利率(参数B4)已对齐源表0.3。
A15: • 制费明细P01~P07为自下而上工序估算工具（商空项目已置0辅料/工装避免重复）；商空加工成本以「加工成本明细」综合表为准。
A16: • 风险检查（报价汇总七）：客供料清单8项与硬件BOM内8项单价0的客供标记一一对应，均不计入成本；未报价物料(非客供)应为0。客供料参考金额按用量×单价=565.138元/台，源表合计554.3197（源表口径差10.82，不影响报价）。
A17: • 包装费双口径：报价汇总取包装BOM实际63.7765元/台；包装计算表按几何模型估算约43.67元/件，两者互为校验，BOM优先。EPS泡沫模具16667元×2已列入一次性费用。
A18: • 成本差异1.35%(参数B50)与运费率1.16%(参数B51)均取自源表比例；小计含散热器68元后，成本差异与运费随之联动放大，符合"全部成本因素入表"的口径。

Sheet 报价汇总
A1: 产品成本测算报价表（包装费 + 运费自动计算）
A3: 一、产品基础信息（输入）
A4: 产品代码 | B4: N10305002124 | Z4: 福州市/厦门市/泉州市
A5: 产品名称 | B5: DRV-26P-NJTJ(RoHS)中央式空调控制器驱动板组件 | Z5: 宁德市/莆田市/漳州市
A6: 客户名称 | B6: 青岛国创智能家电研究院有限公司 | Z6: 龙岩市/三明市/南平市
A7: 报价日期 | B7: =TODAY() | Z7: 拉萨市
A8: 年需求量(PCS) | B8: 5000 | Z8: 日喀则市/山南市/林芝市/昌都市/那曲市/阿里地区
A9: MOQ(PCS) | B9: 50 | Z9: 贵阳市/遵义市/安顺市
A10: 备注 | B10: 工装、模具费直接向客户收取；已扣除8颗客供料核算成本；散热器68元未税另计；N10305002124与N10305002125共用模具 | Z10: 黔南布依族苗族自治州/黔东南苗族侗族自治州/铜仁市/毕节市/六盘水市/黔西南布依族苗族自治州
Z11: 广州市/深圳市/珠海市/中山市/东莞市
A12: 二、产品规格（输入，驱动包装费） | Z12: 江门市/惠州市/佛山市/肇庆市
A13: 成品长(mm,含散热器) | B13: 660 | Z13: 汕尾市/阳江市/揭阳市/茂名市/韶关市/梅州市/汕头市/湛江市/河源市/清远市/云浮市/潮州市
A14: 成品宽(mm) | B14: 390 | Z14: 武汉市/鄂州市
A15: 成品高(mm) | B15: 260 | Z15: 襄阳市/孝感市/黄石市/荆州市/宜昌市/神农架林区/十堰市/随州市/荆门市
A16: 单台净重(kg) | B16: 3.5 | Z16: 黄冈市/咸宁市/恩施土家族苗族自治州/潜江市/仙桃市/天门市
A17: 每箱件数N | B17: 2 | Z17: 株洲市/长沙市/湘潭市
A18: 是否含整托分摊 | B18: 是 | Z18: 益阳市
A19: 是否带散热器(是/否) | B19: 是 | D19: =IF(OR(B19="是",B20="是"),"自动→大板：EPE上下垫片+四角护角+纸箱+托盘+缠绕膜+打包带","自动→小板：防静电气泡袋+隔板+纸箱+护角+托盘+缠绕膜") | Z19: 岳阳市/衡阳市/郴州市/常德市/娄底市/邵阳市/湘西土家族苗族自治州/张家界市/怀化市/永州市
A20: 是否带组装结构(是/否) | B20: 是 | D20: 装配节拍(秒/台) | E20: 12 | F20: 工时费(元/小时) | G20: =参数!$B$46
A21: 三、物流（输入，驱动运费） | Z21: 重庆市
A22: 物流产品 | B22: 次日达 | Z22: 成都市/资阳市/眉山市
A23: 目的地 | B23: 青岛市 | Z23: 绵阳市
A24: 每票件数M | B24: 20 | Z24: 自贡市/南充市/达州市/遂宁市/广安市/巴中市/泸州市/宜宾市/内江市/乐山市/雅安市/德阳市/广元市
A25: 声明价值(元/票,可选) | Z25: 攀枝花市/凉山彝族自治州/甘孜藏族自治州/阿坝藏族羌族自治州
A26: 注 | B26: 物流产品选次日达/特惠普运；目的地只需填城市名（如“宁波”“杭州”），系统按所选产品自动匹配对应费率行；该产品不覆盖此城市时运费显示空白。 | Z26: 合肥市/芜湖市/马鞍山市
A27: 四、成本构成（未税/单台，自动计算） | Z27: 滁州市/蚌埠市/六安市
A28: 成本项目 | B28: 金额 | C28: 单位 | D28: 备注 | E28: 公式 | Z28: 淮南市/安庆市/宿州市/亳州市/阜阳市/黄山市/淮北市/铜陵市/宣城市/池州市
A29: 硬件材料 | B29: =SUMIFS(物料明细!$H:$H,物料明细!$B:$B,"硬件") | C29: 元/台 | D29: 物料明细·硬件(272项) | Z29: 乌鲁木齐市
A30: 结构件 | B30: =SUMIFS(物料明细!$H:$H,物料明细!$B:$B,"结构件") | C30: 元/台 | D30: 物料明细·结构件(32项，含组装结构) | Z30: 塔城地区/白杨市/新星市/哈密市/昆玉市/和田地区/北屯市/阿勒泰地区/克孜勒苏柯尔克孜自治州/双河市/博尔塔拉蒙古自治州/克拉玛依市/胡杨河市/石河子市/五家渠市/昌吉回族自治州/吐鲁番市/巴音郭楞蒙古自治州/铁门关市/阿克苏地区/阿拉尔市/图木舒克市/喀什地区/伊犁哈萨克自治州/可克达拉市
A31: 散热器 | B31: =SUMIFS(物料明细!$H:$H,物料明细!$B:$B,"散热器") | C31: 元/台 | D31: 单独采购68元未税(参数B49)，源表未含 | Z31: 南京市/无锡市/苏州市/常州市
A32: 包装材料 | B32: =SUMIFS(物料明细!$H:$H,物料明细!$B:$B,"包装材料") | C32: 元/台 | D32: ="包装BOM实际(商空方案8项)；包装计算模型估算="&TEXT(包装计算!$B$43,"0.00")&"元/件，可互校" | Z32: 镇江市/南通市/扬州市
A33: 辅助材料 | B33: =SUMIFS(物料明细!$H:$H,物料明细!$B:$B,"辅助材料") | C33: 元/台 | D33: 物料明细·辅料(锡丝/助焊剂等，16项) | Z33: 盐城市/徐州市/淮安市/连云港市/泰州市/宿迁市
A34: 加工成本 | B34: =加工成本明细!$C$18 | C34: 元/台 | D34: 综合口径：人工+SMT+机插+折旧+水电+管理(加工成本明细)
A35: 小计(料工费) | B35: =SUM(B29:B34) | C35: 元/台 | D35: 材料+加工(源表口径+散热器68) | Z35: 天津市
A36: 成本差异 | B36: =B35*参数!$B$50 | C36: 元/台 | D36: 制造损耗/差异缓冲(参数B50，默认1.35%) | Z36: 长春市
A37: 运费 | B37: =IF(ISNUMBER(运费计算!$B$33),运费计算!$B$33,B35*参数!$B$51) | C37: 元/台 | D37: =IF(ISNUMBER(运费计算!$B$33),"跨越费率自动计算(运费计算表)","跨越费率未覆盖该目的地，按参数B51运费率回退") | Z37: 吉林市
A38: 利润加成 | B38: =SUM(B35:B37)*参数!$B$52 | C38: 元/台 | D38: 成本内加成(参数B52，商空默认0) | Z38: 延边朝鲜族自治州/四平市/通化市/白城市/辽源市/松原市/白山市
A39: 总成本未税 | B39: =SUM(B35:B38) | C39: 元/台 | D39: 主营业务成本(单台) | Z39: 银川市
Z40: 石嘴山市/吴忠市/固原市/中卫市
A41: 五、自动报价结果 | Z41: 石家庄市/廊坊市
...

Sheet 物料明细
A1: 物料明细
A2: 序号 | B2: 物料分类 | C2: 物料编码 | D2: 物料名称规格 | E2: 单机用量 | F2: 未税单价 | G2: 损耗率 | H2: 金额 | I2: 是否客供 | J2: 备注
A3: =IF(C3<>"",ROW()-2,"") | B3: 硬件 | C3: 301H030491 | D3: 片式电阻 RC0805FR-07300KL/0805W8F3003T5E 1/8W,300KΩ,1%,0805(国巨/厚声)(编带)(RoHS) | E3: 18 | F3: 0.0045 | H3: =IF(I3="是",0,IF(OR(E3="",F3=""),0,E3*F3*(1+IF(G3="",0,G3)))) | I3: 否 | J3: 深圳市超利维实业有限公司
A4: =IF(C4<>"",ROW()-2,"") | B4: 硬件 | C4: 306110396 | D4: 高压陶瓷电容 HGK3AF103ZG3AW 10nF,1KV,P=7.5(万明)(编带)(RoHS) | E4: 1 | F4: 0.1331 | H4: =IF(I4="是",0,IF(OR(E4="",F4=""),0,E4*F4*(1+IF(G4="",0,G4)))) | I4: 否 | J4: 厦门万明电子有限公司
A5: =IF(C5<>"",ROW()-2,"") | B5: 硬件 | C5: 3155US1M | D5: 超快恢复二极管 US1M 1A,1KV,SMA(强茂)(编带)(RoHS) | E5: 1 | F5: 0.0274 | H5: =IF(I5="是",0,IF(OR(E5="",F5=""),0,E5*F5*(1+IF(G5="",0,G5)))) | I5: 否 | J5: 厦门镁富莱工贸有限公司
A6: =IF(C6<>"",ROW()-2,"") | B6: 硬件 | C6: 604B03VHZ51R | D6: 端子 B3P-VH (JST)(RoHS) | E6: 1 | F6: 0.222 | H6: =IF(I6="是",0,IF(OR(E6="",F6=""),0,E6*F6*(1+IF(G6="",0,G6)))) | I6: 否 | J6: 深圳市恒有电子有限公司
A7: =IF(C7<>"",ROW()-2,"") | B7: 硬件 | C7: 604B05VHZ51R | D7: 端子 B5P-VH (JST)(RoHS) | E7: 2 | F7: 0.322 | H7: =IF(I7="是",0,IF(OR(E7="",F7=""),0,E7*F7*(1+IF(G7="",0,G7)))) | I7: 否 | J7: 深圳市恒有电子有限公司
A8: =IF(C8<>"",ROW()-2,"") | B8: 硬件 | C8: N30101000615 | D8: 片式电阻 RC1206JR-0775RL/1206W4J0750T5E 1/4W,75Ω,5%,1206(国巨/厚声)(编带)(RoHS) | E8: 1 | F8: 0.0045 | H8: =IF(I8="是",0,IF(OR(E8="",F8=""),0,E8*F8*(1+IF(G8="",0,G8)))) | I8: 否 | J8: 厚声国际贸易（昆山）有限公司
A9: =IF(C9<>"",ROW()-2,"") | B9: 硬件 | C9: N30101000894 | D9: 片式电阻 RC1206FR-0722RL/1206W4F220JT5E 1/4W,22Ω,1%,1206(国巨/厚声)(编带)(RoHS) | E9: 2 | F9: 0.0058 | H9: =IF(I9="是",0,IF(OR(E9="",F9=""),0,E9*F9*(1+IF(G9="",0,G9)))) | I9: 否 | J9: 厚声国际贸易（昆山）有限公司
A10: =IF(C10<>"",ROW()-2,"") | B10: 硬件 | C10: N30101001049 | D10: 片式电阻 RC1206FR-076R8L/1206W4F680KT5E 1/4W,6.8Ω,1%,1206(国巨/厚声)(编带)(RoHS) | E10: 2 | F10: 0.0083 | H10: =IF(I10="是",0,IF(OR(E10="",F10=""),0,E10*F10*(1+IF(G10="",0,G10)))) | I10: 否 | J10: 厚声国际贸易（昆山）有限公司
A11: =IF(C11<>"",ROW()-2,"") | B11: 硬件 | C11: N30101005306 | D11: 片式电阻 GMR320HJCFAR100 7W,100mΩ,1%,2817(Rohm)(编带)(RoHS) | E11: 2 | F11: 2.38 | H11: =IF(I11="是",0,IF(OR(E11="",F11=""),0,E11*F11*(1+IF(G11="",0,G11)))) | I11: 否 | J11: 北天星电子(深圳)有限公司
A12: =IF(C12<>"",ROW()-2,"") | B12: 硬件 | C12: N30101005309 | D12: 片式电阻 1210W2F3003T5E 1/2W,300KΩ,1%,1210(厚声)(编带)(RoHS) | E12: 8 | F12: 0.023 | H12: =IF(I12="是",0,IF(OR(E12="",F12=""),0,E12*F12*(1+IF(G12="",0,G12)))) | I12: 否 | J12: 厚声国际贸易（昆山）有限公司
A13: =IF(C13<>"",ROW()-2,"") | B13: 硬件 | C13: N30103000520 | D13: 金属膜电阻 MF02SJJ0364A10 2WS,360KΩ,5%(厚声)(HF;RoHS) | E13: 3 | F13: 0.065 | H13: =IF(I13="是",0,IF(OR(E13="",F13=""),0,E13*F13*(1+IF(G13="",0,G13)))) | I13: 否 | J13: 厚声国际贸易（昆山）有限公司
A14: =IF(C14<>"",ROW()-2,"") | B14: 硬件 | C14: N30103000526 | D14: 金属膜电阻 MF01WFF3003A10 1W,300KΩ,1%(厚声)(编带)(HF;RoHS) | E14: 1 | F14: 0.0828 | H14: =IF(I14="是",0,IF(OR(E14="",F14=""),0,E14*F14*(1+IF(G14="",0,G14)))) | I14: 否 | J14: 厚声国际贸易（昆山）有限公司
... A306: =IF(C306<>"",ROW()-2,"") | B306: 结构件 | C306: N71014000080 | D306: 塑胶线夹 CHA-5 白色(插销式线夹)(罗克)(RoHS) | E306: 1 | F306: 0.12 | H306: =IF(I306="是",0,IF(OR(E306="",F306=""),0,E306*F306*(1+IF(G306="",0,G306)))) | I306: 否 | J306: 厦门罗克科技有限公司
A307: =IF(C307<>"",ROW()-2,"") | B307: 散热器 | C307: HS-DRV26P | D307: 散热器（商空大功率驱动板，单独采购，未税） | E307: 1 | F307: =参数!$B$49 | H307: =IF(I307="是",0,IF(OR(E307="",F307=""),0,E307*F307*(1+IF(G307="",0,G307)))) | I307: 否 | J307: 源表未含，按68元未税单列
A308: =IF(C308<>"",ROW()-2,"") | B308: 包装材料 | C308: 4013430R | D308: 塑胶线夹 3.6X300 (尼龙扣)(正顺达)(RoHS) | E308: 2 | F308: 0.099 | H308: =IF(I308="是",0,IF(OR(E308="",F308=""),0,E308*F308*(1+IF(G308="",0,G308)))) | I308: 否 | J308: 厦门正顺达电子有限公司
A309: =IF(C309<>"",ROW()-2,"") | B309: 包装材料 | C309: N40501000405 | D309: 纸箱 665X393X405 (RoHS) | E309: 1 | F309: 10.98 | H309: =IF(I309="是",0,IF(OR(E309="",F309=""),0,E309*F309*(1+IF(G309="",0,G309)))) | I309: 否 | J309: 厦门比瑞特包装科技有限公司
A310: =IF(C310<>"",ROW()-2,"") | B310: 包装材料 | C310: N40505000136 | D310: 塑料袋 355X245 (凹凸)(RoHS) | E310: 1 | F310: 0.25 | H310: =IF(I310="是",0,IF(OR(E310="",F310=""),0,E310*F310*(1+IF(G310="",0,G310)))) | I310: 否 | J310: 厦门比瑞特包装科技有限公司
A311: =IF(C311<>"",ROW()-2,"") | B311: 包装材料 | C311: N40505000140 | D311: 塑料袋 372X322X700 (防静电,厚度0.1mm)(RoHS) | E311: 1 | F311: 3.39 | H311: =IF(I311="是",0,IF(OR(E311="",F311=""),0,E311*F311*(1+IF(G311="",0,G311)))) | I311: 否 | J311: 厦门比瑞特包装科技有限公司
A312: =IF(C312<>"",ROW()-2,"") | B312: 包装材料 | C312: N40511000095 | D312: 泡沫 660×399×115 (EPS料,右侧，DRV-20P,26P包装用)(RoHS) | E312: 1 | F312: 22.1 | H312: =IF(I312="是",0,IF(OR(E312="",F312=""),0,E312*F312*(1+IF(G312="",0,G312)))) | I312: 否 | J312: 厦门鹏源鑫工贸有限公司；含EPS泡沫模具(见一次性费用)
A313: =IF(C313<>"",ROW()-2,"") | B313: 包装材料 | C313: N40511000096 | D313: 泡沫 660×399×146 (EPS料,左侧，DRV-20P,26P包装用)(RoHS) | E313: 1 | F313: 24.7 | H313: =IF(I313="是",0,IF(OR(E313="",F313=""),0,E313*F313*(1+IF(G313="",0,G313)))) | I313: 否 | J313: 厦门鹏源鑫工贸有限公司；含EPS泡沫模具(见一次性费用)
A314: =IF(C314<>"",ROW()-2,"") | B314: 包装材料 | C314: N40512000282 | D314: 泡沫棉 40X20X199 (右侧EVA棉块2)(高密度)(防静电)(RoHS) | E314: 2 | F314: 1.0619 | H314: =IF(I314="是",0,IF(OR(E314="",F314=""),0,E314*F314*(1+IF(G314="",0,G314)))) | I314: 否 | J314: 厦门市达唯工贸有限公司
A315: =IF(C315<>"",ROW()-2,"") | B315: 包装材料 | C315: N60703001395 | D315: 标签 BQ12080W001-HL (格式标签)(1寸卷芯,外径83mm)(RoHS) | E315: 1 | F315: 0.0347 | H315: =IF(I315="是",0,IF(OR(E315="",F315=""),0,E315*F315*(1+IF(G315="",0,G315)))) | I315: 否 | J315: 厦门亿华辉工贸有限公司（ZZ）
A316: =IF(C316<>"",ROW()-2,"") | B316: 辅助材料 | C316: N40716000018 | D316: 锡丝 BSD620-W Sn0.3Ag0.7Cu(φ3.0)(博士达)(RoHS) | E316: 0.001723778 | F316: 309.2832 | H316: =IF(I316="是",0,IF(OR(E316="",F316=""),0,E316*F316*(1+IF(G316="",0,G316)))) | I316: 否 | J316: KG
A317: =IF(C317<>"",ROW()-2,"") | B317: 辅助材料 | C317: N40716000015 | D317: 锡丝 YTW101 Sn0.7Cu,Flux2.4％(φ0.8)(亚通)(RoHS) | E317: 0.099898221 | F317: 265.4779 | H317: =IF(I317="是",0,IF(OR(E317="",F317=""),0,E317*F317*(1+IF(G317="",0,G317)))) | I317: 否 | J317: KG 按V3.0计算用量
A318: =IF(C318<>"",ROW()-2,"") | B318: 辅助材料 | C318: 458F007 | D318: 助焊剂 TF-328 (深圳同方)(RoHS) | E318: 0.005 | F318: 15.8828 | H318: =IF(I318="是",0,IF(OR(E318="",F318=""),0,E318*F318*(1+IF(G318="",0,G318)))) | I318: 否 | J318: L
A319: =IF(C319<>"",ROW()-2,"") | B319: 辅助材料 | C319: 409012 | D319: 导热硅脂 HZ-KS101 (百合花)(RoHS) | E319: 0.0049 | F319: 6.1538 | H319: =IF(I319="是",0,IF(OR(E319="",F319=""),0,E319*F319*(1+IF(G319="",0,G319)))) | I319: 否 | J319: BOT
... A339: =IF(C339<>"",ROW()-2,"") | B339: 客供料 | C339: 客供9 | D339: MCU R5F526T8ADFM/LQFP64 | E339: 2 | F339: 7.75 | H339: =IF(I339="是",0,IF(OR(E339="",F339=""),0,E339*F339*(1+IF(G339="",0,G339)))) | I339: 是 | J339: 客供不计入报价；瑞萨 新晔 12W

Sheet 制费明细
A1: 制费明细（工程报价表格式 P01~P07：自下而上工序估算工具）｜注：商空项目加工成本以「加工成本明细」综合表为准
A3: 客户 | B3: =报价汇总!B6 | C3: 机型 | D3: =报价汇总!B4 | E3: 预计订单(pcs) | G3: =报价汇总!B8 | H3: 联动报价汇总年需求量(B8)；夹具一次性费用分摊分母
A4: 人工费率(元/秒) | B4: 0.0089138889 | C4: 32.09元/小时÷3600 | D4: 宽放系数 | E4: 1.1 | F4: 烧录/成型/组装共用 | G4: 费率来源：003/009参考报价反推（0.0588元÷6.6s），可按实际改
A6: P01 SMT贴片（费用 = 工艺单价 × 元件个数）
A7: 项目 | B7: 工序名称 | C7: 元件类型 | D7: 工艺单价(元) | E7: 元件个数 | F7: 备注 | G7: 费用(元) | H7: 说明
A8: P01 | B8: SMT | C8: 0603/0402 | D8: 0.019 | E8: 56 | G8: =IFERROR(D8*E8,0)
C9: 1206/0805 | D9: 0.02 | E9: 4 | G9: =IFERROR(D9*E9,0)
C10: 二/三极管 | D10: 0.02 | E10: 0 | G10: =IFERROR(D10*E10,0)
C11: 按键/插座 | D11: 0.06 | E11: 4 | G11: =IFERROR(D11*E11,0)
C12: 电感/MOS管/EC等 | D12: 0.035 | E12: 1 | G12: =IFERROR(D12*E12,0)
C13: 贴片IC | D13: 0.018 | E13: 9 | F13: 每4个pin为1个元件 | G13: =IFERROR(D13*E13,0)
C14: 模块 | D14: 0.142 | E14: 0 | G14: =IFERROR(D14*E14,0)
C15: SMT成本(元) | G15: =SUM(G8:G14)
A17: P02 烧录（工序工时 = 工作时间 × 工序个数 × 宽放；成本 = 工时 × 人工费率）
A18: 项目 | B18: 工序名称 | C18: 工艺流程 | D18: 工作时间(s) | E18: 工序个数 | F18: 宽放系数 | G18: 工序工时(s) | H18: 费用(元)
A19: P02 | B19: SL | C19: 离线烧录 | D19: 6 | E19: 1 | F19: =$E$4 | G19: =D19*E19*F19 | H19: =G19*$B$4
C20: 在线烧录 | D20: 3 | E20: 0 | F20: =$E$4 | G20: =D20*E20*F20 | H20: =G20*$B$4
C21: 烧录成本(元) | H21: =SUM(H19:H20)
A23: P03 AI/RI 机插（费用 = 单价 × 个数 × 宽放）
A24: 项目 | B24: 工序名称 | C24: 元件类型 | D24: 工艺单价(元) | E24: 元件个数 | F24: 宽放系数 | G24: 费用(元) | H24: 说明
A25: P03 | B25: AI/RI | C25: 电阻/二极管 | D25: 0.025 | E25: 0 | F25: =$E$4 | G25: =IFERROR(D25*E25*F25,0)
C26: 跳线 | D26: 0.022 | E26: 0 | F26: =$E$4 | G26: =IFERROR(D26*E26*F26,0)
C27: RI | D27: 0.025 | E27: 0 | F27: =$E$4 | G27: =IFERROR(D27*E27*F27,0)
C28: AI成本(元) | G28: =SUM(G25:G27)
A30: P04 成型（工序工时 = 工作时间 × 元件数量 × 宽放；成本 = 工时 × 人工费率）
A31: 项目 | B31: 工序名称 | C31: 工艺流程 | D31: 工作时间(s) | E31: 元件数量 | F31: 宽放系数 | G31: 工序工时(s) | H31: 费用(元)
A32: P04 | B32: 成型 | C32: 电解电容 | D32: 1.2 | E32: 0 | F32: =$E$4 | G32: =D32*E32*F32 | H32: =G32*$B$4
C33: 贴板成型 | D33: 1.8 | E33: 0 | F33: =$E$4 | G33: =D33*E33*F33 | H33: =G33*$B$4
C34: 自动成型 | D34: 0.6 | E34: 0 | F34: =$E$4 | G34: =D34*E34*F34 | H34: =G34*$B$4
C35: 晶闸管成型 | D35: 6 | E35: 0 | F35: =$E$4 | G35: =D35*E35*F35 | H35: =G35*$B$4
C36: 散热器组装 | D36: 20 | E36: 0 | F36: =$E$4 | G36: =D36*E36*F36 | H36: =G36*$B$4
C37: 光敏电阻成型 | D37: 8 | E37: 0 | F37: =$E$4 | G37: =D37*E37*F37 | H37: =G37*$B$4
C38: 铆钉 | D38: 0.5 | E38: 0 | F38: =$E$4 | G38: =D38*E38*F38 | H38: =G38*$B$4
C39: 成型成本(元) | H39: =SUM(H32:H38)
A41: P05 组装（18道工序：工序工时 = 工作节拍 × 工序个数 × 宽放；成本 = 工时 × 人工费率）
A42: 项目 | B42: 工序名称 | C42: 工艺流程 | D42: 工作节拍(s) | E42: 工序个数 | F42: 宽放系数 | G42: 工序工时(s) | H42: 费用(元)
A43: P05 | B43: 组装 | C43: 安装过炉治具 | D43: 3 | E43: 1 | F43: =$E$4 | G43: =D43*E43*F43 | H43: =G43*$B$4
C44: 插件 | D44: 3 | E44: 1 | F44: =$E$4 | G44: =D44*E44*F44 | H44: =G44*$B$4
C45: 插件QC | D45: 3 | E45: 1 | F45: =$E$4 | G45: =D45*E45*F45 | H45: =G45*$B$4
C46: 卸送治具/AVI检测 | D46: 3 | E46: 2 | F46: =$E$4 | G46: =D46*E46*F46 | H46: =G46*$B$4
...

Sheet 加工成本明细
A1: 加工成本明细（商空大功率驱动板·综合加工成本构成）
A3: 一、加工成本构成（元/台，综合口径：人工+制费+SMT/机插）
A4: 序号 | B4: 成本组成 | C4: 金额(元/台) | F4: 说明
A5: 1 | B5: 贴片加工成本 | C5: 6.1656 | F5: SMT贴片 1101.001点×0.0056
A6: 2 | B6: 机插加工成本 | C6: 0.2394 | F6: AI机插 14点×0.0171
A7: 3 | B7: 预烧写加工成本 | C7: 0 | F7: 本项目无
A8: 4 | B8: 人工成本 | C8: 82.0882 | F8: 插焊/测试/组装等直接人工（详见二）
A9: 5 | B9: 折旧（专用） | C9: 0.8424 | F9: 专用设备折旧
A10: 6 | B10: 折旧（公共） | C10: 2.2 | F10: 公共设备折旧分摊
A11: 7 | B11: 水电（专用） | C11: 1.4745 | F11: 专用水电
A12: 8 | B12: 水电（公共） | C12: 1.4776 | F12: 公共水电分摊
A13: 9 | B13: 工装 | C13: 0 | F13: 工装直接向客户收取（详见三），不计入单台
A14: 10 | B14: 低值易耗 | C14: 4.5477 | F14: 低值易耗品摊销
A15: 11 | B15: 管理人员工资 | C15: 21.3676 | F15: 制造管理费用分摊
A16: 12 | B16: 其他 | C16: 6.0253 | F16: 其他制造费用
A17: 13 | B17: 检验成本 | C17: 0 | F17: 本项目未单列
B18: 加工成本合计(元/台) | C18: =SUM(C5:C17) | F18: → 报价汇总「四、成本构成」加工成本行
A20: 二、人工工时定额明细（源表未提供逐行人工成本，人工成本合计82.0882元见上）
A21: 序号 | B21: 生产分段 | C21: 工序类别 | D21: 生产定额 | E21: 人数 | F21: 备注
A22: 1 | B22: 装配段 | C22: 装配 | D22: 12 | E22: 10
A23: 2 | B23: 装配段 | C23: FCT | D23: 12 | E23: 2
A24: 3 | B24: 装配段 | C24: 外观检验 | D24: 12 | E24: 2
A25: 4 | B25: 装配段 | C25: OQC | D25: 12 | E25: 0.24
A26: 5 | B26: 装配段 | C26: 产前准备 | D26: 12 | E26: 0.6
A27: 6 | B27: 装配段 | C27: 杂项设备 | D27: 12 | E27: 0.6
A28: 7 | B28: 装配段 | C28: 维修清尾 | D28: 12 | E28: 0.36
A29: 8 | B29: 装配段 | C29: 包装 | D29: 12 | E29: 2
A30: 9 | B30: 插焊段 | C30: 焊接 | D30: 80 | E30: 5
A31: 10 | B31: 插焊段 | C31: 插件 | D31: 80 | E31: 9
A32: 11 | B32: 插焊段 | C32: 维修清尾 | D32: 80 | E32: 0.5
A33: 12 | B33: 插焊段 | C33: 喷漆 | D33: 80 | E33: 0.6
... A73: 52 | B73: 插焊段 | C73: 产前准备 | D73: 240 | E73: 0.6
C74: 人工成本合计(元/台) | D74: 82.0882 | F74: 源表人工成本为汇总值，逐行成本不可拆分
A76: 三、工装治具明细（一次性，直接向客户收取，不计入单台成本）
A77: 序号 | B77: 工艺/名称 | C77: 数量 | D77: 单价(元) | E77: 金额(元) | F77: 年产能/单片分摊
A78: 1 | B78: 装配/装配工装 | C78: 2 | D78: 2000 | E78: 4000 | F78: 年5000/单片0.2667
A79: 2 | B79: 自动测试/测试工装 | C79: 2 | D79: 4000 | E79: 8000 | F79: 年5000/单片0.5333
A80: 3 | B80: 波峰焊/波峰焊托盘 | C80: 15 | D80: 300 | E80: 4500 | F80: 年5000/单片0.3
A81: 4 | B81: 双面喷漆/喷漆托盘 | C81: 0 | D81: 0 | E81: 0 | F81: 年5000/单片0
A82: 5 | B82: 自动测试/自动测试工装 | C82: 2 | D82: 4000 | E82: 8000 | F82: 年5000/单片0.5333
...

Sheet 参数
A1: 参数设置
A2: 参数项 | B2: 参数值 | C2: 说明
A3: 税率 | B3: 0.13 | C3: 增值税率，默认13%
A4: 目标毛利率 | B4: 0.3 | C4: 报价目标毛利率
A5: 默认损耗率 | B5: 0.02 | C5: 物料未填损耗率时使用
A6: 默认分摊数量 | B6: 5000 | C6: 工装治具费用默认分摊数量
A8: 二、包装与整托参数
A9: 参数项 | B9: 参数值 | C9: 单位 | D9: 说明
A10: 防静电气泡袋单价 | B10: 2.5 | C10: 元/㎡
A11: 气泡袋单边余量 | B11: 30 | C11: mm
A12: 干燥剂单价 | B12: 0.1 | C12: 元/袋
A13: 湿度指示卡单价 | B13: 0.3 | C13: 元/张
A14: EPE珍珠棉单价 | B14: 1800 | C14: 元/m³
A15: EPE珍珠棉密度 | B15: 22 | C15: kg/m³
A16: 单瓦楞3层纸板 | B16: 2 | C16: 元/㎡
A17: 双瓦楞5层纸板 | B17: 3.2 | C17: 元/㎡
A18: 重型7层纸板 | B18: 5 | C18: 元/㎡
A19: 双瓦楞纸板克重 | B19: 700 | C19: g/㎡
A20: 纸箱制箱加工费 | B20: 1.5 | C20: 元/个
A21: 材料损耗率 | B21: 0.05 | C21: 比例
... A32: 每托层数 | B32: 4 | C32: 层
A34: 三、物流参数
A35: 参数项 | B35: 参数值 | C35: 单位 | D35: 说明
A36: 体积重系数 | B36: 6000 | C36: ㎝³/kg
A37: 保费费率 | B37: 0.004 | C37: ‰即0.4%
A38: 保费最低收费 | B38: 5 | C38: 元/票
A39: 是否计保费 | B39: 否 | C39: 是/否
A41: 四、包装方案参数（小板/大板）
A42: 参数项 | B42: 参数值 | C42: 单位 | D42: 说明
A43: 防静电气泡袋克重 | B43: 60 | C43: g/㎡ | D43: 气泡袋面密度
A44: 隔板单价 | B44: 0.3 | C44: 元/件 | D44: 小板每件隔板
A45: 隔板克重 | B45: 20 | C45: g/件 | D45: 小板隔板重量
A46: 默认装配工时费 | B46: 60 | C46: 元/小时 | D46: 首页可按项目覆盖
A48: 五、商空大功率项目专用参数
A49: 散热器单价(未税,元) | B49: 68
A50: 成本差异率(制造损耗缓冲) | B50: 0.0135
A51: 运费费率(跨越不覆盖时备用) | B51: 0.0116
A52: 成本内利润加成率(商空默认0) | B52: 0
A53: EPS泡沫模具费(一次性,元) | B53: 29499.115
A54: 工装治具费(一次性,直接收取,元) | B54: 48700
...

Sheet 包装计算
A1: 包装费计算（自动，按包装方案清单）
A3: 一、输入（自动取自报价汇总）
A4: 成品长(mm) | B4: =报价汇总!B13
A5: 成品宽(mm) | B5: =报价汇总!B14
A6: 成品高(mm) | B6: =报价汇总!B15
A7: 每箱件数N | B7: =报价汇总!B17
A8: 是否含整托 | B8: =报价汇总!B18
A9: 包装方案(自动) | B9: =IF(OR(报价汇总!B19="是",报价汇总!B20="是"),"大板","小板")
A11: 二、包装几何（自动）
A12: 成品最大边长(mm) | B12: =MAX(B4:B6)
A13: 缓冲厚度t(mm) | B13: =VLOOKUP($B$12,$A$58:$D$61,3,TRUE())
A14: 箱内长(mm) | B14: =B4+2*B13+参数!$B$22
A15: 箱内宽(mm) | B15: =B5+2*B13+参数!$B$22
A16: 箱内高(mm) | B16: =B7*(B6+2*B13)+参数!$B$22
A17: 单箱体积(㎝³) | B17: =B14*B15*B16/1000
A19: 三、内包装材料费（单件）
A20: 气泡袋长(mm) | B20: =B4+B6+2*参数!$B$11
A21: 气泡袋宽(mm) | B21: =B5+B6+2*参数!$B$11
A22: 气泡袋面积(㎡) | B22: =B20*B21/10^6
A23: 气泡袋费(元/件) | B23: =B22*参数!$B$10
A24: 隔板费(元/件) | B24: =IF($B$9="小板",IF(OR($B$7="",$B$7=0),0,参数!$B$44*MAX($B$7-1,0)/$B$7),0)
A25: EPE体积(垫片+护角,㎥/件) | B25: =(2*B4*B5*B13+4*B13*B13*B6)/10^9
A26: EPE费(元/件) | B26: =B25*参数!$B$14
A27: 内包材料费(元/件) | B27: =IF($B$9="小板",B23+B24,B26)
A28: 纸箱用纸面积(㎡) | B28: =(B14+B15)*2*(B15+2*B16)/10^6*(1+参数!$B$21)
A29: 瓦楞类型 | B29: =VLOOKUP($B$12,$A$58:$D$61,4,TRUE())
A30: 纸板单价(元/㎡) | B30: =VLOOKUP(B29,$A$65:$B$67,2,FALSE())
A31: 纸箱费(元/箱) | B31: =B28*B30+参数!$B$20
A32: 纸箱费(元/件) | B32: =IF(OR(B7="",B7=0),0,B31/B7)
A33: 辅料费(元/件) | B33: =IF(OR(B7="",B7=0),0,(参数!$B$23+参数!$B$24)/B7)
A34: 内包装单件费(元) | B34: =B27+B32+B33
A36: 四、整托分摊（可选，勾选含整托生效）
A37: 每箱占地(㎡) | B37: =B14*B15/10^6
A38: 每托件数(件) | B38: =IF(OR(B37="",B37=0),0,ROUNDDOWN(参数!$B$31/B37,0)*参数!$B$32)
A39: 每托包装费(元/托) | B39: =参数!$B$29+参数!$B$25/参数!$B$26+参数!$B$27*参数!$B$28+IF($B$9="大板",参数!$B$30,0)
A40: 整托分摊(元/件) | B40: =IF(OR(B38="",B38=0),0,B39/B38)
A41: 包装增重(kg/件) | B41: =IF(OR(B7="",B7=0),0,IF($B$9="小板",B22*参数!$B$43/1000,B25*参数!$B$15)+B28*参数!$B$19/1000/B7+IF($B$9="小板",参数!$B$45/1000*MAX($B$7-1,0)/$B$7,0)+0.005)
A43: 包装费合计(元/件) | B43: =B34+IF($B$8="是",B40,0)
A45: 五、包装方案清单对照（√=该方案包含）
A46: 包装物料 | B46: 单位 | C46: 单价(元) | D46: 小板 | E46: 大板
...

Sheet 跨越费率
A1: 跨越VIP运费费率（源自青岛国创VIP报价表，可按需改价）
A3: 产品 | B3: 目的省份 | C3: 目的地 | D3: 首重重量 | E3: 首重价格 | F3: 起重 | G3: 最低收费 | H3: 段1单价 | I3: 段2单价 | J3: 段3单价 | K3: 段4单价 | L3: 段5单价 | M3: 段6单价 | N3: 段7单价 | O3: 段8单价 | P3: 段9单价 | Q3: 匹配键
A4: 次日达 | B4: 福建省 | C4: 福州市/厦门市/泉州市 | D4: 1 | E4: 20 | F4: 30 | G4: 255 | H4: 8.1 | I4: 8.1 | J4: 8.1 | K4: 8.1 | L4: 7.2 | M4: 6.3 | N4: 6.3 | O4: 6.3 | P4: 6.3 | Q4: 次日达|福州市/厦门市/泉州市
A5: 次日达 | C5: 宁德市/莆田市/漳州市 | D5: 1 | E5: 20 | F5: 30 | G5: 255 | H5: 8.1 | I5: 8.1 | J5: 8.1 | K5: 8.1 | L5: 7.2 | M5: 6.3 | N5: 6.3 | O5: 6.3 | P5: 6.3 | Q5: 次日达|宁德市/莆田市/漳州市
A6: 次日达 | C6: 龙岩市/三明市/南平市 | D6: 1 | E6: 20 | F6: 30 | G6: 255 | H6: 8.1 | I6: 8.1 | J6: 8.1 | K6: 8.1 | L6: 7.2 | M6: 6.3 | N6: 6.3 | O6: 6.3 | P6: 6.3 | Q6: 次日达|龙岩市/三明市/南平市
A7: 次日达 | B7: 西藏自治区 | C7: 拉萨市 | D7: 1 | E7: 20 | F7: 30 | G7: 542 | H7: 18 | I7: 18 | J7: 18 | K7: 18 | L7: 18 | M7: 18 | N7: 18 | O7: 18 | P7: 18 | Q7: 次日达|拉萨市
A8: 次日达 | C8: 日喀则市/山南市/林芝市/昌都市/那曲市/阿里地区 | D8: 1 | E8: 25 | F8: 30 | G8: 678 | H8: 22.5 | I8: 22.5 | J8: 22.5 | K8: 22.5 | L8: 22.5 | M8: 22.5 | N8: 22.5 | O8: 22.5 | P8: 22.5 | Q8: 次日达|日喀则市/山南市/林芝市/昌都市/那曲市/阿里地区
A9: 次日达 | B9: 贵州省 | C9: 贵阳市/遵义市/安顺市 | D9: 1 | E9: 20 | F9: 30 | G9: 307 | H9: 9.9 | I9: 9.9 | J9: 9.9 | K9: 9 | L9: 9 | M9: 8.1 | N9: 8.1 | O9: 8.1 | P9: 8.1 | Q9: 次日达|贵阳市/遵义市/安顺市
A10: 次日达 | C10: 黔南布依族苗族自治州/黔东南苗族侗族自治州/铜仁市/毕节市/六盘水市/黔西南布依族苗族自治州 | D10: 1 | E10: 20 | F10: 30 | G10: 307 | H10: 9.9 | I10: 9.9 | J10: 9.9 | K10: 9 | L10: 9 | M10: 8.1 | N10: 8.1 | O10: 8.1 | P10: 8.1 | Q10: 次日达|黔南布依族苗族自治州/黔东南苗族侗族自治州/铜仁市/毕节市/六盘水市/黔西南布依族苗族自治州
A11: 次日达 | B11: 广东省 | C11: 广州市/深圳市/珠海市/中山市/东莞市 | D11: 1 | E11: 20 | F11: 15 | G11: 171 | H11: 10.8 | I11: 10.8 | J11: 10.8 | K11: 9.9 | L11: 9 | M11: 8.1 | N11: 8.1 | O11: 8.1 | P11: 8.1 | Q11: 次日达|广州市/深圳市/珠海市/中山市/东莞市
A12: 次日达 | C12: 江门市/惠州市/佛山市/肇庆市 | D12: 1 | E12: 20 | F12: 15 | G12: 171 | H12: 10.8 | I12: 10.8 | J12: 10.8 | K12: 9.9 | L12: 9 | M12: 8.1 | N12: 8.1 | O12: 8.1 | P12: 8.1 | Q12: 次日达|江门市/惠州市/佛山市/肇庆市
A13: 次日达 | C13: 汕尾市/阳江市/揭阳市/茂名市/韶关市/梅州市/汕头市/湛江市/河源市/清远市/云浮市/潮州市 | D13: 1 | E13: 20 | F13: 15 | G13: 171 | H13: 10.8 | I13: 10.8 | J13: 10.8 | K13: 9.9 | L13: 9 | M13: 8.1 | N13: 8.1 | O13: 8.1 | P13: 8.1 | Q13: 次日达|汕尾市/阳江市/揭阳市/茂名市/韶关市/梅州市/汕头市/湛江市/河源市/清远市/云浮市/潮州市
A14: 次日达 | B14: 湖北省 | C14: 武汉市/鄂州市 | D14: 1 | E14: 20 | F14: 30 | G14: 255 | H14: 8.1 | I14: 8.1 | J14: 8.1 | K14: 8.1 | L14: 7.2 | M14: 6.3 | N14: 6.3 | O14: 6.3 | P14: 6.3 | Q14: 次日达|武汉市/鄂州市
A15: 次日达 | C15: 襄阳市/孝感市/黄石市/荆州市/宜昌市/神农架林区/十堰市/随州市/荆门市 | D15: 1 | E15: 20 | F15: 30 | G15: 255 | H15: 8.1 | I15: 8.1 | J15: 8.1 | K15: 8.1 | L15: 7.2 | M15: 6.3 | N15: 6.3 | O15: 6.3 | P15: 6.3 | Q15: 次日达|襄阳市/孝感市/黄石市/荆州市/宜昌市/神农架林区/十堰市/随州市/荆门市
A16: 次日达 | C16: 黄冈市/咸宁市/恩施土家族苗族自治州/潜江市/仙桃市/天门市 | D16: 1 | E16: 20 | F16: 30 | G16: 307 | H16: 9.9 | I16: 9.9 | J16: 9.9 | K16: 9.9 | L16: 9 | M16: 8.1 | N16: 8.1 | O16: 8.1 | P16: 8.1 | Q16: 次日达|黄冈市/咸宁市/恩施土家族苗族自治州/潜江市/仙桃市/天门市
A17: 次日达 | B17: 湖南省 | C17: 株洲市/长沙市/湘潭市 | D17: 1 | E17: 20 | F17: 30 | G17: 255 | H17: 8.1 | I17: 8.1 | J17: 8.1 | K17: 8.1 | L17: 7.2 | M17: 6.3 | N17: 6.3 | O17: 6.3 | P17: 6.3 | Q17: 次日达|株洲市/长沙市/湘潭市
A18: 次日达 | C18: 益阳市 | D18: 1 | E18: 20 | F18: 30 | G18: 255 | H18: 8.1 | I18: 8.1 | J18: 8.1 | K18: 8.1 | L18: 7.2 | M18: 6.3 | N18: 6.3 | O18: 6.3 | P18: 6.3 | Q18: 次日达|益阳市
A19: 次日达 | C19: 岳阳市/衡阳市/郴州市/常德市/娄底市/邵阳市/湘西土家族苗族自治州/张家界市/怀化市/永州市 | D19: 1 | E19: 20 | F19: 30 | G19: 307 | H19: 9.9 | I19: 9.9 | J19: 9.9 | K19: 9.9 | L19: 9 | M19: 8.1 | N19: 8.1 | O19: 8.1 | P19: 8.1 | Q19: 次日达|岳阳市/衡阳市/郴州市/常德市/娄底市/邵阳市/湘西土家族苗族自治州/张家界市/怀化市/永州市
A20: 次日达 | B20: 重庆 | C20: 重庆市 | D20: 1 | E20: 20 | F20: 30 | G20: 255 | H20: 8.1 | I20: 8.1 | J20: 8.1 | K20: 8.1 | L20: 7.2 | M20: 7.2 | N20: 7.2 | O20: 7.2 | P20: 7.2 | Q20: 次日达|重庆市
A21: 次日达 | B21: 四川省 | C21: 成都市/资阳市/眉山市 | D21: 1 | E21: 20 | F21: 30 | G21: 255 | H21: 8.1 | I21: 8.1 | J21: 8.1 | K21: 8.1 | L21: 7.2 | M21: 7.2 | N21: 7.2 | O21: 7.2 | P21: 7.2 | Q21: 次日达|成都市/资阳市/眉山市
A22: 次日达 | C22: 绵阳市 | D22: 1 | E22: 20 | F22: 30 | G22: 255 | H22: 8.1 | I22: 8.1 | J22: 8.1 | K22: 8.1 | L22: 7.2 | M22: 7.2 | N22: 7.2 | O22: 7.2 | P22: 7.2 | Q22: 次日达|绵阳市
A23: 次日达 | C23: 自贡市/南充市/达州市/遂宁市/广安市/巴中市/泸州市/宜宾市/内江市/乐山市/雅安市/德阳市/广元市 | D23: 1 | E23: 20 | F23: 30 | G23: 307 | H23: 9.9 | I23: 9.9 | J23: 9.9 | K23: 9.9 | L23: 9 | M23: 9 | N23: 9 | O23: 9 | P23: 9 | Q23: 次日达|自贡市/南充市/达州市/遂宁市/广安市/巴中市/泸州市/宜宾市/内江市/乐山市/雅安市/德阳市/广元市
A24: 次日达 | C24: 攀枝花市/凉山彝族自治州/甘孜藏族自治州/阿坝藏族羌族自治州 | D24: 1 | E24: 20 | F24: 30 | G24: 385 | H24: 12.6 | I24: 12.6 | J24: 12.6 | K24: 12.6 | L24: 11.7 | M24: 11.7 | N24: 11.7 | O24: 11.7 | P24: 11.7 | Q24: 次日达|攀枝花市/凉山彝族自治州/甘孜藏族自治州/阿坝藏族羌族自治州
A25: 次日达 | B25: 安徽省 | C25: 合肥市/芜湖市/马鞍山市 | D25: 1 | E25: 20 | F25: 30 | G25: 255 | H25: 8.1 | I25: 8.1 | J25: 8.1 | K25: 8.1 | L25: 7.2 | M25: 6.3 | N25: 6.3 | O25: 6.3 | P25: 6.3 | Q25: 次日达|合肥市/芜湖市/马鞍山市
A26: 次日达 | C26: 滁州市/蚌埠市/六安市 | D26: 1 | E26: 20 | F26: 30 | G26: 281 | H26: 9 | I26: 9 | J26: 9 | K26: 9 | L26: 8.1 | M26: 7.2 | N26: 7.2 | O26: 7.2 | P26: 7.2 | Q26: 次日达|滁州市/蚌埠市/六安市
A27: 次日达 | C27: 淮南市/安庆市/宿州市/亳州市/阜阳市/黄山市/淮北市/铜陵市/宣城市/池州市 | D27: 1 | E27: 20 | F27: 30 | G27: 307 | H27: 9.9 | I27: 9.9 | J27: 9.9 | K27: 9.9 | L27: 9 | M27: 8.1 | N27: 8.1 | O27: 8.1 | P27: 8.1 | Q27: 次日达|淮南市/安庆市/宿州市/亳州市/阜阳市/黄山市/淮北市/铜陵市/宣城市/池州市
A28: 次日达 | B28: 新疆维吾尔自治区 | C28: 乌鲁木齐市 | D28: 1 | E28: 20 | F28: 30 | G28: 542 | H28: 18 | I28: 18 | J28: 18 | K28: 18 | L28: 18 | M28: 18 | N28: 18 | O28: 18 | P28: 18 | Q28: 次日达|乌鲁木齐市
A29: 次日达 | C29: 塔城地区/白杨市/新星市/哈密市/昆玉市/和田地区/北屯市/阿勒泰地区/克孜勒苏柯尔克孜自治州/双河市/博尔塔拉蒙古自治州/克拉玛依市/胡杨河市/石河子市/五家渠市/昌吉回族自治州/吐鲁番市/巴音郭楞蒙古自治州/铁门关市/阿克苏地区/阿拉尔市/图木舒克市/喀什地区/伊犁哈萨克自治州/可克达拉市 | D29: 1 | E29: 25 | F29: 30 | G29: 678 | H29: 22.5 | I29: 22.5 | J29: 22.5 | K29: 22.5 | L29: 22.5 | M29: 22.5 | N29: 22.5 | O29: 22.5 | P29: 22.5 | Q29: 次日达|塔城地区/白杨市/新星市/哈密市/昆玉市/和田地区/北屯市/阿勒泰地区/克孜勒苏柯尔克孜自治州/双河市/博尔塔拉蒙古自治州/克拉玛依市/胡杨河市/石河子市/五家渠市/昌吉回族自治州/吐鲁番市/巴音郭楞蒙古自治州/铁门关市/阿克苏地区/阿拉尔市/图木舒克市/喀什地区/伊犁哈萨克自治州/可克达拉市
A30: 次日达 | B30: 江苏省 | C30: 南京市/无锡市/苏州市/常州市 | D30: 1 | E30: 20 | F30: 15 | G30: 133 | H30: 8.1 | I30: 8.1 | J30: 8.1 | K30: 7.2 | L30: 6.3 | M30: 6.3 | N30: 6.3 | O30: 6.3 | P30: 6.3 | Q30: 次日达|南京市/无锡市/苏州市/常州市
A31: 次日达 | C31: 镇江市/南通市/扬州市 | D31: 1 | E31: 20 | F31: 15 | G31: 133 | H31: 8.1 | I31: 8.1 | J31: 8.1 | K31: 7.2 | L31: 6.3 | M31: 6.3 | N31: 6.3 | O31: 6.3 | P31: 6.3 | Q31: 次日达|镇江市/南通市/扬州市
A32: 次日达 | C32: 盐城市/徐州市/淮安市/连云港市/泰州市/宿迁市 | D32: 1 | E32: 20 | F32: 15 | G32: 133 | H32: 8.1 | I32: 8.1 | J32: 8.1 | K32: 7.2 | L32: 6.3 | M32: 6.3 | N32: 6.3 | O32: 6.3 | P32: 6.3 | Q32: 次日达|盐城市/徐州市/淮安市/连云港市/泰州市/宿迁市
A33: 次日达 | B33: 天津 | C33: 天津市 | D33: 1 | E33: 20 | F33: 20 | G33: 157 | H33: 7.2 | I33: 7.2 | J33: 7.2 | K33: 7.2 | L33: 6.3 | M33: 6.3 | N33: 6.3 | O33: 6.3 | P33: 6.3 | Q33: 次日达|天津市
A34: 次日达 | B34: 吉林省 | C34: 长春市 | D34: 1 | E34: 20 | F34: 30 | G34: 333 | H34: 10.8 | I34: 10.8 | J34: 10.8 | K34: 9.9 | L34: 9.9 | M34: 9 | N34: 9 | O34: 9 | P34: 9 | Q34: 次日达|长春市
A35: 次日达 | C35: 吉林市 | D35: 1 | E35: 20 | F35: 30 | G35: 359 | H35: 11.7 | I35: 11.7 | J35: 11.7 | K35: 10.8 | L35: 10.8 | M35: 9.9 | N35: 9.9 | O35: 9.9 | P35: 9.9 | Q35: 次日达|吉林市
A36: 次日达 | C36: 延边朝鲜族自治州/四平市/通化市/白城市/辽源市/松原市/白山市 | D36: 1 | E36: 20 | F36: 30 | G36: 412 | H36: 13.5 | I36: 13.5 | J36: 13.5 | K36: 12.6 | L36: 12.6 | M36: 11.7 | N36: 11.7 | O36: 11.7 | P36: 11.7 | Q36: 次日达|延边朝鲜族自治州/四平市/通化市/白城市/辽源市/松原市/白山市
A37: 次日达 | B37: 宁夏回族自治区 | C37: 银川市 | D37: 1 | E37: 20 | F37: 30 | G37: 490 | H37: 16.2 | I37: 16.2 | J37: 16.2 | K37: 14.4 | L37: 14.4 | M37: 14.4 | N37: 13.5 | O37: 13.5 | P37: 13.5 | Q37: 次日达|银川市
A38: 次日达 | C38: 石嘴山市/吴忠市/固原市/中卫市 | D38: 1 | E38: 20 | F38: 30 | G38: 542 | H38: 18 | I38: 18 | J38: 18 | K38: 16.2 | L38: 16.2 | M38: 16.2 | N38: 15.3 | O38: 15.3 | P38: 15.3 | Q38: 次日达|石嘴山市/吴忠市/固原市/中卫市
A39: 次日达 | B39: 河北省 | C39: 石家庄市/廊坊市 | D39: 1 | E39: 20 | F39: 30 | G39: 229 | H39: 7.2 | I39: 7.2 | J39: 7.2 | K39: 7.2 | L39: 7.2 | M39: 6.3 | N39: 6.3 | O39: 6.3 | P39: 6.3 | Q39: 次日达|石家庄市/廊坊市
A40: 次日达 | C40: 邯郸市/保定市/雄安新区/唐山市/沧州市/秦皇岛市 | D40: 1 | E40: 20 | F40: 30 | G40: 255 | H40: 8.1 | I40: 8.1 | J40: 8.1 | K40: 8.1 | L40: 8.1 | M40: 7.2 | N40: 7.2 | O40: 7.2 | P40: 7.2 | Q40: 次日达|邯郸市/保定市/雄安新区/唐山市/沧州市/秦皇岛市
A41: 次日达 | C41: 张家口市/承德市/衡水市/邢台市 | D41: 1 | E41: 20 | F41: 30 | G41: 281 | H41: 9 | I41: 9 | J41: 9 | K41: 9 | L41: 9 | M41: 8.1 | N41: 8.1 | O41: 8.1 | P41: 8.1 | Q41: 次日达|张家口市/承德市/衡水市/邢台市
...

Sheet 运费计算
A1: 运费计算（跨越费率，实重/体积重取大）
A3: 一、输入与费率定位（自动）
A4: 物流产品 | B4: =报价汇总!B22
A5: 目的地 | B5: =报价汇总!B23
A6: 每票件数M | B6: =报价汇总!B24
A7: 单台毛重(kg) | B7: =IF(报价汇总!B16="","",报价汇总!B16+包装计算!$B$41)
A8: 单箱体积(㎝³) | B8: =包装计算!$B$17
A9: 每箱件数N | B9: =报价汇总!B17
A10: 箱数(票内) | B10: =IF(OR(B6="",B9="",B9=0),"",B6/B9)
A11: 匹配键 | B11: =IF($B$12="","",INDEX(跨越费率!$Q$4:$Q$300,$B$12))
A12: 费率行号 | B12: =IF(OR($B$4="",$B$5=""),"",IFERROR(MATCH(1,INDEX((跨越费率!$A$4:$A$300=$B$4)*(ISNUMBER(SEARCH($B$5,跨越费率!$Q$4:$Q$300))),0),0),""))
A14: 二、计费重量（自动）
A15: 单票实重(kg) | B15: =IF(OR(B7="",B6=""),"",B7*B6)
A16: 单票体积重(kg) | B16: =IF(OR(B8="",B10=""),"",B8*B10/参数!$B$36)
A17: 计费重量(kg) | B17: =IF(AND(ISNUMBER(B15),ISNUMBER(B16)),MAX(B15,B16),"")
A18: 起重(kg) | B18: =IF(B12="","",INDEX(跨越费率!$F$4:$F$300,B12))
A19: 计费重量起重后 | B19: =IF(OR(B17="",B18=""),"",MAX(B17,B18))
A21: 三、运费（自动）
A22: 首重重量 | B22: =IF(B12="","",INDEX(跨越费率!$D$4:$D$300,B12))
A23: 首重价格 | B23: =IF(B12="","",INDEX(跨越费率!$E$4:$E$300,B12))
A24: 段位置idx | B24: =IF(OR(B19="",B4=""),"",IF(B4="次日达",MATCH(B19,$B$26:$J$26,1),MATCH(B19,$B$27:$J$27,1)))
A25: 段单价 | B25: =IF(OR(B12="",B24=""),"",INDEX(跨越费率!$H$4:$P$300,B12,B24))
A26: 次日达段下限 | B26: 1 | C26: 10 | D26: 30 | E26: 50 | F26: 100 | G26: 300 | H26: 500 | I26: 1000 | J26: 2000
A27: 特惠段下限 | B27: 1 | C27: 50 | D27: 100 | E27: 200 | F27: 300 | G27: 500 | H27: 1000 | I27: 2000 | J27: 0
A28: 最低收费 | B28: =IF(B12="","",INDEX(跨越费率!$G$4:$G$300,B12))
A29: 单票运费 | B29: =IF(OR(B23="",B19="",B25="",B28=""),"",MAX(B23+(B19-B22)*B25,B28))
A30: 声明价值(元/票) | B30: =报价汇总!B25
A31: 保费(可选) | B31: =IF(参数!$B$39="是",IF(NOT(ISNUMBER(B30)),"",MAX(参数!$B$37*B30,参数!$B$38)),0)
A32: 单票运费合计 | B32: =IF(OR(B29="",B31=""),"",B29+B31)
A33: 单台运费(元/件) | B33: =IF(OR(B32="",B6="",B6=0),"",B32/B6)
A35: 运费口径：计费重量=MAX(实重,体积重)；体积重=箱体积(㎝³)/体积系数；运费=首重价格+(计费重量-首重重量)×段单价，最低不低于最低收费。
A36: 目的地需与所选物流产品匹配：次日达与特惠普运的目的地划分不同，选错时本表运费显示空白。
