Workbook

Sheet 使用说明
A1: 产品成本测算报价表 · 使用说明
A3: 怎么用 | B3: 首页【报价汇总】只填：产品信息、成品尺寸与单台净重、每箱件数、是否含整托、物流产品、目的地、每票件数。包装费与运费全部自动算。
A4: 包装费 | B4: 按【成品最大边长】自动匹配缓冲厚度与纸箱瓦楞档位，算出单件内包装费；勾选含整托则叠加托盘分摊。费率在《参数》页改。
A5: 运费 | B5: 依据《跨越费率》（源自青岛国创VIP报价表）按 实重/体积重取大→起重→分段单价 计算单票运费，再摊到单件。目的地在首页下拉选择，产品可选次日达/特惠普运。
A6: 物料明细/加工及工装 | B6: 沿用原模板，硬件/结构件/辅助材料与加工费、工装分摊在此填写。
A7: 成本与报价 | B7: 总成本=材料+加工+工装+包装+运费+利润；建议报价=总成本/(1-目标毛利率)。毛利率/税率在《参数》页改。
A8: 注意 | B8: 跨越费率为参考价，可在《跨越费率》页直接改；金额默认不含税；EPE按全包覆估算偏保守。

Sheet 报价汇总
A1: 产品成本测算报价表（包装费 + 运费自动计算）
A3: 一、产品基础信息（输入）
A4: 产品代码 | Z4: 福州市/厦门市/泉州市
A5: 产品名称 | Z5: 宁德市/莆田市/漳州市
A6: 客户名称 | Z6: 龙岩市/三明市/南平市
A7: 报价日期 | B7: =TODAY() -> 46307 | Z7: 拉萨市
A8: 年需求量(PCS) | Z8: 日喀则市/山南市/林芝市/昌都市/那曲市/阿里地区
A9: MOQ(PCS) | Z9: 贵阳市/遵义市/安顺市
A10: 备注 | Z10: 黔南布依族苗族自治州/黔东南苗族侗族自治州/铜仁市/毕节市/六盘水市/黔西南布依族苗族自治州
Z11: 广州市/深圳市/珠海市/中山市/东莞市
A12: 二、产品规格（输入，驱动包装费） | Z12: 江门市/惠州市/佛山市/肇庆市
A13: 成品长(mm,含散热器) | Z13: 汕尾市/阳江市/揭阳市/茂名市/韶关市/梅州市/汕头市/湛江市/河源市/清远市/云浮市/潮州市
A14: 成品宽(mm) | Z14: 武汉市/鄂州市
A15: 成品高(mm) | Z15: 襄阳市/孝感市/黄石市/荆州市/宜昌市/神农架林区/十堰市/随州市/荆门市
A16: 单台净重(kg) | Z16: 黄冈市/咸宁市/恩施土家族苗族自治州/潜江市/仙桃市/天门市
A17: 每箱件数N | Z17: 株洲市/长沙市/湘潭市
A18: 是否含整托分摊 | Z18: 益阳市
Z19: 岳阳市/衡阳市/郴州市/常德市/娄底市/邵阳市/湘西土家族苗族自治州/张家界市/怀化市/永州市
A20: 三、物流（输入，驱动运费） | Z20: 重庆市
A21: 物流产品 | Z21: 成都市/资阳市/眉山市
A22: 目的地 | Z22: 绵阳市
A23: 每票件数M | Z23: 自贡市/南充市/达州市/遂宁市/广安市/巴中市/泸州市/宜宾市/内江市/乐山市/雅安市/德阳市/广元市
A24: 声明价值(元/票,可选) | Z24: 攀枝花市/凉山彝族自治州/甘孜藏族自治州/阿坝藏族羌族自治州
A25: 注 | B25: 次日达与特惠普运的目的地划分不同，请选择与所选产品一致的目的地；选错该运费显示空白。 | Z25: 合肥市/芜湖市/马鞍山市
A26: 四、成本构成（未税/单台，自动计算） | Z26: 滁州市/蚌埠市/六安市
A27: 成本项目 | B27: 金额 | C27: 单位 | D27: 备注 | E27: 公式 | Z27: 淮南市/安庆市/宿州市/亳州市/阜阳市/黄山市/淮北市/铜陵市/宣城市/池州市
A28: 硬件材料 | B28: =SUMIFS(物料明细!$H:$H,物料明细!$B:$B,"硬件") -> 0.322728 | C28: 元/台 | D28: 物料明细 | Z28: 乌鲁木齐市
A29: 结构件 | B29: =SUMIFS(物料明细!$H:$H,物料明细!$B:$B,"结构件") -> 0 | C29: 元/台 | D29: 物料明细 | Z29: 塔城地区/白杨市/新星市/哈密市/昆玉市/和田地区/北屯市/阿勒泰地区/克孜勒苏柯尔克孜自治州/双河市/博尔塔拉蒙古自治州/克拉玛依市/胡杨河市/石河子市/五家渠市/昌吉回族自治州/吐鲁番市/巴音郭楞蒙古自治州/铁门关市/阿克苏地区/阿拉尔市/图木舒克市/喀什地区/伊犁哈萨克自治州/可克达拉市
A30: 包装材料 | B30: =包装计算!$B$32+IF($B$18="是",包装计算!$B$38,0) -> 0.1288 | C30: 元/台 | D30: 包装计算（自动） | Z30: 南京市/无锡市/苏州市/常州市
A31: 辅助材料 | B31: =SUMIFS(物料明细!$H:$H,物料明细!$B:$B,"辅助材料") -> 0 | C31: 元/台 | D31: 物料明细 | Z31: 镇江市/南通市/扬州市
A32: 加工费 | B32: =加工及工装!F13 -> 0.12 | C32: 元/台 | D32: 加工及工装 | Z32: 盐城市/徐州市/淮安市/连云港市/泰州市/宿迁市
A33: 工装分摊 | B33: =加工及工装!H23 -> 0.042 | C33: 元/台 | D33: 加工及工装 | Z33: 天津市
A34: 运费 | B34: =运费计算!$B$33 | C34: 元/台 | D34: 运费计算（跨越费率） | Z34: 长春市
A35: 利润 | B35: =SUM(B28:B34)*0.15 -> 0.0920292 | C35: 元/台 | D35: 工厂利润 | Z35: 吉林市
A36: 总成本未税 | B36: =SUM(B28:B35) -> 0.7055572 | C36: 元/台 | D36: 自动汇总 | Z36: 延边朝鲜族自治州/四平市/通化市/白城市/辽源市/松原市/白山市
Z37: 银川市
A38: 五、自动报价结果 | Z38: 石嘴山市/吴忠市/固原市/中卫市
A39: 报价项目 | B39: 结果 | C39: 单位 | D39: 备注 | E39: 公式 | Z39: 石家庄市/廊坊市
A40: 目标毛利率 | B40: =参数!B4 -> 0.15 | C40: % | D40: 参数页可改 | Z40: 邯郸市/保定市/雄安新区/唐山市/沧州市/秦皇岛市
A41: 建议报价未税 | B41: =IFERROR(B36/(1-B40),0) -> 0.83006729 | C41: 元/台 | D41: 总成本/(1-毛利率) | Z41: 张家口市/承德市/衡水市/邢台市
...

Sheet 物料明细
A1: 物料明细
A2: 序号 | B2: 物料分类 | C2: 物料编码 | D2: 物料名称规格 | E2: 单机用量 | F2: 未税单价 | G2: 损耗率 | H2: 金额 | I2: 是否客供 | J2: 备注
A3: =IF(C3<>"",ROW()-2,"") -> 1 | B3: 硬件 | C3: IC001 | D3: 电源管理IC TO252 | E3: 1 | F3: 0.314 | G3: 0.02 | H3: =IF(I3="是",0,E3*F3*(1+G3)) -> 0.32028
A4: =IF(C4<>"",ROW()-2,"") -> 2 | B4: 硬件 | C4: R001 | D4: 片式电阻04021kΩ | E4: 2 | F4: 0.0012 | G4: 0.02 | H4: =IF(I4="是",0,E4*F4*(1+G4)) -> 0.002448
A5: =IF(C5<>"",ROW()-2,"") -> 3 | B5: 包装材料 | C5: PKG001 | D5: 纸箱670×387×406 | E5: 1 | F5: 7.15 | G5: 0 | H5: =IF(I5="是",0,E5*F5*(1+G5)) -> 7.15
A6: =IF(C6<>"",ROW()-2,"") -> 4 | B6: 客供料 | C6: CUST001 | D6: 客户提供物料 | E6: 1 | F6: 2.5 | G6: 0 | H6: =IF(I6="是",0,E6*F6*(1+G6)) -> 0 | I6: 是 | J6: 客供不计入报价
A7: =IF(C7<>"",ROW()-2,"") | H7: =IF(I7="是",0,E7*F7*(1+G7)) -> 0
A8: =IF(C8<>"",ROW()-2,"") | H8: =IF(I8="是",0,E8*F8*(1+G8)) -> 0
A9: =IF(C9<>"",ROW()-2,"") | H9: =IF(I9="是",0,E9*F9*(1+G9)) -> 0
A10: =IF(C10<>"",ROW()-2,"") | H10: =IF(I10="是",0,E10*F10*(1+G10)) -> 0
A11: =IF(C11<>"",ROW()-2,"") | H11: =IF(I11="是",0,E11*F11*(1+G11)) -> 0
A12: =IF(C12<>"",ROW()-2,"") | H12: =IF(I12="是",0,E12*F12*(1+G12)) -> 0
A13: =IF(C13<>"",ROW()-2,"") | H13: =IF(I13="是",0,E13*F13*(1+G13)) -> 0
A14: =IF(C14<>"",ROW()-2,"") | H14: =IF(I14="是",0,E14*F14*(1+G14)) -> 0
A15: =IF(C15<>"",ROW()-2,"") | H15: =IF(I15="是",0,E15*F15*(1+G15)) -> 0
A16: =IF(C16<>"",ROW()-2,"") | H16: =IF(I16="是",0,E16*F16*(1+G16)) -> 0
A17: =IF(C17<>"",ROW()-2,"") | H17: =IF(I17="是",0,E17*F17*(1+G17)) -> 0
A18: =IF(C18<>"",ROW()-2,"") | H18: =IF(I18="是",0,E18*F18*(1+G18)) -> 0
... A102: =IF(C102<>"",ROW()-2,"") | H102: =IF(I102="是",0,E102*F102*(1+G102)) -> 0

Sheet 加工及工装
A1: 加工费及工装治具
A3: 一、加工费
A4: 类型 | B4: 工序名称 | C4: 数量/点数 | D4: 单价 | E4: 确认 | F4: 费用 | G4: 内部成本 | H4: 差异
A5: SMT | B5: 0402/0603贴片 | C5: 0 | D5: 0.0056 | E5: 是 | F5: =IF(E5="是",IFERROR(C5*D5,0),0) -> 0 | H5: =IFERROR(F5-G5,0) -> 0
A6: AI | B6: 机插 | C6: 0 | D6: 0.0171 | E6: 是 | F6: =IF(E6="是",IFERROR(C6*D6,0),0) -> 0 | H6: =IFERROR(F6-G6,0) -> 0
A7: DIP | B7: DIP焊接 | C7: 0 | D7: 0.025 | E7: 是 | F7: =IF(E7="是",IFERROR(C7*D7,0),0) -> 0 | H7: =IFERROR(F7-G7,0) -> 0
A8: 组装 | B8: 装配人工 | C8: 0 | D8: 0 | E8: 是 | F8: =IF(E8="是",IFERROR(C8*D8,0),0) -> 0 | H8: =IFERROR(F8-G8,0) -> 0
A9: 测试 | B9: FCT/ICT | C9: 0 | D9: 0 | E9: 是 | F9: =IF(E9="是",IFERROR(C9*D9,0),0) -> 0 | H9: =IFERROR(F9-G9,0) -> 0
A10: 包装 | B10: 包装人工 | C10: 1 | D10: 0 | E10: 是 | F10: =IF(E10="是",IFERROR(C10*D10,0),0) -> 0 | H10: =IFERROR(F10-G10,0) -> 0
A11: 物流 | B11: 物流费用 | C11: 1 | D11: 0.12 | E11: 是 | F11: =IF(E11="是",IFERROR(C11*D11,0),0) -> 0.12 | H11: =IFERROR(F11-G11,0) -> 0.12
F12: =IF(E12="是",IFERROR(C12*D12,0),0) -> 0 | H12: =IFERROR(F12-G12,0) -> 0
E13: 加工费小计 | F13: =SUM(F5:F12) -> 0.12 | G13: =SUM(G5:G12) -> 0
A16: 二、工装治具
A17: 类型 | B17: 治具名称 | C17: 数量 | D17: 单价 | E17: 总价 | F17: 确认 | G17: 分摊数量 | H17: 单台分摊
A18: 钢网 | B18: SMT钢网 | C18: 1 | D18: 210 | E18: =IFERROR(C18*D18,0) -> 210 | F18: 是 | G18: 5000 | H18: =IF(F18="是",IFERROR(E18/G18,0),0) -> 0.042
A19: 测试工装 | B19: FCT测试工装 | C19: 0 | D19: 4500 | E19: =IFERROR(C19*D19,0) -> 0 | F19: 否 | G19: 5000 | H19: =IF(F19="是",IFERROR(E19/G19,0),0) -> 0
A20: 模具 | B20: 注塑模具 | C20: 0 | D20: 0 | E20: =IFERROR(C20*D20,0) -> 0 | F20: 否 | G20: 5000 | H20: =IF(F20="是",IFERROR(E20/G20,0),0) -> 0
A21: 其他 | B21: 其他一次性费用 | C21: 0 | D21: 0 | E21: =IFERROR(C21*D21,0) -> 0 | F21: 否 | G21: 5000 | H21: =IF(F21="是",IFERROR(E21/G21,0),0) -> 0
E22: =IFERROR(C22*D22,0) -> 0 | H22: =IF(F22="是",IFERROR(E22/G22,0),0) -> 0
E23: =SUM(E18:E22) -> 210 | H23: =SUM(H18:H22) -> 0.042

Sheet 参数
A1: 参数设置
A2: 参数项 | B2: 参数值 | C2: 说明
A3: 税率 | B3: 0.13 | C3: 增值税率，默认13%
A4: 目标毛利率 | B4: 0.15 | C4: 报价目标毛利率
A5: 默认损耗率 | B5: 0.02 | C5: 物料未填损耗率时使用
A6: 默认分摊数量 | B6: 5000 | C6: 工装治具费用默认分摊数量
A8: 二、包装与整托参数
A9: 参数项 | B9: 参数值 | C9: 单位 | D9: 说明
A10: 防静电袋单价 | B10: 8 | C10: 元/㎡
A11: 防静电袋单边余量 | B11: 30 | C11: mm
A12: 干燥剂单价 | B12: 0.1 | C12: 元/袋
A13: 湿度指示卡单价 | B13: 0.3 | C13: 元/张
A14: EPE珍珠棉单价 | B14: 1800 | C14: 元/m³
A15: EPE珍珠棉密度 | B15: 22 | C15: kg/m³
A16: 单瓦楞3层纸板 | B16: 2 | C16: 元/㎡
A17: 双瓦楞5层纸板 | B17: 3.2 | C17: 元/㎡
A18: 重型7层纸板 | B18: 5 | C18: 元/㎡
A19: 双瓦楞纸板克重 | B19: 700 | C19: g/㎡
A20: 纸箱制箱加工费 | B20: 1.5 | C20: 元/个
A21: 材料损耗率 | B21: 0.05 | C21: 比例
... A32: 每托层数 | B32: 4 | C32: 层
A34: 三、物流参数
A35: 参数项 | B35: 参数值 | C35: 单位 | D35: 说明
A36: 体积重系数 | B36: 6000 | C36: ㎝³/kg
A37: 保费费率 | B37: 0.004 | C37: ‰即0.4%
A38: 保费最低收费 | B38: 5 | C38: 元/票
A39: 是否计保费 | B39: 否 | C39: 是/否

Sheet 包装计算
A1: 包装费计算（自动，成品尺寸→单件包装费）
A3: 输入（自动取自报价汇总）
A4: 成品长(mm) | B4: =报价汇总!B13 -> 0
A5: 成品宽(mm) | B5: =报价汇总!B14 -> 0
A6: 成品高(mm) | B6: =报价汇总!B15 -> 0
A7: 每箱件数N | B7: =报价汇总!B17 -> 0
A8: 是否含整托 | B8: =报价汇总!B18 -> 0
A9: 成品最大边长(mm) | B9: =MAX(B4:B6) -> 0
A10: 包装几何（自动）
A11: 推荐缓冲厚度t(mm) | B11: =VLOOKUP($B$9,$A$44:$D$47,3,TRUE) -> 15
A12: 箱内长(mm) | B12: =B4+2*B11+参数!$B$22 -> 40
A13: 箱内宽(mm) | B13: =B5+2*B11+参数!$B$22 -> 40
A14: 箱内高(mm) | B14: =B7*(B6+2*B11)+参数!$B$22 -> 10
A15: 单箱体积(㎝³) | B15: =B12*B13*B14/1000 -> 16
A16: 内包装费用（单件）
A17: ESD袋长(mm) | B17: =B4+B6+2*参数!$B$11 -> 60
A18: ESD袋宽(mm) | B18: =B5+B6+2*参数!$B$11 -> 60
A19: ESD袋面积(㎡) | B19: =B17*B18/10^6 -> 0.0036
A20: ESD袋费(元/件) | B20: =B19*参数!$B$10 -> 0.0288
A21: 干燥剂费(元/件) | B21: =参数!$B$12 -> 0.1
A22: 湿度卡费(元/件) | B22: =IF(OR(B7="",B7=0),"",参数!$B$13/B7)
A23: 缓冲体积(㎥/件) | B23: =2*B11*(B4*B5+B4*B6+B5*B6)/10^9 -> 0
A24: 缓冲费(元/件) | B24: =B23*参数!$B$14 -> 0
A25: 纸箱用纸面积(㎡) | B25: =(B12+B13)*2*(B13+2*B14)/10^6*(1+参数!$B$21) -> 0.01008
A26: 瓦楞类型 | B26: =VLOOKUP($B$9,$A$44:$D$47,4,TRUE) -> 单瓦楞3层
A27: 纸板单价(元/㎡) | B27: =VLOOKUP(B26,$A$51:$B$53,2,FALSE) -> 2
A28: 纸箱费(元/箱) | B28: =B25*B27+参数!$B$20 -> 1.52016
A29: 纸箱费(元/件) | B29: =IF(OR(B7="",B7=0),"",B28/B7)
A30: 辅料费(元/件) | B30: =IF(OR(B7="",B7=0),"",(参数!$B$23+参数!$B$24)/B7)
A32: 内包装单件费(元) | B32: =SUM(B20,B21,B22,B24,B29,B30) -> 0.1288
A34: 整托分摊（可选）
A35: 每箱占地(㎡) | B35: =B12*B13/10^6 -> 0.0016
A36: 每托件数(件) | B36: =IF(OR(B35="",B35=0),"",ROUNDDOWN(参数!$B$31/B35,0)*参数!$B$32) -> 2748
A37: 每托包装费(元/托) | B37: =参数!$B$25/参数!$B$26+参数!$B$27*参数!$B$28+参数!$B$29+参数!$B$30 -> 27.2
A38: 整托分摊(元/件) | B38: =IF(NOT(ISNUMBER(B36)),"",B37/B36) -> 0.0098981077
A39: 包装增重(kg/件) | B39: =IF(OR(B7="",B7=0),"",(B23*参数!$B$15+B25*参数!$B$19/1000+B19*0.08+0.005)/B7)
A42: 包装档位表（自动匹配，按成品最大边长）
A43: 下限mm | B43: 上限mm | C43: 推荐缓冲厚度mm | D43: 推荐瓦楞
A44: 0 | B44: 200 | C44: 15 | D44: 单瓦楞3层
A45: 200 | B45: 350 | C45: 20 | D45: 双瓦楞5层
...

Sheet 跨越费率
A1: 跨越VIP运费费率（源自青岛国创VIP报价表，可按需改价）
A3: 产品 | B3: 目的省份 | C3: 目的地 | D3: 首重重量 | E3: 首重价格 | F3: 起重 | G3: 最低收费 | H3: 段1单价 | I3: 段2单价 | J3: 段3单价 | K3: 段4单价 | L3: 段5单价 | M3: 段6单价 | N3: 段7单价 | O3: 段8单价 | P3: 段9单价 | Q3: 匹配键
A4: 次日达 | B4: 福建省 | C4: 福州市/厦门市/泉州市 | D4: 1 | E4: 20 | F4: 30 | G4: 255 | H4: 8.1 | I4: 8.1 | J4: 8.1 | K4: 8.1 | L4: 7.2 | M4: 6.3 | N4: 6.3 | O4: 6.3 | P4: 6.3 | Q4: 次日达|福州市/厦门市/泉州市
A5: 次日达 | C5: 宁德市/莆田市/漳州市 | D5: 1 | E5: 20 | F5: 30 | G5: 255 | H5: 8.1 | I5: 8.1 | J5: 8.1 | K5: 8.1 | L5: 7.2 | M5: 6.3 | N5: 6.3 | O5: 6.3 | P5: 6.3 | Q5: 次日达|宁德市/莆田市/漳州市
A6: 次日达 | C6: 龙岩市/三明市/南平市 | D6: 1 | E6: 20 | F6: 30 | G6: 255 | H6: 8.1 | I6: 8.1 | J6: 8.1 | K6: 8.1 | L6: 7.2 | M6: 6.3 | N6: 6.3 | O6: 6.3 | P6: 6.3 | Q6: 次日达|龙岩市/三明市/南平市
A7: 次日达 | B7: 西藏自治区 | C7: 拉萨市 | D7: 1 | E7: 20 | F7: 30 | G7: 542 | H7: 18 | I7: 18 | J7: 18 | K7: 18 | L7: 18 | M7: 18 | N7: 18 | O7: 18 | P7: 18 | Q7: 次日达|拉萨市
A8: 次日达 | C8: 日喀则市/山南市/林芝市/昌都市/那曲市/阿里地区 | D8: 1 | E8: 25 | F8: 30 | G8: 678 | H8: 22.5 | I8: 22.5 | J8: 22.5 | K8: 22.5 | L8: 22.5 | M8: 22.5 | N8: 22.5 | O8: 22.5 | P8: 22.5 | Q8: 次日达|日喀则市/山南市/林芝市/昌都市/那曲市/阿里地区
A9: 次日达 | B9: 贵州省 | C9: 贵阳市/遵义市/安顺市 | D9: 1 | E9: 20 | F9: 30 | G9: 307 | H9: 9.9 | I9: 9.9 | J9: 9.9 | K9: 9 | L9: 9 | M9: 8.1 | N9: 8.1 | O9: 8.1 | P9: 8.1 | Q9: 次日达|贵阳市/遵义市/安顺市
A10: 次日达 | C10: 黔南布依族苗族自治州/黔东南苗族侗族自治州/铜仁市/毕节市/六盘水市/黔西南布依族苗族自治州 | D10: 1 | E10: 20 | F10: 30 | G10: 307 | H10: 9.9 | I10: 9.9 | J10: 9.9 | K10: 9 | L10: 9 | M10: 8.1 | N10: 8.1 | O10: 8.1 | P10: 8.1 | Q10: 次日达|黔南布依族苗族自治州/黔东南苗族侗族自治州/铜仁市/毕节市/六盘水市/黔西南布依族苗族自治州
A11: 次日达 | B11: 广东省 | C11: 广州市/深圳市/珠海市/中山市/东莞市 | D11: 1 | E11: 20 | F11: 15 | G11: 171 | H11: 10.8 | I11: 10.8 | J11: 10.8 | K11: 9.9 | L11: 9 | M11: 8.1 | N11: 8.1 | O11: 8.1 | P11: 8.1 | Q11: 次日达|广州市/深圳市/珠海市/中山市/东莞市
A12: 次日达 | C12: 江门市/惠州市/佛山市/肇庆市 | D12: 1 | E12: 20 | F12: 15 | G12: 171 | H12: 10.8 | I12: 10.8 | J12: 10.8 | K12: 9.9 | L12: 9 | M12: 8.1 | N12: 8.1 | O12: 8.1 | P12: 8.1 | Q12: 次日达|江门市/惠州市/佛山市/肇庆市
A13: 次日达 | C13: 汕尾市/阳江市/揭阳市/茂名市/韶关市/梅州市/汕头市/湛江市/河源市/清远市/云浮市/潮州市 | D13: 1 | E13: 20 | F13: 15 | G13: 171 | H13: 10.8 | I13: 10.8 | J13: 10.8 | K13: 9.9 | L13: 9 | M13: 8.1 | N13: 8.1 | O13: 8.1 | P13: 8.1 | Q13: 次日达|汕尾市/阳江市/揭阳市/茂名市/韶关市/梅州市/汕头市/湛江市/河源市/清远市/云浮市/潮州市
A14: 次日达 | B14: 湖北省 | C14: 武汉市/鄂州市 | D14: 1 | E14: 20 | F14: 30 | G14: 255 | H14: 8.1 | I14: 8.1 | J14: 8.1 | K14: 8.1 | L14: 7.2 | M14: 6.3 | N14: 6.3 | O14: 6.3 | P14: 6.3 | Q14: 次日达|武汉市/鄂州市
A15: 次日达 | C15: 襄阳市/孝感市/黄石市/荆州市/宜昌市/神农架林区/十堰市/随州市/荆门市 | D15: 1 | E15: 20 | F15: 30 | G15: 255 | H15: 8.1 | I15: 8.1 | J15: 8.1 | K15: 8.1 | L15: 7.2 | M15: 6.3 | N15: 6.3 | O15: 6.3 | P15: 6.3 | Q15: 次日达|襄阳市/孝感市/黄石市/荆州市/宜昌市/神农架林区/十堰市/随州市/荆门市
A16: 次日达 | C16: 黄冈市/咸宁市/恩施土家族苗族自治州/潜江市/仙桃市/天门市 | D16: 1 | E16: 20 | F16: 30 | G16: 307 | H16: 9.9 | I16: 9.9 | J16: 9.9 | K16: 9.9 | L16: 9 | M16: 8.1 | N16: 8.1 | O16: 8.1 | P16: 8.1 | Q16: 次日达|黄冈市/咸宁市/恩施土家族苗族自治州/潜江市/仙桃市/天门市
A17: 次日达 | B17: 湖南省 | C17: 株洲市/长沙市/湘潭市 | D17: 1 | E17: 20 | F17: 30 | G17: 255 | H17: 8.1 | I17: 8.1 | J17: 8.1 | K17: 8.1 | L17: 7.2 | M17: 6.3 | N17: 6.3 | O17: 6.3 | P17: 6.3 | Q17: 次日达|株洲市/长沙市/湘潭市
A18: 次日达 | C18: 益阳市 | D18: 1 | E18: 20 | F18: 30 | G18: 255 | H18: 8.1 | I18: 8.1 | J18: 8.1 | K18: 8.1 | L18: 7.2 | M18: 6.3 | N18: 6.3 | O18: 6.3 | P18: 6.3 | Q18: 次日达|益阳市
A19: 次日达 | C19: 岳阳市/衡阳市/郴州市/常德市/娄底市/邵阳市/湘西土家族苗族自治州/张家界市/怀化市/永州市 | D19: 1 | E19: 20 | F19: 30 | G19: 307 | H19: 9.9 | I19: 9.9 | J19: 9.9 | K19: 9.9 | L19: 9 | M19: 8.1 | N19: 8.1 | O19: 8.1 | P19: 8.1 | Q19: 次日达|岳阳市/衡阳市/郴州市/常德市/娄底市/邵阳市/湘西土家族苗族自治州/张家界市/怀化市/永州市
A20: 次日达 | B20: 重庆 | C20: 重庆市 | D20: 1 | E20: 20 | F20: 30 | G20: 255 | H20: 8.1 | I20: 8.1 | J20: 8.1 | K20: 8.1 | L20: 7.2 | M20: 7.2 | N20: 7.2 | O20: 7.2 | P20: 7.2 | Q20: 次日达|重庆市
A21: 次日达 | B21: 四川省 | C21: 成都市/资阳市/眉山市 | D21: 1 | E21: 20 | F21: 30 | G21: 255 | H21: 8.1 | I21: 8.1 | J21: 8.1 | K21: 8.1 | L21: 7.2 | M21: 7.2 | N21: 7.2 | O21: 7.2 | P21: 7.2 | Q21: 次日达|成都市/资阳市/眉山市
A22: 次日达 | C22: 绵阳市 | D22: 1 | E22: 20 | F22: 30 | G22: 255 | H22: 8.1 | I22: 8.1 | J22: 8.1 | K22: 8.1 | L22: 7.2 | M22: 7.2 | N22: 7.2 | O22: 7.2 | P22: 7.2 | Q22: 次日达|绵阳市
A23: 次日达 | C23: 自贡市/南充市/达州市/遂宁市/广安市/巴中市/泸州市/宜宾市/内江市/乐山市/雅安市/德阳市/广元市 | D23: 1 | E23: 20 | F23: 30 | G23: 307 | H23: 9.9 | I23: 9.9 | J23: 9.9 | K23: 9.9 | L23: 9 | M23: 9 | N23: 9 | O23: 9 | P23: 9 | Q23: 次日达|自贡市/南充市/达州市/遂宁市/广安市/巴中市/泸州市/宜宾市/内江市/乐山市/雅安市/德阳市/广元市
A24: 次日达 | C24: 攀枝花市/凉山彝族自治州/甘孜藏族自治州/阿坝藏族羌族自治州 | D24: 1 | E24: 20 | F24: 30 | G24: 385 | H24: 12.6 | I24: 12.6 | J24: 12.6 | K24: 12.6 | L24: 11.7 | M24: 11.7 | N24: 11.7 | O24: 11.7 | P24: 11.7 | Q24: 次日达|攀枝花市/凉山彝族自治州/甘孜藏族自治州/阿坝藏族羌族自治州
A25: 次日达 | B25: 安徽省 | C25: 合肥市/芜湖市/马鞍山市 | D25: 1 | E25: 20 | F25: 30 | G25: 255 | H25: 8.1 | I25: 8.1 | J25: 8.1 | K25: 8.1 | L25: 7.2 | M25: 6.3 | N25: 6.3 | O25: 6.3 | P25: 6.3 | Q25: 次日达|合肥市/芜湖市/马鞍山市
A26: 次日达 | C26: 滁州市/蚌埠市/六安市 | D26: 1 | E26: 20 | F26: 30 | G26: 281 | H26: 9 | I26: 9 | J26: 9 | K26: 9 | L26: 8.1 | M26: 7.2 | N26: 7.2 | O26: 7.2 | P26: 7.2 | Q26: 次日达|滁州市/蚌埠市/六安市
A27: 次日达 | C27: 淮南市/安庆市/宿州市/亳州市/阜阳市/黄山市/淮北市/铜陵市/宣城市/池州市 | D27: 1 | E27: 20 | F27: 30 | G27: 307 | H27: 9.9 | I27: 9.9 | J27: 9.9 | K27: 9.9 | L27: 9 | M27: 8.1 | N27: 8.1 | O27: 8.1 | P27: 8.1 | Q27: 次日达|淮南市/安庆市/宿州市/亳州市/阜阳市/黄山市/淮北市/铜陵市/宣城市/池州市
A28: 次日达 | B28: 新疆维吾尔自治区 | C28: 乌鲁木齐市 | D28: 1 | E28: 20 | F28: 30 | G28: 542 | H28: 18 | I28: 18 | J28: 18 | K28: 18 | L28: 18 | M28: 18 | N28: 18 | O28: 18 | P28: 18 | Q28: 次日达|乌鲁木齐市
A29: 次日达 | C29: 塔城地区/白杨市/新星市/哈密市/昆玉市/和田地区/北屯市/阿勒泰地区/克孜勒苏柯尔克孜自治州/双河市/博尔塔拉蒙古自治州/克拉玛依市/胡杨河市/石河子市/五家渠市/昌吉回族自治州/吐鲁番市/巴音郭楞蒙古自治州/铁门关市/阿克苏地区/阿拉尔市/图木舒克市/喀什地区/伊犁哈萨克自治州/可克达拉市 | D29: 1 | E29: 25 | F29: 30 | G29: 678 | H29: 22.5 | I29: 22.5 | J29: 22.5 | K29: 22.5 | L29: 22.5 | M29: 22.5 | N29: 22.5 | O29: 22.5 | P29: 22.5 | Q29: 次日达|塔城地区/白杨市/新星市/哈密市/昆玉市/和田地区/北屯市/阿勒泰地区/克孜勒苏柯尔克孜自治州/双河市/博尔塔拉蒙古自治州/克拉玛依市/胡杨河市/石河子市/五家渠市/昌吉回族自治州/吐鲁番市/巴音郭楞蒙古自治州/铁门关市/阿克苏地区/阿拉尔市/图木舒克市/喀什地区/伊犁哈萨克自治州/可克达拉市
A30: 次日达 | B30: 江苏省 | C30: 南京市/无锡市/苏州市/常州市 | D30: 1 | E30: 20 | F30: 15 | G30: 133 | H30: 8.1 | I30: 8.1 | J30: 8.1 | K30: 7.2 | L30: 6.3 | M30: 6.3 | N30: 6.3 | O30: 6.3 | P30: 6.3 | Q30: 次日达|南京市/无锡市/苏州市/常州市
A31: 次日达 | C31: 镇江市/南通市/扬州市 | D31: 1 | E31: 20 | F31: 15 | G31: 133 | H31: 8.1 | I31: 8.1 | J31: 8.1 | K31: 7.2 | L31: 6.3 | M31: 6.3 | N31: 6.3 | O31: 6.3 | P31: 6.3 | Q31: 次日达|镇江市/南通市/扬州市
A32: 次日达 | C32: 盐城市/徐州市/淮安市/连云港市/泰州市/宿迁市 | D32: 1 | E32: 20 | F32: 15 | G32: 133 | H32: 8.1 | I32: 8.1 | J32: 8.1 | K32: 7.2 | L32: 6.3 | M32: 6.3 | N32: 6.3 | O32: 6.3 | P32: 6.3 | Q32: 次日达|盐城市/徐州市/淮安市/连云港市/泰州市/宿迁市
A33: 次日达 | B33: 天津 | C33: 天津市 | D33: 1 | E33: 20 | F33: 20 | G33: 157 | H33: 7.2 | I33: 7.2 | J33: 7.2 | K33: 7.2 | L33: 6.3 | M33: 6.3 | N33: 6.3 | O33: 6.3 | P33: 6.3 | Q33: 次日达|天津市
A34: 次日达 | B34: 吉林省 | C34: 长春市 | D34: 1 | E34: 20 | F34: 30 | G34: 333 | H34: 10.8 | I34: 10.8 | J34: 10.8 | K34: 9.9 | L34: 9.9 | M34: 9 | N34: 9 | O34: 9 | P34: 9 | Q34: 次日达|长春市
A35: 次日达 | C35: 吉林市 | D35: 1 | E35: 20 | F35: 30 | G35: 359 | H35: 11.7 | I35: 11.7 | J35: 11.7 | K35: 10.8 | L35: 10.8 | M35: 9.9 | N35: 9.9 | O35: 9.9 | P35: 9.9 | Q35: 次日达|吉林市
A36: 次日达 | C36: 延边朝鲜族自治州/四平市/通化市/白城市/辽源市/松原市/白山市 | D36: 1 | E36: 20 | F36: 30 | G36: 412 | H36: 13.5 | I36: 13.5 | J36: 13.5 | K36: 12.6 | L36: 12.6 | M36: 11.7 | N36: 11.7 | O36: 11.7 | P36: 11.7 | Q36: 次日达|延边朝鲜族自治州/四平市/通化市/白城市/辽源市/松原市/白山市
A37: 次日达 | B37: 宁夏回族自治区 | C37: 银川市 | D37: 1 | E37: 20 | F37: 30 | G37: 490 | H37: 16.2 | I37: 16.2 | J37: 16.2 | K37: 14.4 | L37: 14.4 | M37: 14.4 | N37: 13.5 | O37: 13.5 | P37: 13.5 | Q37: 次日达|银川市
A38: 次日达 | C38: 石嘴山市/吴忠市/固原市/中卫市 | D38: 1 | E38: 20 | F38: 30 | G38: 542 | H38: 18 | I38: 18 | J38: 18 | K38: 16.2 | L38: 16.2 | M38: 16.2 | N38: 15.3 | O38: 15.3 | P38: 15.3 | Q38: 次日达|石嘴山市/吴忠市/固原市/中卫市
A39: 次日达 | B39: 河北省 | C39: 石家庄市/廊坊市 | D39: 1 | E39: 20 | F39: 30 | G39: 229 | H39: 7.2 | I39: 7.2 | J39: 7.2 | K39: 7.2 | L39: 7.2 | M39: 6.3 | N39: 6.3 | O39: 6.3 | P39: 6.3 | Q39: 次日达|石家庄市/廊坊市
A40: 次日达 | C40: 邯郸市/保定市/雄安新区/唐山市/沧州市/秦皇岛市 | D40: 1 | E40: 20 | F40: 30 | G40: 255 | H40: 8.1 | I40: 8.1 | J40: 8.1 | K40: 8.1 | L40: 8.1 | M40: 7.2 | N40: 7.2 | O40: 7.2 | P40: 7.2 | Q40: 次日达|邯郸市/保定市/雄安新区/唐山市/沧州市/秦皇岛市
A41: 次日达 | C41: 张家口市/承德市/衡水市/邢台市 | D41: 1 | E41: 20 | F41: 30 | G41: 281 | H41: 9 | I41: 9 | J41: 9 | K41: 9 | L41: 9 | M41: 8.1 | N41: 8.1 | O41: 8.1 | P41: 8.1 | Q41: 次日达|张家口市/承德市/衡水市/邢台市
...

Sheet 运费计算
A1: 运费计算（跨越费率，实重/体积重取大）
A3: 一、输入与费率定位（自动）
A4: 物流产品 | B4: =报价汇总!B21 -> 0
A5: 目的地 | B5: =报价汇总!B22 -> 0
A6: 每票件数M | B6: =报价汇总!B23 -> 0
A7: 单台毛重(kg) | B7: =IF(报价汇总!B16="","",报价汇总!B16+包装计算!$B$39)
A8: 单箱体积(㎝³) | B8: =包装计算!$B$15 -> 16
A9: 每箱件数N | B9: =报价汇总!B17 -> 0
A10: 箱数(票内) | B10: =IF(OR(B6="",B9="",B9=0),"",B6/B9)
A11: 匹配键 | B11: =IF(OR(B4="",B5=""),"",B4&"|"&B5) -> 0|0
A12: 费率行号 | B12: =IF(B11="","",IFERROR(MATCH(B11,跨越费率!$Q$4:$Q$300,0),""))
A14: 二、计费重量（自动）
A15: 单票实重(kg) | B15: =IF(OR(B7="",B6=""),"",B7*B6)
A16: 单票体积重(kg) | B16: =IF(OR(B8="",B10=""),"",B8*B10/参数!$B$36)
A17: 计费重量(kg) | B17: =IF(AND(ISNUMBER(B15),ISNUMBER(B16)),MAX(B15,B16),"")
A18: 起重(kg) | B18: =IF(B12="","",INDEX(跨越费率!$F$4:$F$300,B12))
A19: 计费重量起重后 | B19: =IF(OR(B17="",B18=""),"",MAX(B17,B18))
A21: 三、运费（自动）
A22: 首重重量 | B22: =IF(B12="","",INDEX(跨越费率!$D$4:$D$300,B12))
A23: 首重价格 | B23: =IF(B12="","",INDEX(跨越费率!$E$4:$E$300,B12))
A24: 段位置idx | B24: =IF(OR(B19="",B4=""),"",IF(B4="次日达",MATCH(B19,$B$26:$J$26,1),MATCH(B19,$B$27:$J$27,1)))
A25: 段单价 | B25: =IF(OR(B12="",B24=""),"",INDEX(跨越费率!$H$4:$P$300,B12,B24))
A26: 次日达段下限 | B26: 1 | C26: 10 | D26: 30 | E26: 50 | F26: 100 | G26: 300 | H26: 500 | I26: 1000 | J26: 2000
A27: 特惠段下限 | B27: 1 | C27: 50 | D27: 100 | E27: 200 | F27: 300 | G27: 500 | H27: 1000 | I27: 2000 | J27: 0
A28: 最低收费 | B28: =IF(B12="","",INDEX(跨越费率!$G$4:$G$300,B12))
A29: 单票运费 | B29: =IF(OR(B23="",B19="",B25="",B28=""),"",MAX(B23+(B19-B22)*B25,B28))
A30: 声明价值(元/票) | B30: =报价汇总!B24 -> 0
A31: 保费(可选) | B31: =IF(参数!$B$39="是",IF(NOT(ISNUMBER(B30)),"",MAX(参数!$B$37*B30,参数!$B$38)),0) -> 0
A32: 单票运费合计 | B32: =IF(OR(B29="",B31=""),"",B29+B31)
A33: 单台运费(元/件) | B33: =IF(OR(B32="",B6="",B6=0),"",B32/B6)
A35: 运费口径：计费重量=MAX(实重,体积重)；体积重=箱体积(㎝³)/体积系数；运费=首重价格+(计费重量-首重重量)×段单价，最低不低于最低收费。
A36: 目的地需与所选物流产品匹配：次日达与特惠普运的目的地划分不同，选错时本表运费显示空白。
