Workbook

Sheet Sheet1
A1: 厦门华联电子股份有限公司智能控制器/汽车与工控 产品报价单
A2: 产品报价申请单流程编号 | B2: 销售公司/国内销售部/汽控国内部-产品报价成本核算申请单-2025-10-0713
A3: 产品信息 | B3: 1 | C3: 产品代码 | D3: N10305002124 | E3: N10305002124
B4: 2 | C4: 产品名称 | D4: DRV-26P-NJTJ(RoHS)中央式空调控制器驱动板组件(D5A13H000000) | E4: DRV-26P-NJTJ(RoHS)中央式空调控制器驱动板组件(D5A13H000000)
B5: 3 | C5: 客户名称 | D5: 青岛国创智能家电研究院有限公司 | E5: 青岛国创智能家电研究院有限公司
B6: 4 | C6: 报价日期 | D6: 45943.74 | E6: 2026/1/8更新包装，制造降本
B7: 5 | C7: 年需求量 | D7: 5000 | E7: 5000
B8: 6 | C8: MOQ | D8: 50 | E8: 50
B9: 7 | C9: MPQ
B10: 8 | C10: 备注 | D10: 工装、模具费直接向客户收取； 已扣除8颗客供料核算成本 | E10: 工装、模具费直接向客户收取；(N10305002124与N10305002125共用) 已扣除8颗客供料核算成本
A11: 成本及费用组成 | D11: 金额 | E11: 金额
A12: 材料成本 | B12: 1 | C12: 硬件 | D12: =[1]N10305002124原材料报价单!O288 -> 358.46316 | E12: =[1]N10305002124原材料报价单!O288 -> 358.46316
B13: 2 | C13: 结构件 | D13: =[1]N10305002124原材料报价单!O321 -> 416.4798 | E13: =[1]N10305002124原材料报价单!O321 -> 416.4798
B14: 3 | C14: 包装材料 | D14: =[1]N10305002124原材料报价单!O15 -> 96.6702 | E14: =[1]N10305002124原材料报价单!O355 -> 63.7765
B15: 4 | C15: 辅助材料 | D15: =[1]N10305002124原材料报价单!M342 -> 37.854901 | E15: =[1]N10305002124原材料报价单!M375 -> 37.943115
B16: 小计 | D16: =SUM(D12:D15) -> 909.46806 | E16: =SUM(E12:E15) -> 876.66258
A17: 加工成本 | B17: 5 | C17: 贴片加工成本 | D17: 6.1656 | E17: 6.1656
B18: 6 | C18: 机插加工成本 | D18: 0.2394 | E18: 0.2394
B19: 7 | C19: 预烧写加工成本 | D19: 0 | E19: 0
B20: 8 | C20: 人工成本 | D20: 111.0501 | E20: 82.0882
B21: 9 | C21: 折旧（专用） | D21: 0.8424 | E21: 0.8424
B22: 10 | C22: 折旧（公共） | D22: 2.9761 | E22: 2.2
B23: 11 | C23: 水电（专用） | D23: 1.4745 | E23: 1.4745
B24: 12 | C24: 水电（公共） | D24: 1.9989 | E24: 1.4776
B25: 13 | C25: 工装 | D25: 0 | E25: 0
B26: 14 | C26: 低耗 | D26: 6.1522 | E26: 4.5477
B27: 15 | C27: 管理人员工资 | D27: 31.9713 | E27: 21.3676
B28: 16 | C28: 其他 | D28: 8.1511 | E28: 6.0253
B29: 17 | C29: 检验成本 | D29: 0 | E29: 0
B30: 小计 | D30: =SUM(D17:D29) -> 171.0216 | E30: =SUM(E17:E29) -> 126.4283
A31: 其他费用 | B31: 18 | C31: 工装费 | D31: =[1]N10305002124制造成本!G86 -> 48700 | E31: =[1]N10305002124制造成本!P86 -> 48700
B32: 19 | C32: 模具费 | E32: =[1]N10305002124制造成本!N111 -> 29499.115
B33: 20 | C33: 认证费/实验费
B34: 21 | C34: 硬件开发费
B35: 22 | C35: 软件开发费
B36: 23 | C36: 认证费/实验费
B37: 直接向客户收费小计 | D37: =SUM(D31:D36) -> 48700 | E37: =SUM(E31:E36) -> 78199.115
B38: 24 | C38: 分摊在产品成本中
A39: 料工费成本（合计） | D39: =SUM(D16,D30,D38) -> 1080.4897 | E39: =SUM(E16,E30,E38) -> 1003.0909
B40: 成本差异 | D40: =D39*1.35% -> 14.58661 | E40: =E39*1.35% -> 13.541727
...

Sheet 汇总情况
A1: 厦门华联电子股份有限公司智能控制器/汽车与工控 产品报价单
A2: 产品报价申请单流程编号 | B2: 销售公司/国内销售部/汽控国内部-产品报价成本核算申请单-2025-10-0713
A3: 产品信息 | B3: 1 | C3: 产品代码 | D3: N10305002124 | E3: N10305002124
B4: 2 | C4: 产品名称 | D4: DRV-26P-NJTJ(RoHS)中央式空调控制器驱动板组件(D5A13H000000) | E4: DRV-26P-NJTJ(RoHS)中央式空调控制器驱动板组件(D5A13H000000)
B5: 3 | C5: 客户名称 | D5: 青岛国创智能家电研究院有限公司 | E5: 青岛国创智能家电研究院有限公司
B6: 4 | C6: 报价日期 | D6: 45943.74 | E6: 2026/1/8更新包装，制造降本
B7: 5 | C7: 年需求量 | D7: 5000 | E7: 5000
B8: 6 | C8: MOQ | D8: 50 | E8: 50
B9: 7 | C9: MPQ
B10: 8 | C10: 备注 | D10: 工装、模具费直接向客户收取； 已扣除8颗客供料核算成本 | E10: 工装、模具费直接向客户收取；(N10305002124与N10305002125共用) 已扣除8颗客供料核算成本
A11: 成本及费用组成 | D11: 金额 | E11: 金额
A12: 材料成本 | B12: 1 | C12: 硬件 | D12: =[1]N10305002124原材料报价单!O288 -> 358.46316 | E12: =[1]N10305002124原材料报价单!O288 -> 358.46316
B13: 2 | C13: 结构件 | D13: =[1]N10305002124原材料报价单!O321 -> 416.4798 | E13: =[1]N10305002124原材料报价单!O321 -> 416.4798
B14: 3 | C14: 包装材料 | D14: =[1]N10305002124原材料报价单!O15 -> 96.6702 | E14: =[1]N10305002124原材料报价单!O355 -> 63.7765
B15: 4 | C15: 辅助材料 | D15: =[1]N10305002124原材料报价单!M342 -> 37.854901 | E15: =[1]N10305002124原材料报价单!M375 -> 37.943115
B16: 小计 | D16: =SUM(D12:D15) -> 909.46806 | E16: =SUM(E12:E15) -> 876.66258
A17: 加工成本 | B17: 5 | C17: 贴片加工成本 | D17: 6.1656 | E17: 6.1656
B18: 6 | C18: 机插加工成本 | D18: 0.2394 | E18: 0.2394
B19: 7 | C19: 预烧写加工成本 | D19: 0 | E19: 0
B20: 8 | C20: 人工成本 | D20: 111.0501 | E20: 82.0882
B21: 9 | C21: 折旧（专用） | D21: 0.8424 | E21: 0.8424
B22: 10 | C22: 折旧（公共） | D22: 2.9761 | E22: 2.2
B23: 11 | C23: 水电（专用） | D23: 1.4745 | E23: 1.4745
B24: 12 | C24: 水电（公共） | D24: 1.9989 | E24: 1.4776
B25: 13 | C25: 工装 | D25: 0 | E25: 0
B26: 14 | C26: 低耗 | D26: 6.1522 | E26: 4.5477
B27: 15 | C27: 管理人员工资 | D27: 31.9713 | E27: 21.3676
B28: 16 | C28: 其他 | D28: 8.1511 | E28: 6.0253
B29: 17 | C29: 检验成本 | D29: 0 | E29: 0
B30: 小计 | D30: =SUM(D17:D29) -> 171.0216 | E30: =SUM(E17:E29) -> 126.4283
A31: 其他费用 | B31: 18 | C31: 工装费 | D31: =[1]N10305002124制造成本!G86 -> 48700 | E31: =[1]N10305002124制造成本!P86 -> 48700
B32: 19 | C32: 模具费 | E32: =[1]N10305002124制造成本!N111 -> 29499.115
B33: 20 | C33: 认证费/实验费
B34: 21 | C34: 硬件开发费
B35: 22 | C35: 软件开发费
B36: 23 | C36: 认证费/实验费
B37: 直接向客户收费小计 | D37: =SUM(D31:D36) -> 48700 | E37: =SUM(E31:E36) -> 78199.115
B38: 24 | C38: 分摊在产品成本中
A39: 料工费成本（合计） | D39: =SUM(D16,D30,D38) -> 1080.4897 | E39: =SUM(E16,E30,E38) -> 1003.0909
B40: 成本差异 | D40: =D39*1.35% -> 14.58661 | E40: =E39*1.35% -> 13.541727
...

Sheet Sheet2
A1: 项目名称 | C1: 汽车与工控控制器-DRV-20P-NJTJ(RoHS)中央式空调控制器驱动板组件(D5A13G000000)--二次重新报价！！ | E1: 客户名称 | F1: 青岛国创智能家电研究院有限公司 | K1: 报价项目类型 | L1: 已立项产品报价 | O1: 王前良 | W1: 销售公司/国内销售部/汽控国内部
A2: 产品编码 | C2: N10305002124 | E2: 产品名称 | F2: DRV-26P-NJTJ(RoHS)中央式空调控制器驱动板组件(D5A13H000000) | K2: 硬件设计师 | L2: 李沁峰 | O2: 陈可璜 | W2: 45950
A3: 硬件 | E3: 结构件 | K3: 包装材料 | T3: 0 | X3: 0
A4: 序号 | B4: 物料类型 | C4: 物料编码 | D4: 物料名称 | E4: 物料级别 | F4: 装配形式 | G4: 单机用量 | H4: 最低价物料编码 | I4: 最低价物料名称 | J4: 采购员 | K4: 供应商代码 | L4: 供应商名称 | M4: 未税单价 | N4: 损耗率 | O4: 金额 | T4: 提前期 | U4: 最小订货量 | V4: 最小包装量 | W4: 模具费（含税13%） | X4: 价格说明 | Y4: 备注 | Z4: 位号 | AA4: 替代料编码1 | AB4: 替代料名称1 | AC4: 未税单价1 | AD4: 替代料编码2 | AE4: 替代料名称2 | AF4: 未税单价2 | AG4: 替代料编码3 | AH4: 替代料名称3 | AI4: 未税单价3
A5: 6 | B5: 包装组件 | C5: 4013430R | D5: 塑胶线夹 3.6X300 (尼龙扣)(正顺达)(RoHS) | E5: AB级替换 | F5: N/A | G5: 3 | H5: 4013430R | I5: 塑胶线夹 3.6X300 (尼龙扣)(RoHS) | J5: 沈艺聪 | K5: XMZSD | L5: 厦门正顺达电子有限公司 | M5: 0.099 | N5: 0 | O5: =G5*M5 -> 0.297 | T5: 21 | U5: 10000 | Y5: 2025-10-13包装方案
A6: 7 | B6: 包装组件 | C6: N40501000374 | D6: 纸箱 670X387X406 (RoHS) | E6: AB级替换 | F6: PKG | G6: 1 | H6: N40501000374 | I6: 纸箱 670X387X406 (RoHS) | J6: 512 | K6: 11363 | L6: 厦门比瑞特包装科技有限公司 | M6: 7.1593 | N6: 0 | O6: =G6*M6 -> 7.1593 | T6: 14 | U6: 1 | V6: 1
A7: 8 | B7: 包装组件 | C7: N40505000136 | D7: 塑料袋 355X245 (凹凸)(RoHS) | E7: AB级替换 | F7: PKG | G7: 1 | H7: N40505000136 | I7: 塑料袋 355X245 (凹凸)(RoHS) | J7: 512 | K7: 11363 | L7: 厦门比瑞特包装科技有限公司 | M7: 0.25 | N7: 0 | O7: =G7*M7 -> 0.25 | T7: 14 | U7: 1000 | V7: 1000
A8: 9 | B8: 包装组件 | C8: N40512000278 | D8: 泡沫棉 660X377X374 (泡沫盒底座)(防静电)(RoHS) | E8: AB级替换 | F8: PKG | G8: 1 | H8: N40512000278 | I8: 泡沫棉 660X377X374 (泡沫盒底座)(防静电)(RoHS) | J8: 512 | K8: 10379 | L8: 厦门市达唯工贸有限公司 | M8: 69.5575 | N8: 0 | O8: =G8*M8 -> 69.5575 | T8: 14 | U8: 1 | V8: 1
A9: 10 | B9: 包装组件 | C9: N40512000279 | D9: 泡沫棉 660X377X110 (泡沫盒上盖)(防静电)(RoHS) | E9: AB级替换 | F9: PKG | G9: 1 | H9: N40512000279 | I9: 泡沫棉 660X377X110 (泡沫盒上盖)(防静电)(RoHS) | J9: 512 | K9: 10379 | L9: 厦门市达唯工贸有限公司 | M9: 8.6726 | N9: 0 | O9: =G9*M9 -> 8.6726 | T9: 14 | U9: 1 | V9: 1
A10: 11 | B10: 包装组件 | C10: N40512000280 | D10: 泡沫棉 50X45X200 (左侧EVA棉块)(高密度)(防静电)(RoHS) | E10: AB级替换 | F10: PKG | G10: 1 | H10: N40512000280 | I10: 泡沫棉 50X45X200 (左侧EVA棉块)(高密度)(防静电)(RoHS) | J10: 512 | K10: 10379 | L10: 厦门市达唯工贸有限公司 | M10: 2.2655 | N10: 0 | O10: =G10*M10 -> 2.2655 | T10: 14 | U10: 1 | V10: 1
A11: 12 | B11: 包装组件 | C11: N40512000281 | D11: 泡沫棉 50X45X200 (右侧EVA棉块1)(高密度)(防静电)(RoHS) | E11: AB级替换 | F11: PKG | G11: 1 | H11: N40512000281 | I11: 泡沫棉 50X45X200 (右侧EVA棉块1)(高密度)(防静电)(RoHS) | J11: 512 | K11: 10379 | L11: 厦门市达唯工贸有限公司 | M11: 2.2655 | N11: 0 | O11: =G11*M11 -> 2.2655 | T11: 14 | U11: 1 | V11: 1
A12: 13 | B12: 包装组件 | C12: N40512000282 | D12: 泡沫棉 40X20X199 (右侧EVA棉块2)(高密度)(防静电)(RoHS) | E12: AB级替换 | F12: PKG | G12: 3 | H12: N40512000282 | I12: 泡沫棉 40X20X199 (右侧EVA棉块2)(高密度)(防静电)(RoHS) | J12: 512 | K12: 10379 | L12: 厦门市达唯工贸有限公司 | M12: 1.0619 | N12: 0 | O12: =G12*M12 -> 3.1857 | T12: 14 | U12: 1 | V12: 1
A13: 14 | B13: 包装组件 | C13: N40517000012 | D13: 纸护角 50X50X403 (RoHS) | E13: AB级替换 | F13: PKG | G13: 4 | H13: N40517000012 | I13: 纸护角 50X50X403 (RoHS) | J13: 512 | K13: 11363 | L13: 厦门比瑞特包装科技有限公司 | M13: 0.7456 | N13: 0 | O13: =G13*M13 -> 2.9824 | T13: 14 | U13: 1 | V13: 1
A14: 15 | B14: 包装组件 | C14: N60703001395 | D14: 标签 BQ12080W001-HL (格式标签)(1寸卷芯,外径83mm)(RoHS) | E14: AB级替换 | F14: 贴装 | G14: 1 | H14: N60703001395 | I14: 标签 BQ12080W001-HL (格式标签)(1寸卷芯,外径83mm)(宏鹭华)(RoHS) | J14: 吴桃春 | K14: DWQK2 | L14: 东莞市全科电子材料有限公司 | M14: 0.0347 | N14: 0 | O14: =G14*M14 -> 0.0347 | T14: 14 | U14: 3000
I15: 包装成本 | O15: =SUM(O5:O14) -> 96.6702
A16: 16 | B16: 硬件 | C16: 301H030491 | D16: 片式电阻 RC0805FR-07300KL/0805W8F3003T5E 1/8W,300KΩ,1%,0805(国巨/厚声)(编带)(RoHS) | E16: AB级替换 | F16: SMT | G16: 18 | H16: N30101005840 | I16: 片式电阻 RC0805FR-07300KL 1/8W,300KΩ,1%,0805(国巨)(编带)(RoHS) | J16: 196386 | K16: 10266 | L16: 深圳市超利维实业有限公司 | M16: 0.0045 | N16: 0 | O16: =G16*M16 -> 0.081 | T16: 56 | U16: 5000 | V16: 5000 | Z16: R163-168,178,179,182-191 | AA16: N30101007034 | AB16: 片式电阻 0805W8F3003T5E 1/8W,300KΩ,1%,0805(厚声)(编带)(RoHS) | AC16: 0.0049 | AD16: 301H030491 | AE16: 片式电阻 RC0805FR-07300KL/0805W8F3003T5E 1/8W,300KΩ,1%,0805(国巨/厚声)(编带)(RoHS) | AF16: 报价中
A17: 17 | B17: 硬件 | C17: 306110396 | D17: 高压陶瓷电容 HGK3AF103ZG3AW 10nF,1KV,P=7.5(万明)(编带)(RoHS) | E17: AB级替换 | F17: 插焊 | G17: 1 | H17: 306110396 | I17: 高压陶瓷电容 HGK3AF103ZG3AW 10nF,1KV,P=7.5(万明)(编带)(RoHS) | J17: 196386 | K17: 10423 | L17: 厦门万明电子有限公司 | M17: 0.1331 | N17: 0 | O17: =G17*M17 -> 0.1331 | T17: 50 | U17: 20000 | V17: 2000 | Y17: 生产后按万明回复交期出货，不接受按贵司需求数量出货 | Z17: C50A
A18: 18 | B18: 硬件 | C18: 3155US1M | D18: 超快恢复二极管 US1M 1A,1KV,SMA(强茂)(编带)(RoHS) | E18: AB级替换 | F18: SMT | G18: 1 | H18: N31511000061 | I18: 超快恢复二极管 US1M 1A,1KV,SMA(晶导微)(编带)(RoHS) | J18: 514 | K18: 10382 | L18: 厦门镁富莱工贸有限公司 | M18: 0.0274 | N18: 0 | O18: =G18*M18 -> 0.0274 | T18: 35 | U18: 1 | V18: 1 | Z18: V16 | AA18: 3155US1M | AB18: 超快恢复二极管 US1M 1A,1KV,SMA(强茂)(编带)(RoHS) | AC18: 0.084
A19: 19 | B19: 硬件 | C19: 604B03VHZ51R | D19: 端子 B3P-VH (JST)(RoHS) | E19: AB级替换 | F19: 插焊 | G19: 1 | H19: 604B03VHZ51R | I19: 端子 B3P-VH (JST)(RoHS) | J19: 王临泽 | K19: HYDZ2 | L19: 深圳市恒有电子有限公司 | M19: 0.222 | N19: 0 | O19: =G19*M19 -> 0.222 | T19: 150 | U19: 1000 | Z19: X5
A20: 20 | B20: 硬件 | C20: 604B05VHZ51R | D20: 端子 B5P-VH (JST)(RoHS) | E20: AB级替换 | F20: 插焊 | G20: 2 | H20: 604B05VHZ51R | I20: 端子 B5P-VH (JST)(RoHS) | J20: 王临泽 | K20: HYDZ2 | L20: 深圳市恒有电子有限公司 | M20: 0.322 | N20: 0 | O20: =G20*M20 -> 0.644 | T20: 112 | U20: 1000 | Z20: X12,16
A21: 21 | B21: 硬件 | C21: N30101000615 | D21: 片式电阻 RC1206JR-0775RL/1206W4J0750T5E 1/4W,75Ω,5%,1206(国巨/厚声)(编带)(RoHS) | E21: AB级替换 | F21: SMT | G21: 1 | H21: N30101006583 | I21: 片式电阻 1206W4J0750T5E 1/4W,75Ω,5%,1206(厚声)(编带)(RoHS) | J21: 罗城 | K21: 10648 | L21: 厚声国际贸易（昆山）有限公司 | M21: 0.0045 | N21: 0 | O21: =G21*M21 -> 0.0045 | T21: 56 | U21: 0 | V21: 5000 | Z21: R118 | AA21: N30101005467 | AB21: 片式电阻 RC1206JR-0775RL 1/4W,75Ω,5%,1206(国巨)(编带)(RoHS) | AC21: 0.0077 | AD21: N30101000615 | AE21: 片式电阻 RC1206JR-0775RL/1206W4J0750T5E 1/4W,75Ω,5%,1206(国巨/厚声)(编带)(RoHS) | AF21: 报价中
A22: 22 | B22: 硬件 | C22: N30101000894 | D22: 片式电阻 RC1206FR-0722RL/1206W4F220JT5E 1/4W,22Ω,1%,1206(国巨/厚声)(编带)(RoHS) | E22: AB级替换 | F22: SMT | G22: 2 | H22: N30101006783 | I22: 片式电阻 1206W4F220JT5E 1/4W,22Ω,1%,1206(厚声)(编带)(RoHS) | J22: 罗城 | K22: 10648 | L22: 厚声国际贸易（昆山）有限公司 | M22: 0.0058 | N22: 0 | O22: =G22*M22 -> 0.0116 | T22: 56 | U22: 0 | V22: 5000 | Z22: R10,30 | AA22: N30101005525 | AB22: 片式电阻 RC1206FR-0722RL 1/4W,22Ω,1%,1206(国巨)(编带)(RoHS) | AC22: 0.0086 | AD22: N30101000894 | AE22: 片式电阻 RC1206FR-0722RL/1206W4F220JT5E 1/4W,22Ω,1%,1206(国巨/厚声)(编带)(RoHS) | AF22: 报价中
A23: 23 | B23: 硬件 | C23: N30101001049 | D23: 片式电阻 RC1206FR-076R8L/1206W4F680KT5E 1/4W,6.8Ω,1%,1206(国巨/厚声)(编带)(RoHS) | E23: AB级替换 | F23: SMT | G23: 2 | H23: N30101006696 | I23: 片式电阻 1206W4F680KT5E 1/4W,6.8Ω,1%,1206(厚声)(编带)(RoHS) | J23: 罗城 | K23: 10648 | L23: 厚声国际贸易（昆山）有限公司 | M23: 0.0083 | N23: 0 | O23: =G23*M23 -> 0.0166 | T23: 56 | U23: 0 | V23: 5000 | Z23: R47,65 | AA23: N30101005600 | AB23: 片式电阻 RC1206FR-076R8L 1/4W,6.8Ω,1%,1206(国巨)(编带)(RoHS) | AC23: 0.0279 | AD23: N30101001049 | AE23: 片式电阻 RC1206FR-076R8L/1206W4F680KT5E 1/4W,6.8Ω,1%,1206(国巨/厚声)(编带)(RoHS) | AF23: 报价中
A24: 24 | B24: 硬件 | C24: N30101005306 | D24: 片式电阻 GMR320HJCFAR100 7W,100mΩ,1%,2817(Rohm)(编带)(RoHS) | E24: AB级替换 | F24: SMT | G24: 2 | H24: N30101005306 | I24: 片式电阻 GMR320HJCFAR100 7W,100mΩ,1%,2817(Rohm)(编带)(RoHS) | J24: 521 | K24: 10265 | L24: 北天星电子(深圳)有限公司 | M24: 2.38 | N24: 0 | O24: =G24*M24 -> 4.76 | T24: 120 | U24: 1 | V24: 1 | Z24: R92,241
A25: 25 | B25: 硬件 | C25: N30101005309 | D25: 片式电阻 1210W2F3003T5E 1/2W,300KΩ,1%,1210(厚声)(编带)(RoHS) | E25: AB级替换 | F25: SMT | G25: 8 | H25: N30101005309 | I25: 片式电阻 1210W2F3003T5E 1/2W,300KΩ,1%,1210(厚声)(编带)(RoHS) | J25: 罗城 | K25: 10648 | L25: 厚声国际贸易（昆山）有限公司 | M25: 0.023 | N25: 0 | O25: =G25*M25 -> 0.184 | T25: 91 | U25: 0 | V25: 20000 | Z25: R192-199
A26: 26 | B26: 硬件 | C26: N30103000520 | D26: 金属膜电阻 MF02SJJ0364A10 2WS,360KΩ,5%(厚声)(HF;RoHS) | E26: AB级替换 | F26: 插焊 | G26: 3 | H26: N30103000520 | I26: 金属膜电阻 MF02SJJ0364A10 2WS,360KΩ,5%(厚声)(HF;RoHS) | J26: 罗城 | K26: 10648 | L26: 厚声国际贸易（昆山）有限公司 | M26: 0.065 | N26: 0 | O26: =G26*M26 -> 0.195 | T26: 91 | U26: 0 | V26: 20000 | Z26: R295,296,365
A27: 27 | B27: 硬件 | C27: N30103000526 | D27: 金属膜电阻 MF01WFF3003A10 1W,300KΩ,1%(厚声)(编带)(HF;RoHS) | E27: AB级替换 | F27: 插焊 | G27: 1 | H27: N30103000526 | I27: 金属膜电阻 MF01WFF3003A10 1W,300KΩ,1%(厚声)(编带)(RoHS) | J27: 陈虹 | K27: HSMY2 | L27: 厚声国际贸易（昆山）有限公司 | M27: 0.0828 | N27: 0 | O27: =G27*M27 -> 0.0828 | T27: 42 | U27: 1000 | V27: 1000 | Z27: R11
A28: 28 | B28: 硬件 | C28: N30103000527 | D28: 金属膜电阻 MF02WJJ0753A10 2W,75KΩ,5%(厚声)(编带)(HF;RoHS) | E28: AB级替换 | F28: 插焊 | G28: 1 | H28: N30103000527 | I28: 金属膜电阻 MF02WJJ0753A10 2W,75KΩ,5%(厚声)(编带)(HF;RoHS) | J28: 罗城 | K28: 10648 | L28: 厚声国际贸易（昆山）有限公司 | M28: 0.092 | N28: 0 | O28: =G28*M28 -> 0.092 | T28: 91 | U28: 0 | V28: 20000 | Z28: R34
A29: 29 | B29: 硬件 | C29: N30111000138 | D29: 合金电阻 DSLR-K-7-3F 7W,3mΩ,1%,5930(业展)(编带)(REACH;RoHS) | E29: AB级替换 | F29: SMT | G29: 3 | H29: N30111000138 | I29: 合金电阻 DSLR-K-7-3F 7W,3mΩ,1%,5930(业展)(编带)(REACH;RoHS) | J29: 521 | K29: 10265 | L29: 北天星电子(深圳)有限公司 | M29: 0.9 | N29: 0 | O29: =G29*M29 -> 2.7 | T29: 120 | U29: 1 | V29: 1 | Z29: R87,89,90
A30: 30 | B30: 硬件 | C30: N30111000139 | D30: 合金电阻 LR123WF200LT4E 3W,200mΩ,1%,2512(厚声)(编带)(RoHS) | E30: AB级替换 | F30: SMT | G30: 8 | H30: N30111000139 | I30: 合金电阻 LR123WF200LT4E 3W,200mΩ,1%,2512(厚声)(编带)(RoHS) | J30: 521 | K30: 10648 | L30: 厚声国际贸易（昆山）有限公司 | M30: 0.22 | N30: 0 | O30: =G30*M30 -> 1.76 | T30: 1 | U30: 1 | V30: 4000 | Z30: R233-236,293,294,297,298
A31: 31 | B31: 硬件 | C31: N30199000015 | D31: 片式电阻 1/4W,0Ω,5%,1206(编带)(RoHS)(互换件) | E31: AB级替换 | F31: SMT | G31: 1 | H31: N30101002864 | I31: 片式电阻 RS-06000JT 1/4W,0Ω,5%,1206(风华)(编带)(RoHS) | J31: 陈虹 | K31: MHDZ2 | L31: 厦门美赫电子有限公司 | M31: 0.0042 | N31: 0 | O31: =G31*M31 -> 0.0042 | T31: 56 | U31: 5000 | Z31: R144 | AA31: N30101006682 | AB31: 片式电阻 1206W4J0000T5E 1/4W,0Ω,5%,1206(厚声)(编带)(RoHS) | AC31: 0.0042 | AD31: N30101005366 | AE31: 片式电阻 RC1206JR-070RL 1/4W,0Ω,5%,1206(国巨)(编带)(RoHS) | AF31: 0.0075 | AG31: N30101002359 | AH31: 片式电阻 CR1206J40000G 1/4W,0Ω,5%,1206(丽智)(编带)(RoHS) | AI31: 报价中
A32: 32 | B32: 硬件 | C32: N30199000022 | D32: 片式电阻 1/10W,10KΩ,1%,0603(编带)(RoHS)(互换件) | E32: AB级替换 | F32: SMT | G32: 49 | H32: N30101002483 | I32: 片式电阻 0603WAF1002T5E 1/10W,10KΩ,1%,0603(厚声)(编带)(RoHS) | J32: 陈虹 | K32: HSMY2 | L32: 厚声国际贸易（昆山）有限公司 | M32: 0.0018 | N32: 0 | O32: =G32*M32 -> 0.0882 | T32: 56 | U32: 5000 | Z32: R4,5,7,14,16,20,21,23,26,27,31,38,39,42,52,62,63,73,75,77,80,82,83,98-100,112-114,116,141-143,145,200-202,218-223,225-227,231,232,260 | AA32: N30101002583 | AB32: 片式电阻 RS-03K1002FT 1/10W,10KΩ,1%,0603(风华)(编带)(RoHS) | AC32: 0.0018 | AD32: 301H0103H1 | AE32: 片式电阻 RC0603FR-0710KL 1/10W,10KΩ,1%,0603(国巨)(编带)(RoHS) | AF32: 0.0025 | AG32: N30101002366 | AH32: 片式电阻 CR0603FA1002G 1/10W,10KΩ,1%,0603(丽智)(编带)(RoHS) | AI32: 报价中
A33: 33 | B33: 硬件 | C33: N30199000047 | D33: 片式电阻 1/10W,1KΩ,1%,0603(编带)(RoHS)(互换件) | E33: AB级替换 | F33: SMT | G33: 25 | H33: N30101002910 | I33: 片式电阻 RS-03K1001FT 1/10W,1KΩ,1%,0603(风华)(编带)(RoHS) | J33: 陈虹 | K33: MHDZ2 | L33: 厦门美赫电子有限公司 | M33: 0.0018 | N33: 0 | O33: =G33*M33 -> 0.045 | T33: 56 | U33: 5000 | Z33: R6,12,41,43-45,58,60,64,67-71,76,93-97,224,261,270,299,456 | AA33: N30101007519 | AB33: 片式电阻 0603WAF1001T5E 1/10W,1KΩ,1%,0603(厚声)(编带)(RoHS) | AC33: 0.0018 | AD33: N30101006259 | AE33: 片式电阻 RC0603FR-071KL 1/10W,1KΩ,1%,0603(国巨)(编带)(RoHS) | AF33: 0.0025 | AG33: N30101002909 | AH33: 片式电阻 CR0603FA1001G 1/10W,1KΩ,1%,0603(丽智)(编带)(RoHS) | AI33: 报价中
A34: 34 | B34: 硬件 | C34: N30199000075 | D34: 片式电阻 1/10W,4.7KΩ,1%,0603(编带)(RoHS)(互换件) | E34: AB级替换 | F34: SMT | G34: 9 | H34: N30101002965 | I34: 片式电阻 RS-03K4701FT 1/10W,4.7KΩ,1%,0603(风华)(编带)(RoHS) | J34: 陈虹 | K34: MHDZ2 | L34: 厦门美赫电子有限公司 | M34: 0.0018 | N34: 0 | O34: =G34*M34 -> 0.0162 | T34: 56 | U34: 5000 | Z34: R2,8,46,49-51,103-105 | AA34: N30101007321 | AB34: 片式电阻 0603WAF4701T5E 1/10W,4.7KΩ,1%,0603(厚声)(编带)(RoHS) | AC34: 0.0018 | AD34: N30101006127 | AE34: 片式电阻 RC0603FR-074K7L 1/10W,4.7KΩ,1%,0603(国巨)(编带)(RoHS) | AF34: 0.0026 | AG34: N30101002964 | AH34: 片式电阻 CR0603FA4701G 1/10W,4.7KΩ,1%,0603(丽智)(编带)(RoHS) | AI34: 报价中
A35: 35 | B35: 硬件 | C35: N30199000085 | D35: 片式电阻 1/10W,20KΩ,1%,0603(编带)(RoHS)(互换件) | E35: AB级替换 | F35: SMT | G35: 2 | H35: N30101002985 | I35: 片式电阻 RS-03K2002FT 1/10W,20KΩ,1%,0603(风华)(编带)(RoHS) | J35: 陈虹 | K35: MHDZ2 | L35: 厦门美赫电子有限公司 | M35: 0.0018 | N35: 0 | O35: =G35*M35 -> 0.0036 | T35: 56 | U35: 5000 | Z35: R74,81 | AA35: N30101007433 | AB35: 片式电阻 0603WAF2002T5E 1/10W,20KΩ,1%,0603(厚声)(编带)(RoHS) | AC35: 0.0018 | AD35: N30101006246 | AE35: 片式电阻 RC0603FR-0720KL 1/10W,20KΩ,1%,0603(国巨)(编带)(RoHS) | AF35: 0.0026 | AG35: N30101002984 | AH35: 片式电阻 CR0603FA2002G 1/10W,20KΩ,1%,0603(丽智)(编带)(RoHS) | AI35: 报价中
A36: 36 | B36: 硬件 | C36: N30199000101 | D36: 片式电阻 1/10W,2.2KΩ,1%,0603(编带)(RoHS)(互换件) | E36: AB级替换 | F36: SMT | G36: 7 | H36: N30101003017 | I36: 片式电阻 RS-03K2201FT 1/10W,2.2KΩ,1%,0603(风华)(编带)(RoHS) | J36: 陈虹 | K36: MHDZ2 | L36: 厦门美赫电子有限公司 | M36: 0.0018 | N36: 0 | O36: =G36*M36 -> 0.0126 | T36: 56 | U36: 5000 | Z36: R17,22,28,29,35,40,117 | AA36: N30101007423 | AB36: 片式电阻 0603WAF2201T5E 1/10W,2.2KΩ,1%,0603(厚声)(编带)(RoHS) | AC36: 0.0018 | AD36: N30101006208 | AE36: 片式电阻 RC0603FR-072K2L 1/10W,2.2KΩ,1%,0603(国巨)(编带)(RoHS) | AF36: 0.0025 | AG36: N30101003016 | AH36: 片式电阻 CR0603FA2201G 1/10W,2.2KΩ,1%,0603(丽智)(编带)(RoHS) | AI36: 报价中
A37: 37 | B37: 硬件 | C37: N30199000108 | D37: 片式电阻 1/10W,22KΩ,1%,0603(编带)(RoHS)(互换件) | E37: AB级替换 | F37: SMT | G37: 2 | H37: N30101003031 | I37: 片式电阻 RS-03K2202FT 1/10W,22KΩ,1%,0603(风华)(编带)(RoHS) | J37: 虞思旻 | K37: MHDZ2 | L37: 厦门美赫电子有限公司 | M37: 0.0018 | N37: 0 | O37: =G37*M37 -> 0.0036 | T37: 56 | U37: 5000 | Z37: R56,61 | AA37: N30101007422 | AB37: 片式电阻 0603WAF2202T5E 1/10W,22KΩ,1%,0603(厚声)(编带)(RoHS) | AC37: 0.0018 | AD37: N30101006238 | AE37: 片式电阻 RC0603FR-0722KL 1/10W,22KΩ,1%,0603(国巨)(编带)(RoHS) | AF37: 0.0026 | AG37: N30101003030 | AH37: 片式电阻 CR0603FA2202G 1/10W,22KΩ,1%,0603(丽智)(编带)(RoHS) | AI37: 报价中
A38: 38 | B38: 硬件 | C38: N30199000111 | D38: 片式电阻 1/10W,15KΩ,1%,0603(编带)(RoHS)(互换件) | E38: AB级替换 | F38: SMT | G38: 8 | H38: N30101003071 | I38: 片式电阻 RS-03K1502FT 1/10W,15KΩ,1%,0603(风华)(编带)(RoHS) | J38: 陈虹 | K38: MHDZ2 | L38: 厦门美赫电子有限公司 | M38: 0.0018 | N38: 0 | O38: =G38*M38 -> 0.0144 | T38: 56 | U38: 5000 | Z38: R148,149,174,175,248,249,274,275 | AA38: N30101007468 | AB38: 片式电阻 0603WAF1502T5E 1/10W,15KΩ,1%,0603(厚声)(编带)(RoHS) | AC38: 0.0018 | AD38: N30101006296 | AE38: 片式电阻 RC0603FR-0715KL 1/10W,15KΩ,1%,0603(国巨)(编带)(RoHS) | AF38: 0.0026 | AG38: N30101003070 | AH38: 片式电阻 CR0603FA1502G 1/10W,15KΩ,1%,0603(丽智)(编带)(RoHS) | AI38: 报价中
A39: 39 | B39: 硬件 | C39: N30199000117 | D39: 片式电阻 1/4W,100Ω,5%,1206(编带)(RoHS)(互换件) | E39: AB级替换 | F39: SMT | G39: 2 | H39: N30101003083 | I39: 片式电阻 RS-06K101JT 1/4W,100Ω,5%,1206(风华)(编带)(RoHS) | J39: 陈虹 | K39: MHDZ2 | L39: 厦门美赫电子有限公司 | M39: 0.0042 | N39: 0 | O39: =G39*M39 -> 0.0084 | T39: 56 | U39: 5000 | Z39: R228,230 | AA39: N30101006680 | AB39: 片式电阻 1206W4J0101T5E 1/4W,100Ω,5%,1206(厚声)(编带)(RoHS) | AC39: 0.0042 | AD39: N30101005376 | AE39: 片式电阻 RC1206JR-07100RL 1/4W,100Ω,5%,1206(国巨)(编带)(RoHS) | AF39: 0.0075 | AG39: N30101003082 | AH39: 片式电阻 CR1206J40101G 1/4W,100Ω,5%,1206(丽智)(编带)(RoHS) | AI39: 报价中
A40: 40 | B40: 硬件 | C40: N30199000127 | D40: 片式电阻 1/10W,5.6KΩ,1%,0603(编带)(RoHS)(互换件) | E40: AB级替换 | F40: SMT | G40: 1 | H40: N30101003103 | I40: 片式电阻 RS-03K5601FT 1/10W,5.6KΩ,1%,0603(风华)(编带)(RoHS) | J40: 陈虹 | K40: MHDZ2 | L40: 厦门美赫电子有限公司 | M40: 0.0018 | N40: 0 | O40: =G40*M40 -> 0.0018 | T40: 56 | U40: 5000 | Z40: R84 | AA40: N30101007296 | AB40: 片式电阻 0603WAF5601T5E 1/10W,5.6KΩ,1%,0603(厚声)(编带)(RoHS) | AC40: 0.0018 | AD40: N30101006101 | AE40: 片式电阻 RC0603FR-075K6L 1/10W,5.6KΩ,1%,0603(国巨)(编带)(RoHS) | AF40: 0.0026 | AG40: N30101003102 | AH40: 片式电阻 CR0603FA5601G 1/10W,5.6KΩ,1%,0603(丽智)(编带)(RoHS) | AI40: 报价中
...

Sheet Sheet3
A1: (Q251020183811524 / N10305002124 / DRV-26P-NJTJ(RoHS)中央式空调控制器驱动板组件(D5A13H000000))产品加工成本核算报表 | J1: (Q260105085808046 / N10305002124 / DRV-26P-NJTJ(RoHS)中央式空调控制器驱动板组件(D5A13H000000))产品加工成本核算报表
A3: 贴片、机插加工成本 | J3: 贴片、机插加工成本
A4: 工序 | B4: 点数 | C4: 单点成本 | D4: 金额 | J4: 工序 | K4: 点数 | L4: 单点成本 | M4: 金额
A5: 贴片 | B5: 1101.001 | C5: 0.0056 | D5: 6.1656 | J5: 贴片 | K5: 1101.001 | L5: 0.0056 | M5: 6.1656
A6: 机插 | B6: 14 | C6: 0.0171 | D6: =B6*C6 -> 0.2394 | J6: 机插 | K6: 14 | L6: 0.0171 | M6: =K6*L6 -> 0.2394
A7: 预烧写 | B7: 0 | C7: 0.0498 | D7: 0 | J7: 预烧写 | K7: 0 | L7: 0.0498 | M7: 0
A10: 人工成本 | J10: 人工成本
A11: 分段名称 | B11: 工序类别 | C11: 生产定额 | D11: 工序 | E11: 人数 | F11: 人工成本 | J11: 分段名称 | K11: 工序类别 | L11: 生产定额 | M11: 工序 | N11: 人数 | O11: 人工成本
A12: 装配段 | B12: 装配 | C12: 8 | E12: 10 | F12: / | J12: 装配段 | K12: 装配 | L12: 12 | N12: 10 | O12: /
A13: 装配段 | B13: FCT | C13: 8 | E13: 2 | F13: / | J13: 装配段 | K13: FCT | L13: 12 | N13: 2 | O13: /
A14: 装配段 | B14: 外观检验 | C14: 8 | E14: 2 | F14: / | J14: 装配段 | K14: 外观检验 | L14: 12 | N14: 2 | O14: /
A15: 装配段 | B15: OQC | C15: 8 | E15: 0.24 | F15: / | J15: 装配段 | K15: OQC | L15: 12 | N15: 0.24 | O15: /
A16: 装配段 | B16: 产前准备 | C16: 8 | E16: 0.6 | F16: / | J16: 装配段 | K16: 产前准备 | L16: 12 | N16: 0.6 | O16: /
A17: 装配段 | B17: 杂项设备 | C17: 8 | E17: 0.6 | F17: / | J17: 装配段 | K17: 杂项设备 | L17: 12 | N17: 0.6 | O17: /
A18: 装配段 | B18: 维修清尾 | C18: 8 | E18: 0.36 | F18: / | J18: 装配段 | K18: 维修清尾 | L18: 12 | N18: 0.36 | O18: /
A19: 装配段 | B19: 包装 | C19: 8 | E19: 2 | F19: / | J19: 装配段 | K19: 包装 | L19: 12 | N19: 2 | O19: /
A20: 插焊段 | B20: 插件 | C20: 80 | E20: 9 | F20: / | J20: 插焊段 | K20: 焊接 | L20: 80 | N20: 5 | O20: /
A21: 插焊段 | B21: 焊接 | C21: 80 | E21: 5 | F21: / | J21: 插焊段 | K21: 插件 | L21: 80 | N21: 9 | O21: /
A22: 插焊段 | B22: 维修清尾 | C22: 80 | E22: 0.5 | F22: / | J22: 插焊段 | K22: 维修清尾 | L22: 80 | N22: 0.5 | O22: /
A23: 插焊段 | B23: 喷漆 | C23: 80 | E23: 0.6 | F23: / | J23: 插焊段 | K23: 喷漆 | L23: 80 | N23: 0.6 | O23: /
... A63: 测试段 | B63: 外观检验 | C63: 200 | E63: 1 | F63: / | J63: 插焊段 | K63: 产前准备 | L63: 240 | N63: 0.6 | O63: /
A64: 测试段 | B64: FCT | C64: 200 | E64: 3 | F64: / | J64: 总人工成本（含辅助人员） | O64: 82.0882
A65: 总人工成本（含辅助人员） | F65: 111.0501
A68: 工装成本 | J68: 工装成本
A69: 工艺 | B69: 工装名称 | C69: 数量 | D69: 单价 | E69: 年需求 | F69: 工装成本 | G69: 金额 | J69: 工艺 | K69: 工装名称 | L69: 数量 | M69: 单价 | N69: 年需求 | O69: 工装成本 | P69: 金额
A70: 装配 | B70: 装配工装 | C70: 2 | D70: 2000 | E70: 5000 | F70: 0.2667 | G70: =C70*D70 -> 4000 | J70: 装配 | K70: 装配工装 | L70: 2 | M70: 2000 | N70: 5000 | O70: 0.2667 | P70: =L70*M70 -> 4000
A71: 自动测试 | B71: 测试工装 | C71: 2 | D71: 4000 | E71: 5000 | F71: 0.5333 | G71: =C71*D71 -> 8000 | J71: 自动测试 | K71: 测试工装 | L71: 2 | M71: 4000 | N71: 5000 | O71: 0.5333 | P71: =L71*M71 -> 8000
A72: 波峰焊 | B72: 波峰焊托盘 | C72: 15 | D72: 300 | E72: 5000 | F72: 0.3 | G72: =C72*D72 -> 4500 | J72: 波峰焊 | K72: 波峰焊托盘 | L72: 15 | M72: 300 | N72: 5000 | O72: 0.3 | P72: =L72*M72 -> 4500
A73: 双面喷漆 | B73: 喷漆托盘 | C73: 0 | D73: 0 | E73: 5000 | F73: 0 | G73: =C73*D73 -> 0 | J73: 双面喷漆 | K73: 喷漆托盘 | L73: 0 | M73: 0 | N73: 5000 | O73: 0 | P73: =L73*M73 -> 0
A74: 自动测试 | B74: 自动测试工装 | C74: 2 | D74: 4000 | E74: 5000 | F74: 0.5333 | G74: =C74*D74 -> 8000 | J74: 自动测试 | K74: 自动测试工装 | L74: 2 | M74: 4000 | N74: 5000 | O74: 0.5333 | P74: =L74*M74 -> 8000
A75: ICT | B75: ICT针床 | C75: 1 | D75: 0 | E75: 5000 | F75: 0 | G75: =C75*D75 -> 0 | J75: ICT | K75: ICT针床 | L75: 1 | M75: 0 | N75: 5000 | O75: 0 | P75: =L75*M75 -> 0
A76: 装配 | B76: 装配工装 | C76: 3 | D76: 0 | E76: 5000 | F76: 0 | G76: =C76*D76 -> 0 | J76: 装配 | K76: 装配工装 | L76: 3 | M76: 0 | N76: 5000 | O76: 0 | P76: =L76*M76 -> 0
A77: 自动焊锡机 | B77: 自动焊接 | C77: 3 | D77: 400 | E77: 5000 | F77: 0.08 | G77: =C77*D77 -> 1200 | J77: 自动焊锡机 | K77: 自动焊接 | L77: 3 | M77: 400 | N77: 5000 | O77: 0.08 | P77: =L77*M77 -> 1200
A78: 双面喷漆 | B78: 喷漆托盘 | C78: 15 | D78: 0 | E78: 5000 | F78: 0 | G78: =C78*D78 -> 0 | J78: 双面喷漆 | K78: 喷漆托盘 | L78: 15 | M78: 0 | N78: 5000 | O78: 0 | P78: =L78*M78 -> 0
A79: ICT | B79: ICT针床 | C79: 1 | D79: 0 | E79: 5000 | F79: 0 | G79: =C79*D79 -> 0 | J79: ICT | K79: ICT针床 | L79: 1 | M79: 0 | N79: 5000 | O79: 0 | P79: =L79*M79 -> 0
A80: 自动测试 | B80: 自动测试 | C80: 3 | D80: 0 | E80: 5000 | F80: 0 | G80: =C80*D80 -> 0 | J80: 自动测试 | K80: 自动测试 | L80: 3 | M80: 0 | N80: 5000 | O80: 0 | P80: =L80*M80 -> 0
A81: 波峰焊 | B81: 波峰焊托盘 | C81: 0 | D81: 0 | E81: 0 | F81: 0 | G81: =C81*D81 -> 0 | J81: 波峰焊 | K81: 波峰焊托盘 | L81: 0 | M81: 0 | N81: 0 | O81: 0 | P81: =L81*M81 -> 0
... A85: ICT | B85: ICT针床 | C85: 1 | D85: 3500 | E85: 5000 | F85: 0.2333 | G85: =C85*D85 -> 3500 | J85: ICT | K85: ICT针床 | L85: 1 | M85: 3500 | N85: 5000 | O85: 0.2333 | P85: =L85*M85 -> 3500
A86: 合计 | F86: 直接向客户收取 | G86: =SUM(G70:G85) -> 48700 | J86: 合计 | O86: 直接向客户收取 | P86: =SUM(P70:P85) -> 48700
A88: 加工成本汇总 | J88: 加工成本汇总
...

Sheet Sheet4
A1: 项目名称 | C1: 汽车与工控控制器-DRV-20P-NJTJ(RoHS)中央式空调控制器驱动板组件(D5A13G000000)--二次重新报价！！ | E1: 客户名称 | F1: 青岛国创智能家电研究院有限公司 | K1: 报价项目类型 | L1: 已立项产品报价 | Q1: 王前良 | U1: 销售公司/国内销售部/汽控国内部
A2: 产品编码 | C2: N10305002124 | E2: 产品名称 | F2: DRV-26P-NJTJ(RoHS)中央式空调控制器驱动板组件(D5A13H000000) | K2: 硬件设计师 | L2: 李沁峰 | Q2: 陈可璜 | U2: 45950
A3: 硬件 | E3: 结构件 | K3: 包装材料 | R3: 0 | V3: 0
A4: 序号 | B4: 物料类型 | C4: 物料编码 | D4: 物料名称 | E4: 物料级别 | F4: 装配形式 | G4: 单机用量 | H4: 最低价物料编码 | I4: 最低价物料名称 | J4: 采购员 | K4: 供应商代码 | L4: 供应商名称 | M4: 未税单价 | N4: 最新未税单价 | O4: 涨价合计金额 | P4: 损耗率 | Q4: 金额 | R4: 提前期 | S4: 最小订货量 | T4: 最小包装量 | U4: 模具费（含税13%） | V4: 价格说明 | W4: 备注 | X4: 位号 | Y4: 替代料编码1 | Z4: 替代料名称1 | AA4: 未税单价1 | AB4: 替代料编码2 | AC4: 替代料名称2 | AD4: 未税单价2 | AE4: 替代料编码3 | AF4: 替代料名称3 | AG4: 未税单价3
A5: 16 | B5: 硬件 | C5: 301H030491 | D5: 片式电阻 RC0805FR-07300KL/0805W8F3003T5E 1/8W,300KΩ,1%,0805(国巨/厚声)(编带)(RoHS) | E5: AB级替换 | F5: SMT | G5: 18 | H5: N30101005840 | I5: 片式电阻 RC0805FR-07300KL 1/8W,300KΩ,1%,0805(国巨)(编带)(RoHS) | J5: 196386 | K5: 10266 | L5: 深圳市超利维实业有限公司 | M5: 0.0045 | P5: 0 | Q5: =G5*M5 -> 0.081 | R5: 56 | S5: 5000 | T5: 5000 | X5: R163-168,178,179,182-191 | Y5: N30101007034 | Z5: 片式电阻 0805W8F3003T5E 1/8W,300KΩ,1%,0805(厚声)(编带)(RoHS) | AA5: 0.0049 | AB5: 301H030491 | AC5: 片式电阻 RC0805FR-07300KL/0805W8F3003T5E 1/8W,300KΩ,1%,0805(国巨/厚声)(编带)(RoHS) | AD5: 报价中
A6: 17 | B6: 硬件 | C6: 306110396 | D6: 高压陶瓷电容 HGK3AF103ZG3AW 10nF,1KV,P=7.5(万明)(编带)(RoHS) | E6: AB级替换 | F6: 插焊 | G6: 1 | H6: 306110396 | I6: 高压陶瓷电容 HGK3AF103ZG3AW 10nF,1KV,P=7.5(万明)(编带)(RoHS) | J6: 196386 | K6: 10423 | L6: 厦门万明电子有限公司 | M6: 0.1331 | P6: 0 | Q6: =G6*M6 -> 0.1331 | R6: 50 | S6: 20000 | T6: 2000 | W6: 生产后按万明回复交期出货，不接受按贵司需求数量出货 | X6: C50A
A7: 18 | B7: 硬件 | C7: 3155US1M | D7: 超快恢复二极管 US1M 1A,1KV,SMA(强茂)(编带)(RoHS) | E7: AB级替换 | F7: SMT | G7: 1 | H7: N31511000061 | I7: 超快恢复二极管 US1M 1A,1KV,SMA(晶导微)(编带)(RoHS) | J7: 514 | K7: 10382 | L7: 厦门镁富莱工贸有限公司 | M7: 0.0274 | P7: 0 | Q7: =G7*M7 -> 0.0274 | R7: 35 | S7: 1 | T7: 1 | X7: V16 | Y7: 3155US1M | Z7: 超快恢复二极管 US1M 1A,1KV,SMA(强茂)(编带)(RoHS) | AA7: 0.084
A8: 19 | B8: 硬件 | C8: 604B03VHZ51R | D8: 端子 B3P-VH (JST)(RoHS) | E8: AB级替换 | F8: 插焊 | G8: 1 | H8: 604B03VHZ51R | I8: 端子 B3P-VH (JST)(RoHS) | J8: 王临泽 | K8: HYDZ2 | L8: 深圳市恒有电子有限公司 | M8: 0.222 | P8: 0 | Q8: =G8*M8 -> 0.222 | R8: 150 | S8: 1000 | X8: X5
A9: 20 | B9: 硬件 | C9: 604B05VHZ51R | D9: 端子 B5P-VH (JST)(RoHS) | E9: AB级替换 | F9: 插焊 | G9: 2 | H9: 604B05VHZ51R | I9: 端子 B5P-VH (JST)(RoHS) | J9: 王临泽 | K9: HYDZ2 | L9: 深圳市恒有电子有限公司 | M9: 0.322 | P9: 0 | Q9: =G9*M9 -> 0.644 | R9: 112 | S9: 1000 | X9: X12,16
A10: 21 | B10: 硬件 | C10: N30101000615 | D10: 片式电阻 RC1206JR-0775RL/1206W4J0750T5E 1/4W,75Ω,5%,1206(国巨/厚声)(编带)(RoHS) | E10: AB级替换 | F10: SMT | G10: 1 | H10: N30101006583 | I10: 片式电阻 1206W4J0750T5E 1/4W,75Ω,5%,1206(厚声)(编带)(RoHS) | J10: 罗城 | K10: 10648 | L10: 厚声国际贸易（昆山）有限公司 | M10: 0.0045 | N10: 0.0057 | O10: =(N10-M10)*G10 -> 0.0012 | P10: 0 | Q10: =G10*M10 -> 0.0045 | R10: 56 | S10: 0 | T10: 5000 | X10: R118 | Y10: N30101005467 | Z10: 片式电阻 RC1206JR-0775RL 1/4W,75Ω,5%,1206(国巨)(编带)(RoHS) | AA10: 0.0077 | AB10: N30101000615 | AC10: 片式电阻 RC1206JR-0775RL/1206W4J0750T5E 1/4W,75Ω,5%,1206(国巨/厚声)(编带)(RoHS) | AD10: 报价中
A11: 22 | B11: 硬件 | C11: N30101000894 | D11: 片式电阻 RC1206FR-0722RL/1206W4F220JT5E 1/4W,22Ω,1%,1206(国巨/厚声)(编带)(RoHS) | E11: AB级替换 | F11: SMT | G11: 2 | H11: N30101006783 | I11: 片式电阻 1206W4F220JT5E 1/4W,22Ω,1%,1206(厚声)(编带)(RoHS) | J11: 罗城 | K11: 10648 | L11: 厚声国际贸易（昆山）有限公司 | M11: 0.0058 | N11: 0.0075 | O11: =(N11-M11)*G11 -> 0.0034 | P11: 0 | Q11: =G11*M11 -> 0.0116 | R11: 56 | S11: 0 | T11: 5000 | X11: R10,30 | Y11: N30101005525 | Z11: 片式电阻 RC1206FR-0722RL 1/4W,22Ω,1%,1206(国巨)(编带)(RoHS) | AA11: 0.0086 | AB11: N30101000894 | AC11: 片式电阻 RC1206FR-0722RL/1206W4F220JT5E 1/4W,22Ω,1%,1206(国巨/厚声)(编带)(RoHS) | AD11: 报价中
A12: 23 | B12: 硬件 | C12: N30101001049 | D12: 片式电阻 RC1206FR-076R8L/1206W4F680KT5E 1/4W,6.8Ω,1%,1206(国巨/厚声)(编带)(RoHS) | E12: AB级替换 | F12: SMT | G12: 2 | H12: N30101006696 | I12: 片式电阻 1206W4F680KT5E 1/4W,6.8Ω,1%,1206(厚声)(编带)(RoHS) | J12: 罗城 | K12: 10648 | L12: 厚声国际贸易（昆山）有限公司 | M12: 0.0083 | N12: 0.0112 | O12: =(N12-M12)*G12 -> 0.0058 | P12: 0 | Q12: =G12*M12 -> 0.0166 | R12: 56 | S12: 0 | T12: 5000 | X12: R47,65 | Y12: N30101005600 | Z12: 片式电阻 RC1206FR-076R8L 1/4W,6.8Ω,1%,1206(国巨)(编带)(RoHS) | AA12: 0.0279 | AB12: N30101001049 | AC12: 片式电阻 RC1206FR-076R8L/1206W4F680KT5E 1/4W,6.8Ω,1%,1206(国巨/厚声)(编带)(RoHS) | AD12: 报价中
A13: 24 | B13: 硬件 | C13: N30101005306 | D13: 片式电阻 GMR320HJCFAR100 7W,100mΩ,1%,2817(Rohm)(编带)(RoHS) | E13: AB级替换 | F13: SMT | G13: 2 | H13: N30101005306 | I13: 片式电阻 GMR320HJCFAR100 7W,100mΩ,1%,2817(Rohm)(编带)(RoHS) | J13: 521 | K13: 10265 | L13: 北天星电子(深圳)有限公司 | M13: 2.38 | P13: 0 | Q13: =G13*M13 -> 4.76 | R13: 120 | S13: 1 | T13: 1 | X13: R92,241
A14: 25 | B14: 硬件 | C14: N30101005309 | D14: 片式电阻 1210W2F3003T5E 1/2W,300KΩ,1%,1210(厚声)(编带)(RoHS) | E14: AB级替换 | F14: SMT | G14: 8 | H14: N30101005309 | I14: 片式电阻 1210W2F3003T5E 1/2W,300KΩ,1%,1210(厚声)(编带)(RoHS) | J14: 罗城 | K14: 10648 | L14: 厚声国际贸易（昆山）有限公司 | M14: 0.023 | P14: 0 | Q14: =G14*M14 -> 0.184 | R14: 91 | S14: 0 | T14: 20000 | X14: R192-199
A15: 26 | B15: 硬件 | C15: N30103000520 | D15: 金属膜电阻 MF02SJJ0364A10 2WS,360KΩ,5%(厚声)(HF;RoHS) | E15: AB级替换 | F15: 插焊 | G15: 3 | H15: N30103000520 | I15: 金属膜电阻 MF02SJJ0364A10 2WS,360KΩ,5%(厚声)(HF;RoHS) | J15: 罗城 | K15: 10648 | L15: 厚声国际贸易（昆山）有限公司 | M15: 0.065 | P15: 0 | Q15: =G15*M15 -> 0.195 | R15: 91 | S15: 0 | T15: 20000 | X15: R295,296,365
A16: 27 | B16: 硬件 | C16: N30103000526 | D16: 金属膜电阻 MF01WFF3003A10 1W,300KΩ,1%(厚声)(编带)(HF;RoHS) | E16: AB级替换 | F16: 插焊 | G16: 1 | H16: N30103000526 | I16: 金属膜电阻 MF01WFF3003A10 1W,300KΩ,1%(厚声)(编带)(RoHS) | J16: 陈虹 | K16: HSMY2 | L16: 厚声国际贸易（昆山）有限公司 | M16: 0.0828 | P16: 0 | Q16: =G16*M16 -> 0.0828 | R16: 42 | S16: 1000 | T16: 1000 | X16: R11
A17: 28 | B17: 硬件 | C17: N30103000527 | D17: 金属膜电阻 MF02WJJ0753A10 2W,75KΩ,5%(厚声)(编带)(HF;RoHS) | E17: AB级替换 | F17: 插焊 | G17: 1 | H17: N30103000527 | I17: 金属膜电阻 MF02WJJ0753A10 2W,75KΩ,5%(厚声)(编带)(HF;RoHS) | J17: 罗城 | K17: 10648 | L17: 厚声国际贸易（昆山）有限公司 | M17: 0.092 | P17: 0 | Q17: =G17*M17 -> 0.092 | R17: 91 | S17: 0 | T17: 20000 | X17: R34
A18: 29 | B18: 硬件 | C18: N30111000138 | D18: 合金电阻 DSLR-K-7-3F 7W,3mΩ,1%,5930(业展)(编带)(REACH;RoHS) | E18: AB级替换 | F18: SMT | G18: 3 | H18: N30111000138 | I18: 合金电阻 DSLR-K-7-3F 7W,3mΩ,1%,5930(业展)(编带)(REACH;RoHS) | J18: 521 | K18: 10265 | L18: 北天星电子(深圳)有限公司 | M18: 0.9 | P18: 0 | Q18: =G18*M18 -> 2.7 | R18: 120 | S18: 1 | T18: 1 | X18: R87,89,90
A19: 30 | B19: 硬件 | C19: N30111000139 | D19: 合金电阻 LR123WF200LT4E 3W,200mΩ,1%,2512(厚声)(编带)(RoHS) | E19: AB级替换 | F19: SMT | G19: 8 | H19: N30111000139 | I19: 合金电阻 LR123WF200LT4E 3W,200mΩ,1%,2512(厚声)(编带)(RoHS) | J19: 521 | K19: 10648 | L19: 厚声国际贸易（昆山）有限公司 | M19: 0.22 | P19: 0 | Q19: =G19*M19 -> 1.76 | R19: 1 | S19: 1 | T19: 4000 | X19: R233-236,293,294,297,298
A20: 31 | B20: 硬件 | C20: N30199000015 | D20: 片式电阻 1/4W,0Ω,5%,1206(编带)(RoHS)(互换件) | E20: AB级替换 | F20: SMT | G20: 1 | H20: N30101002864 | I20: 片式电阻 RS-06000JT 1/4W,0Ω,5%,1206(风华)(编带)(RoHS) | J20: 陈虹 | K20: MHDZ2 | L20: 厦门美赫电子有限公司 | M20: 0.0042 | N20: 0.0057 | O20: =(N20-M20)*G20 -> 0.0015 | P20: 0 | Q20: =G20*M20 -> 0.0042 | R20: 56 | S20: 5000 | X20: R144 | Y20: N30101006682 | Z20: 片式电阻 1206W4J0000T5E 1/4W,0Ω,5%,1206(厚声)(编带)(RoHS) | AA20: 0.0042 | AB20: N30101005366 | AC20: 片式电阻 RC1206JR-070RL 1/4W,0Ω,5%,1206(国巨)(编带)(RoHS) | AD20: 0.0075 | AE20: N30101002359 | AF20: 片式电阻 CR1206J40000G 1/4W,0Ω,5%,1206(丽智)(编带)(RoHS) | AG20: 报价中
A21: 32 | B21: 硬件 | C21: N30199000022 | D21: 片式电阻 1/10W,10KΩ,1%,0603(编带)(RoHS)(互换件) | E21: AB级替换 | F21: SMT | G21: 49 | H21: N30101002483 | I21: 片式电阻 0603WAF1002T5E 1/10W,10KΩ,1%,0603(厚声)(编带)(RoHS) | J21: 陈虹 | K21: HSMY2 | L21: 厚声国际贸易（昆山）有限公司 | M21: 0.0018 | N21: 0.0024 | O21: =(N21-M21)*G21 -> 0.0294 | P21: 0 | Q21: =G21*M21 -> 0.0882 | R21: 56 | S21: 5000 | X21: R4,5,7,14,16,20,21,23,26,27,31,38,39,42,52,62,63,73,75,77,80,82,83,98-100,112-114,116,141-143,145,200-202,218-223,225-227,231,232,260 | Y21: N30101002583 | Z21: 片式电阻 RS-03K1002FT 1/10W,10KΩ,1%,0603(风华)(编带)(RoHS) | AA21: 0.0018 | AB21: 301H0103H1 | AC21: 片式电阻 RC0603FR-0710KL 1/10W,10KΩ,1%,0603(国巨)(编带)(RoHS) | AD21: 0.0025 | AE21: N30101002366 | AF21: 片式电阻 CR0603FA1002G 1/10W,10KΩ,1%,0603(丽智)(编带)(RoHS) | AG21: 报价中
A22: 33 | B22: 硬件 | C22: N30199000047 | D22: 片式电阻 1/10W,1KΩ,1%,0603(编带)(RoHS)(互换件) | E22: AB级替换 | F22: SMT | G22: 25 | H22: N30101002910 | I22: 片式电阻 RS-03K1001FT 1/10W,1KΩ,1%,0603(风华)(编带)(RoHS) | J22: 陈虹 | K22: MHDZ2 | L22: 厦门美赫电子有限公司 | M22: 0.0018 | N22: 0.0024 | O22: =(N22-M22)*G22 -> 0.015 | P22: 0 | Q22: =G22*M22 -> 0.045 | R22: 56 | S22: 5000 | X22: R6,12,41,43-45,58,60,64,67-71,76,93-97,224,261,270,299,456 | Y22: N30101007519 | Z22: 片式电阻 0603WAF1001T5E 1/10W,1KΩ,1%,0603(厚声)(编带)(RoHS) | AA22: 0.0018 | AB22: N30101006259 | AC22: 片式电阻 RC0603FR-071KL 1/10W,1KΩ,1%,0603(国巨)(编带)(RoHS) | AD22: 0.0025 | AE22: N30101002909 | AF22: 片式电阻 CR0603FA1001G 1/10W,1KΩ,1%,0603(丽智)(编带)(RoHS) | AG22: 报价中
A23: 34 | B23: 硬件 | C23: N30199000075 | D23: 片式电阻 1/10W,4.7KΩ,1%,0603(编带)(RoHS)(互换件) | E23: AB级替换 | F23: SMT | G23: 9 | H23: N30101002965 | I23: 片式电阻 RS-03K4701FT 1/10W,4.7KΩ,1%,0603(风华)(编带)(RoHS) | J23: 陈虹 | K23: MHDZ2 | L23: 厦门美赫电子有限公司 | M23: 0.0018 | N23: 0.0024 | O23: =(N23-M23)*G23 -> 0.0054 | P23: 0 | Q23: =G23*M23 -> 0.0162 | R23: 56 | S23: 5000 | X23: R2,8,46,49-51,103-105 | Y23: N30101007321 | Z23: 片式电阻 0603WAF4701T5E 1/10W,4.7KΩ,1%,0603(厚声)(编带)(RoHS) | AA23: 0.0018 | AB23: N30101006127 | AC23: 片式电阻 RC0603FR-074K7L 1/10W,4.7KΩ,1%,0603(国巨)(编带)(RoHS) | AD23: 0.0026 | AE23: N30101002964 | AF23: 片式电阻 CR0603FA4701G 1/10W,4.7KΩ,1%,0603(丽智)(编带)(RoHS) | AG23: 报价中
A24: 35 | B24: 硬件 | C24: N30199000085 | D24: 片式电阻 1/10W,20KΩ,1%,0603(编带)(RoHS)(互换件) | E24: AB级替换 | F24: SMT | G24: 2 | H24: N30101002985 | I24: 片式电阻 RS-03K2002FT 1/10W,20KΩ,1%,0603(风华)(编带)(RoHS) | J24: 陈虹 | K24: MHDZ2 | L24: 厦门美赫电子有限公司 | M24: 0.0018 | N24: 0.0024 | O24: =(N24-M24)*G24 -> 0.0012 | P24: 0 | Q24: =G24*M24 -> 0.0036 | R24: 56 | S24: 5000 | X24: R74,81 | Y24: N30101007433 | Z24: 片式电阻 0603WAF2002T5E 1/10W,20KΩ,1%,0603(厚声)(编带)(RoHS) | AA24: 0.0018 | AB24: N30101006246 | AC24: 片式电阻 RC0603FR-0720KL 1/10W,20KΩ,1%,0603(国巨)(编带)(RoHS) | AD24: 0.0026 | AE24: N30101002984 | AF24: 片式电阻 CR0603FA2002G 1/10W,20KΩ,1%,0603(丽智)(编带)(RoHS) | AG24: 报价中
A25: 36 | B25: 硬件 | C25: N30199000101 | D25: 片式电阻 1/10W,2.2KΩ,1%,0603(编带)(RoHS)(互换件) | E25: AB级替换 | F25: SMT | G25: 7 | H25: N30101003017 | I25: 片式电阻 RS-03K2201FT 1/10W,2.2KΩ,1%,0603(风华)(编带)(RoHS) | J25: 陈虹 | K25: MHDZ2 | L25: 厦门美赫电子有限公司 | M25: 0.0018 | N25: 0.0024 | O25: =(N25-M25)*G25 -> 0.0042 | P25: 0 | Q25: =G25*M25 -> 0.0126 | R25: 56 | S25: 5000 | X25: R17,22,28,29,35,40,117 | Y25: N30101007423 | Z25: 片式电阻 0603WAF2201T5E 1/10W,2.2KΩ,1%,0603(厚声)(编带)(RoHS) | AA25: 0.0018 | AB25: N30101006208 | AC25: 片式电阻 RC0603FR-072K2L 1/10W,2.2KΩ,1%,0603(国巨)(编带)(RoHS) | AD25: 0.0025 | AE25: N30101003016 | AF25: 片式电阻 CR0603FA2201G 1/10W,2.2KΩ,1%,0603(丽智)(编带)(RoHS) | AG25: 报价中
A26: 37 | B26: 硬件 | C26: N30199000108 | D26: 片式电阻 1/10W,22KΩ,1%,0603(编带)(RoHS)(互换件) | E26: AB级替换 | F26: SMT | G26: 2 | H26: N30101003031 | I26: 片式电阻 RS-03K2202FT 1/10W,22KΩ,1%,0603(风华)(编带)(RoHS) | J26: 虞思旻 | K26: MHDZ2 | L26: 厦门美赫电子有限公司 | M26: 0.0018 | N26: 0.0024 | O26: =(N26-M26)*G26 -> 0.0012 | P26: 0 | Q26: =G26*M26 -> 0.0036 | R26: 56 | S26: 5000 | X26: R56,61 | Y26: N30101007422 | Z26: 片式电阻 0603WAF2202T5E 1/10W,22KΩ,1%,0603(厚声)(编带)(RoHS) | AA26: 0.0018 | AB26: N30101006238 | AC26: 片式电阻 RC0603FR-0722KL 1/10W,22KΩ,1%,0603(国巨)(编带)(RoHS) | AD26: 0.0026 | AE26: N30101003030 | AF26: 片式电阻 CR0603FA2202G 1/10W,22KΩ,1%,0603(丽智)(编带)(RoHS) | AG26: 报价中
A27: 38 | B27: 硬件 | C27: N30199000111 | D27: 片式电阻 1/10W,15KΩ,1%,0603(编带)(RoHS)(互换件) | E27: AB级替换 | F27: SMT | G27: 8 | H27: N30101003071 | I27: 片式电阻 RS-03K1502FT 1/10W,15KΩ,1%,0603(风华)(编带)(RoHS) | J27: 陈虹 | K27: MHDZ2 | L27: 厦门美赫电子有限公司 | M27: 0.0018 | N27: 0.0024 | O27: =(N27-M27)*G27 -> 0.0048 | P27: 0 | Q27: =G27*M27 -> 0.0144 | R27: 56 | S27: 5000 | X27: R148,149,174,175,248,249,274,275 | Y27: N30101007468 | Z27: 片式电阻 0603WAF1502T5E 1/10W,15KΩ,1%,0603(厚声)(编带)(RoHS) | AA27: 0.0018 | AB27: N30101006296 | AC27: 片式电阻 RC0603FR-0715KL 1/10W,15KΩ,1%,0603(国巨)(编带)(RoHS) | AD27: 0.0026 | AE27: N30101003070 | AF27: 片式电阻 CR0603FA1502G 1/10W,15KΩ,1%,0603(丽智)(编带)(RoHS) | AG27: 报价中
A28: 39 | B28: 硬件 | C28: N30199000117 | D28: 片式电阻 1/4W,100Ω,5%,1206(编带)(RoHS)(互换件) | E28: AB级替换 | F28: SMT | G28: 2 | H28: N30101003083 | I28: 片式电阻 RS-06K101JT 1/4W,100Ω,5%,1206(风华)(编带)(RoHS) | J28: 陈虹 | K28: MHDZ2 | L28: 厦门美赫电子有限公司 | M28: 0.0042 | N28: 0.0057 | O28: =(N28-M28)*G28 -> 0.003 | P28: 0 | Q28: =G28*M28 -> 0.0084 | R28: 56 | S28: 5000 | X28: R228,230 | Y28: N30101006680 | Z28: 片式电阻 1206W4J0101T5E 1/4W,100Ω,5%,1206(厚声)(编带)(RoHS) | AA28: 0.0042 | AB28: N30101005376 | AC28: 片式电阻 RC1206JR-07100RL 1/4W,100Ω,5%,1206(国巨)(编带)(RoHS) | AD28: 0.0075 | AE28: N30101003082 | AF28: 片式电阻 CR1206J40101G 1/4W,100Ω,5%,1206(丽智)(编带)(RoHS) | AG28: 报价中
A29: 40 | B29: 硬件 | C29: N30199000127 | D29: 片式电阻 1/10W,5.6KΩ,1%,0603(编带)(RoHS)(互换件) | E29: AB级替换 | F29: SMT | G29: 1 | H29: N30101003103 | I29: 片式电阻 RS-03K5601FT 1/10W,5.6KΩ,1%,0603(风华)(编带)(RoHS) | J29: 陈虹 | K29: MHDZ2 | L29: 厦门美赫电子有限公司 | M29: 0.0018 | N29: 0.0024 | O29: =(N29-M29)*G29 -> 0.0006 | P29: 0 | Q29: =G29*M29 -> 0.0018 | R29: 56 | S29: 5000 | X29: R84 | Y29: N30101007296 | Z29: 片式电阻 0603WAF5601T5E 1/10W,5.6KΩ,1%,0603(厚声)(编带)(RoHS) | AA29: 0.0018 | AB29: N30101006101 | AC29: 片式电阻 RC0603FR-075K6L 1/10W,5.6KΩ,1%,0603(国巨)(编带)(RoHS) | AD29: 0.0026 | AE29: N30101003102 | AF29: 片式电阻 CR0603FA5601G 1/10W,5.6KΩ,1%,0603(丽智)(编带)(RoHS) | AG29: 报价中
A30: 41 | B30: 硬件 | C30: N30199000137 | D30: 片式电阻 1/10W,470Ω,1%,0603(编带)(RoHS)(互换件) | E30: AB级替换 | F30: SMT | G30: 1 | H30: N30101007322 | I30: 片式电阻 0603WAF4700T5E 1/10W,470Ω,1%,0603(厚声)(编带)(RoHS) | J30: 罗城 | K30: 10648 | L30: 厚声国际贸易（昆山）有限公司 | M30: 0.0018 | N30: 0.0024 | O30: =(N30-M30)*G30 -> 0.0006 | P30: 0 | Q30: =G30*M30 -> 0.0018 | R30: 56 | S30: 0 | T30: 5000 | X30: R13 | Y30: N30101006140 | Z30: 片式电阻 RC0603FR-07470RL 1/10W,470Ω,1%,0603(国巨)(编带)(RoHS) | AA30: 0.0025 | AB30: N30101003123 | AC30: 片式电阻 RS-03K4700FT 1/10W,470Ω,1%,0603(风华)(编带)(RoHS) | AD30: 0.0025 | AE30: 301H0471H1 | AF30: 片式电阻 RC0603FR-07470RL/0603WAF4700T5E 1/10W,470Ω,1%,0603(国巨/厚声)(编带)(RoHS) | AG30: 报价中
A31: 42 | B31: 硬件 | C31: N30199000146 | D31: 片式电阻 1/10W,3KΩ,1%,0603(编带)(RoHS)(互换件) | E31: AB级替换 | F31: SMT | G31: 8 | H31: N30101003140 | I31: 片式电阻 RS-03K3001FT 1/10W,3KΩ,1%,0603(风华)(编带)(RoHS) | J31: 虞思旻 | K31: MHDZ2 | L31: 厦门美赫电子有限公司 | M31: 0.0018 | N31: 0.0024 | O31: =(N31-M31)*G31 -> 0.0048 | P31: 0 | Q31: =G31*M31 -> 0.0144 | R31: 56 | S31: 5000 | X31: R146,147,150,151,172,173,176,177 | Y31: N30101007384 | Z31: 片式电阻 0603WAF3001T5E 1/10W,3KΩ,1%,0603(厚声)(编带)(RoHS) | AA31: 0.0018 | AB31: N30101006156 | AC31: 片式电阻 RC0603FR-073KL 1/10W,3KΩ,1%,0603(国巨)(编带)(RoHS) | AD31: 0.0026 | AE31: 301H0033H1 | AF31: 片式电阻 RC0603FR-073KL/0603WAF3001T5E 1/10W,3KΩ,1%,0603(国巨/厚声)(编带)(RoHS) | AG31: 报价中
A32: 43 | B32: 硬件 | C32: N30199000171 | D32: 片式电阻 1/10W,5.1KΩ,1%,0603(编带)(RoHS)(互换件) | E32: AB级替换 | F32: SMT | G32: 2 | H32: N30101007306 | I32: 片式电阻 0603WAF5101T5E 1/10W,5.1KΩ,1%,0603(厚声)(编带)(RoHS) | J32: 罗城 | K32: 10648 | L32: 厚声国际贸易（昆山）有限公司 | M32: 0.0018 | N32: 0.0024 | O32: =(N32-M32)*G32 -> 0.0012 | P32: 0 | Q32: =G32*M32 -> 0.0036 | R32: 56 | S32: 0 | T32: 5000 | X32: R137,138 | Y32: N30101003189 | Z32: 片式电阻 RS-03K5101FT 1/10W,5.1KΩ,1%,0603(风华)(编带)(RoHS) | AA32: 0.0024 | AB32: N30101006104 | AC32: 片式电阻 RC0603FR-075K1L 1/10W,5.1KΩ,1%,0603(国巨)(编带)(RoHS) | AD32: 0.0026 | AE32: 301H0512H1 | AF32: 片式电阻 RC0603FR-075K1L/0603WAF5101T5E 1/10W,5.1KΩ,1%,0603(国巨/厚声)(编带)(RoHS) | AG32: 报价中
A33: 44 | B33: 硬件 | C33: N30199000219 | D33: 片式电阻 1/10W,100Ω,1%,0603(编带)(RoHS)(互换件) | E33: AB级替换 | F33: SMT | G33: 29 | H33: N30101003284 | I33: 片式电阻 RS-03K1000FT 1/10W,100Ω,1%,0603(风华)(编带)(RoHS) | J33: 陈虹 | K33: MHDZ2 | L33: 厦门美赫电子有限公司 | M33: 0.0018 | N33: 0.0024 | O33: =(N33-M33)*G33 -> 0.0174 | P33: 0 | Q33: =G33*M33 -> 0.0522 | R33: 56 | S33: 5000 | X33: R18,24,25,32,33,106-111,119-130,212-217 | Y33: N30101007520 | Z33: 片式电阻 0603WAF1000T5E 1/10W,100Ω,1%,0603(厚声)(编带)(RoHS) | AA33: 0.0018 | AB33: N30101006338 | AC33: 片式电阻 RC0603FR-07100RL 1/10W,100Ω,1%,0603(国巨)(编带)(RoHS) | AD33: 0.0025 | AE33: 301H0101H1 | AF33: 片式电阻 RC0603FR-07100RL/0603WAF1000T5E 1/10W,100Ω,1%,0603(国巨/厚声)(编带)(RoHS) | AG33: 报价中
A34: 45 | B34: 硬件 | C34: N30199000237 | D34: 片式电阻 1/10W,510Ω,1%,0603(编带)(RoHS)(互换件) | E34: AB级替换 | F34: SMT | G34: 2 | H34: N30101003319 | I34: 片式电阻 RS-03K5100FT 1/10W,510Ω,1%,0603(风华)(编带)(RoHS) | J34: 虞思旻 | K34: MHDZ2 | L34: 厦门美赫电子有限公司 | M34: 0.0018 | N34: 0.0024 | O34: =(N34-M34)*G34 -> 0.0012 | P34: 0 | Q34: =G34*M34 -> 0.0036 | R34: 56 | S34: 5000 | X34: R66,78 | Y34: N30101007307 | Z34: 片式电阻 0603WAF5100T5E 1/10W,510Ω,1%,0603(厚声)(编带)(RoHS) | AA34: 0.0018 | AB34: N30101006120 | AC34: 片式电阻 RC0603FR-07510RL 1/10W,510Ω,1%,0603(国巨)(编带)(RoHS) | AD34: 0.0025 | AE34: 301H0511H1 | AF34: 片式电阻 RC0603FR-07510RL/0603WAF5100T5E 1/10W,510Ω,1%,0603(国巨/厚声)(编带)(RoHS) | AG34: 报价中
A35: 46 | B35: 硬件 | C35: N30199000335 | D35: 片式电阻 1/10W,1.5KΩ,1%,0603(编带)(RoHS)(互换件) | E35: AB级替换 | F35: SMT | G35: 1 | H35: N30101003511 | I35: 片式电阻 RS-03K1501FT 1/10W,1.5KΩ,1%,0603(风华)(编带)(RoHS) | J35: 虞思旻 | K35: MHDZ2 | L35: 厦门美赫电子有限公司 | M35: 0.0018 | N35: 0.0024 | O35: =(N35-M35)*G35 -> 0.0006 | P35: 0 | Q35: =G35*M35 -> 0.0018 | R35: 56 | S35: 5000 | X35: R54 | Y35: N30101007469 | Z35: 片式电阻 0603WAF1501T5E 1/10W,1.5KΩ,1%,0603(厚声)(编带)(RoHS) | AA35: 0.0018 | AB35: N30101006268 | AC35: 片式电阻 RC0603FR-071K5L 1/10W,1.5KΩ,1%,0603(国巨)(编带)(RoHS) | AD35: 0.0026 | AE35: N30101003510 | AF35: 片式电阻 CR0603FA1501G 1/10W,1.5KΩ,1%,0603(丽智)(编带)(RoHS) | AG35: 报价中
A36: 47 | B36: 硬件 | C36: N30199000342 | D36: 片式电阻 1/10W,51KΩ,1%,0603(编带)(RoHS)(互换件) | E36: AB级替换 | F36: SMT | G36: 2 | H36: N30101003525 | I36: 片式电阻 RS-03K5102FT 1/10W,51KΩ,1%,0603(风华)(编带)(RoHS) | J36: 虞思旻 | K36: MHDZ2 | L36: 厦门美赫电子有限公司 | M36: 0.0018 | N36: 0.0024 | O36: =(N36-M36)*G36 -> 0.0012 | P36: 0 | Q36: =G36*M36 -> 0.0036 | R36: 56 | S36: 5000 | X36: R15,36 | Y36: N30101007305 | Z36: 片式电阻 0603WAF5102T5E 1/10W,51KΩ,1%,0603(厚声)(编带)(RoHS) | AA36: 0.0018 | AB36: N30101006118 | AC36: 片式电阻 RC0603FR-0751KL 1/10W,51KΩ,1%,0603(国巨)(编带)(RoHS) | AD36: 0.0026 | AE36: N30101003524 | AF36: 片式电阻 CR0603FA5102G 1/10W,51KΩ,1%,0603(丽智)(编带)(RoHS) | AG36: 报价中
A37: 48 | B37: 硬件 | C37: N30199000397 | D37: 片式电阻 1/4W,20KΩ,1%,1206(编带)(RoHS)(互换件) | E37: AB级替换 | F37: SMT | G37: 1 | H37: N30101006792 | I37: 片式电阻 1206W4F2002T5E 1/4W,20KΩ,1%,1206(厚声)(编带)(RoHS) | J37: 陈虹 | K37: HSMY2 | L37: 厚声国际贸易（昆山）有限公司 | M37: 0.0058 | P37: 0 | Q37: =G37*M37 -> 0.0058 | R37: 49 | S37: 1 | X37: R57 | Y37: N30101003634 | Z37: 片式电阻 RS-06K2002FT 1/4W,20KΩ,1%,1206(风华)(编带)(RoHS) | AA37: 0.0069 | AB37: N30101005517 | AC37: 片式电阻 RC1206FR-0720KL 1/4W,20KΩ,1%,1206(国巨)(编带)(RoHS) | AD37: 0.008 | AE37: N30101003633 | AF37: 片式电阻 CR1206F42002G 1/4W,20KΩ,1%,1206(丽智)(编带)(RoHS) | AG37: 报价中
A38: 49 | B38: 硬件 | C38: N30199000444 | D38: 片式电阻 1/10W,6.2KΩ,1%,0603(编带)(RoHS)(互换件) | E38: AB级替换 | F38: SMT | G38: 1 | H38: N30101001125 | I38: 片式电阻 0603WAF6201T5E 1/10W,6.2KΩ,1%,0603(厚声)(编带)(RoHS) | J38: 陈虹 | K38: HSMY2 | L38: 厚声国际贸易（昆山）有限公司 | M38: 0.0018 | N38: 0.0024 | O38: =(N38-M38)*G38 -> 0.0006 | P38: 0 | Q38: =G38*M38 -> 0.0018 | R38: 84 | S38: 5000 | X38: R79 | Y38: N30101003728 | Z38: 片式电阻 RS-03K6201FT 1/10W,6.2KΩ,1%,0603(风华)(编带)(RoHS) | AA38: 0.0018 | AB38: 301H0622H1 | AC38: 片式电阻 RC0603FR-076K2L 1/10W,6.2KΩ,1%,0603(国巨)(编带)(RoHS) | AD38: 0.0025 | AE38: N30101003727 | AF38: 片式电阻 CR0603FA6201G 1/10W,6.2KΩ,1%,0603(丽智)(编带)(RoHS) | AG38: 报价中
A39: 50 | B39: 硬件 | C39: N30199000493 | D39: 片式电阻 1/4W,120Ω,5%,1206(编带)(RoHS)(互换件) | E39: AB级替换 | F39: SMT | G39: 2 | H39: N30101003826 | I39: 片式电阻 RS-06K121JT 1/4W,120Ω,5%,1206(风华)(编带)(RoHS) | J39: 陈虹 | K39: MHDZ2 | L39: 厦门美赫电子有限公司 | M39: 0.0043 | N39: 0.0057 | O39: =(N39-M39)*G39 -> 0.0028 | P39: 0 | Q39: =G39*M39 -> 0.0086 | R39: 56 | S39: 5000 | T39: 5000 | X39: R19,229 | Y39: N30101006672 | Z39: 片式电阻 1206W4J0121T5E 1/4W,120Ω,5%,1206(厚声)(编带)(RoHS) | AA39: 0.0043 | AB39: N30101005381 | AC39: 片式电阻 RC1206JR-07120RL 1/4W,120Ω,5%,1206(国巨)(编带)(RoHS) | AD39: 0.0075 | AE39: 301H012185 | AF39: 片式电阻 RC1206JR-07120RL/1206W4J0121T5E 1/4W,120Ω,5%,1206(国巨/厚声)(编带)(RoHS) | AG39: 报价中
A40: 51 | B40: 硬件 | C40: N30199000523 | D40: 片式电阻 1/4W,1KΩ,1%,1206(编带)(RoHS)(互换件) | E40: AB级替换 | F40: SMT | G40: 4 | H40: N30101003885 | I40: 片式电阻 RS-06K1001FT 1/4W,1KΩ,1%,1206(风华)(编带)(RoHS) | J40: 陈虹 | K40: MHDZ2 | L40: 厦门美赫电子有限公司 | M40: 0.0057 | N40: 0.0075 | O40: =(N40-M40)*G40 -> 0.0072 | P40: 0 | Q40: =G40*M40 -> 0.0228 | R40: 56 | S40: 5000 | X40: R37,86,88,91 | Y40: N30101006828 | Z40: 片式电阻 1206W4F1001T5E 1/4W,1KΩ,1%,1206(厚声)(编带)(RoHS) | AA40: 0.0057 | AB40: N30101005505 | AC40: 片式电阻 RC1206FR-071KL 1/4W,1KΩ,1%,1206(国巨)(编带)(RoHS) | AD40: 0.0075 | AE40: N30101003884 | AF40: 片式电阻 CR1206F41001G 1/4W,1KΩ,1%,1206(丽智)(编带)(RoHS) | AG40: 报价中
...

Sheet 客供料
A1: 26P | B1: D5A13H000000 | E1: TIMS735EXV/9A4A | P1: 8月 | Q1: 9月 | R1: 10月 | S1: 11月 | T1: 12月
A2: 序号 | B2: 物料 | C2: 型号 | D2: 位号 | E2: 数量 | F2: 工艺 | G2: 品牌 | H2: 备注 | I2: 单价 | J2: 渠道 | K2: 交期 | L2: 降后价 | M2: 供应商 | N2: 2026-3-24降价 | P2: 200 | Q2: 200 | R2: 200 | S2: 150 | T2: 150 | U2: 合计 | V2: 累计降幅
A3: 2 | B3: 薄膜电容 | C3: 40μF/1100V/4Pin | D3: C125, C126, C127 | E3: 3 | F3: HI | G3: 松下 | H3: 家中机也用 | I3: 23.98 | J3: 港德 | K3: 4W | L3: 20.3739 | P3: 600 | Q3: 600 | R3: 600 | S3: 450 | T3: 450 | U3: 61.1217 | V3: 10.8183
A4: 3 | B4: 共模滤波器 | C4: CMF50F04QX1 4mH,50A(赛特勒)(RoHS) | D4: L1,2 | E4: 2 | F4: N32302000353 | G4: 菲尔泰科 | I4: 45.8 | J4: 菲尔泰科 | K4: 3W | L4: 20 | P4: 400 | Q4: 400 | R4: 400 | S4: 300 | T4: 300 | U4: 91.6 | V4: 51.6
A5: 4 | B5: 共模电感 | C5: CM10100ZJ-1/9A/15mH | D5: L2 | E5: 1 | F5: HI | G5: 菲尔泰科 | I5: 7 | J5: 菲尔泰科 | K5: 2W | L5: 7 | P5: 200 | Q5: 200 | R5: 200 | S5: 150 | T5: 150 | U5: 7 | V5: 0
A6: 5 | B6: PIM | C6: 100A/1200V/FP100R12N2T7 | D6: A1 | E6: 1 | F6: HI | G6: 英飞凌 | I6: 307.3 | J6: 晶川 | K6: 4-6W | L6: 305 | M6: 芯硕 | N6: 302 | O6: 晶川2026-3-24降价 | P6: 200 | Q6: 200 | R6: 200 | S6: 150 | T6: 150 | U6: 307.3 | V6: 5.3
A7: 6 | B7: 栅极驱动IC | C7: 1EDI20I12MF/SOP-8 | D7: N8, N9, N10, N11, N12, N13 | E7: 6 | F7: SMT | G7: 英飞凌 | I7: 3.83 | J7: 晶川 | K7: 4-6W | L7: 3.73 | M7: 芯硕 | N7: 3.7 | O7: 晶川2026-3-24降价 | P7: 1200 | Q7: 1200 | R7: 1200 | S7: 900 | T7: 900 | U7: 22.98 | V7: 0.78
A8: 7 | B8: IPM | C8: 功率模块 RCI20C60D6U (20A,600V)(IPM模块)(NJTJ专用)(银河边缘)(RoHS) | D8: A2, A3 | E8: 2 | F8: HI | G8: 国创 | I8: 23 | J8: 银河 | K8: 4W | N8: 18.9049 | O8: 2026-3-26降价 由银河转京西 | P8: 400 | Q8: 400 | R8: 400 | S8: 300 | T8: 300 | U8: 46 | V8: 8.1902
A9: 8 | B9: ACDC | C9: TOP264K/ESOP-12B | D9: N3 | E9: 1 | F9: HI | G9: PI | I9: 2.818 | J9: 北高智 | K9: 4-6W | P9: 200 | Q9: 200 | R9: 200 | S9: 150 | T9: 150 | U9: 2.818 | V9: 0
A10: 9 | B10: MCU | C10: R5F526T8ADFM/LQFP64 | D10: N22, N23 | E10: 2 | F10: SMT | G10: 瑞萨 | H10: 家中机也用 | I10: 7.75 | J10: 新晔 | K10: 12W | P10: 400 | Q10: 400 | R10: 400 | S10: 300 | T10: 300 | U10: 15.5 | V10: 0
I11: 554.3197 | U11: 554.3197 | V11: 76.69
A12: 20P | B12: D5A13G000000 | E12: TIMS560EXV9B4A | P12: 8月 | Q12: 9月 | R12: 10月 | S12: 11月 | T12: 12月 | U12: 490.5484 | V12: 10.531
I13: 单价 | J13: 渠道 | K13: 交期 | P13: 150 | Q13: 150 | R13: 150 | S13: 120 | T13: 120
A14: 2 | B14: 薄膜电容 | C14: 40μF/1100V/4Pin | D14: C125, C126, C127 | E14: 3 | F14: HI | G14: 松下 | H14: 家中机通用 | I14: 23.98 | J14: 港德 | K14: 4W | L14: 20.3739 | P14: 450 | Q14: 450 | R14: 450 | S14: 360 | T14: 360 | U14: 71.94 | V14: 10.8183
A15: 3 | B15: 共模滤波器 | C15: CMF50F04QX1 4mH,50A(赛特勒)(RoHS) | D15: L1,2 | E15: 2 | F15: N32302000353 | G15: 菲尔泰科 | I15: 45.8 | J15: 菲尔泰科 | K15: 3W | L15: 20 | P15: 300 | Q15: 300 | R15: 300 | S15: 240 | T15: 240 | U15: 91.6 | V15: 51.6
A16: 4 | B16: 共模电感 | C16: CM10100ZJ-1/9A/15mH | D16: L2 | E16: 1 | F16: HI | G16: 菲尔泰科 | I16: 7 | J16: 菲尔泰科 | K16: 2W | L16: 7 | P16: 150 | Q16: 150 | R16: 150 | S16: 120 | T16: 120 | U16: 7 | V16: 0
A17: 5 | B17: PIM | C17: 功率模块 FP75R12N2T7 (1.2KV,75A)(PIM模块)(Infineon)(RoHS) | D17: A1 | E17: 1 | F17: HI | G17: 英飞凌 | I17: 276 | J17: 晶川 | K17: 4-6W | L17: 273 | M17: 芯硕 | N17: 270 | O17: 晶川 | P17: 150 | Q17: 150 | R17: 150 | S17: 120 | T17: 120 | U17: 276 | V17: 6
A18: 6 | B18: 栅极驱动IC | C18: 1EDI20I12MF/SOP-8 | D18: N8, N9, N10, N11, N12, N13 | E18: 6 | F18: SMT | G18: 英飞凌 | I18: 3.83 | J18: 晶川 | K18: 4-6W | L18: 3.73 | M18: 芯硕 | N18: 3.7 | O18: 晶川 | P18: 900 | Q18: 900 | R18: 900 | S18: 720 | T18: 720 | U18: 22.98 | V18: 0.78
A19: 7 | B19: IPM | C19: 功率模块 RCI20C60D6U (20A,600V)(IPM模块)(NJTJ专用)(银河边缘)(RoHS) | D19: A2, A3 | E19: 2 | F19: HI | G19: 国创 | I19: 23 | J19: 银河 | K19: 4W | N19: 18.9049 | O19: 2026-3-26降价 由银河转京西 | P19: 300 | Q19: 300 | R19: 300 | S19: 240 | T19: 240 | U19: 46 | V19: 8.1902
A20: 8 | B20: ACDC | C20: TOP264K/ESOP-12B | D20: N3 | E20: 1 | F20: HI | G20: PI | I20: 2.818 | J20: 北高智 | K20: 4-6W | L20: 2.818 | P20: 150 | Q20: 150 | R20: 150 | S20: 120 | T20: 120 | U20: 2.818 | V20: 2.818
A21: 9 | B21: MCU | C21: R5F526T8ADFM/LQFP64 | D21: N22, N23 | E21: 2 | F21: SMT | G21: 瑞萨 | H21: 家中机也用 | I21: 7.75 | J21: 新晔 | K21: 12W | P21: 300 | Q21: 300 | R21: 300 | S21: 240 | T21: 240 | U21: 15.5
I22: 533.838 | U22: 533.838
U23: 472.423 | V23: 80.21
