Workbook

Sheet 使用说明
A1: 产品成本测算报价表 · 使用说明
A3: 怎么用 | B3: 首页【报价汇总】只填：产品信息、成品尺寸与单台净重、每箱件数、是否带散热器/组装结构、是否含整托、物流产品、目的地、每票件数。包装费与运费全部自动算。黄色底=必填待填，填完后自动变绿。
A4: 包装费 | B4: 首页【报价汇总】填【带散热器/组装结构】是/否即可自动选方案：选「是」→大板（EPE珍珠棉+纸箱+护角+托盘+缠绕膜+打包带）；选「否」→小板（防静电气泡袋+隔板+纸箱+护角+托盘+缠绕膜）。带散热器/组装结构（暖通商空大功率驱动板）选「是」，水泵、风机板选「否」。单价与系数在《参数》页改。
A5: 运费 | B5: 依据《跨越费率》（源自青岛国创VIP报价表）按 实重/体积重取大→起重→分段单价 计算单票运费，再摊到单件。目的地在首页下拉选择，产品可选次日达/特惠普运。
A6: 物料明细/加工及工装 | B6: 沿用原模板，硬件/结构件/辅助材料与加工费、工装分摊在此填写。
A7: 成本与报价 | B7: 总成本=材料+加工+工装+包装+运费+利润；建议报价=总成本/(1-目标毛利率)。毛利率/税率在《参数》页改。
A8: 注意 | B8: 跨越费率为参考价，可在《跨越费率》页直接改；金额默认不含税；包装费按方案清单自动算。

Sheet 报价汇总
A1: 产品成本测算报价表（包装费 + 运费自动计算）
A3: 一、产品基础信息（输入）
A4: 产品代码 | B4: GCSL-SX-C-01 | Z4: 福州市/厦门市/泉州市
A5: 产品名称 | B5: 2.5kW水冷机驱动方案 | Z5: 宁德市/莆田市/漳州市
A6: 客户名称 | B6: 新能先锋 | Z6: 龙岩市/三明市/南平市
A7: 报价日期 | B7: =TODAY() -> 46307 | Z7: 拉萨市
A8: 年需求量(PCS) | B8: 1000 | Z8: 日喀则市/山南市/林芝市/昌都市/那曲市/阿里地区
A9: MOQ(PCS) | B9: 200 | Z9: 贵阳市/遵义市/安顺市
A10: 备注 | Z10: 黔南布依族苗族自治州/黔东南苗族侗族自治州/铜仁市/毕节市/六盘水市/黔西南布依族苗族自治州
Z11: 广州市/深圳市/珠海市/中山市/东莞市
A12: 二、产品规格（输入，驱动包装费） | Z12: 江门市/惠州市/佛山市/肇庆市
A13: 成品长(mm,含散热器) | B13: 380 | Z13: 汕尾市/阳江市/揭阳市/茂名市/韶关市/梅州市/汕头市/湛江市/河源市/清远市/云浮市/潮州市
A14: 成品宽(mm) | B14: 320 | Z14: 武汉市/鄂州市
A15: 成品高(mm) | B15: 150 | Z15: 襄阳市/孝感市/黄石市/荆州市/宜昌市/神农架林区/十堰市/随州市/荆门市
A16: 单台净重(kg) | B16: 4 | Z16: 黄冈市/咸宁市/恩施土家族苗族自治州/潜江市/仙桃市/天门市
A17: 每箱件数N | B17: 4 | Z17: 株洲市/长沙市/湘潭市
A18: 是否含整托分摊 | B18: 是 | Z18: 益阳市
A19: 带散热器/组装结构(是/否) | B19: 是 | D19: =IF(B19="是","自动→大板：EPE珍珠棉+纸箱+护角+托盘+缠绕膜+打包带","自动→小板：防静电气泡袋+隔板+纸箱+护角+托盘+缠绕膜") -> 自动→大板：EPE珍珠棉+纸箱+护角+托盘+缠绕膜+打包带 | Z19: 岳阳市/衡阳市/郴州市/常德市/娄底市/邵阳市/湘西土家族苗族自治州/张家界市/怀化市/永州市
A20: 三、物流（输入，驱动运费） | Z20: 重庆市
A21: 物流产品 | B21: 特惠普运 | Z21: 成都市/资阳市/眉山市
A22: 目的地 | B22: 宁波 | Z22: 绵阳市
A23: 每票件数M | B23: 50 | Z23: 自贡市/南充市/达州市/遂宁市/广安市/巴中市/泸州市/宜宾市/内江市/乐山市/雅安市/德阳市/广元市
A24: 声明价值(元/票,可选) | Z24: 攀枝花市/凉山彝族自治州/甘孜藏族自治州/阿坝藏族羌族自治州
A25: 注 | B25: 次日达与特惠普运的目的地划分不同，请选择与所选产品一致的目的地；选错该运费显示空白。 | Z25: 合肥市/芜湖市/马鞍山市
A26: 四、成本构成（未税/单台，自动计算） | Z26: 滁州市/蚌埠市/六安市
A27: 成本项目 | B27: 金额 | C27: 单位 | D27: 备注 | E27: 公式 | Z27: 淮南市/安庆市/宿州市/亳州市/阜阳市/黄山市/淮北市/铜陵市/宣城市/池州市
A28: 硬件材料 | B28: =SUMIFS(物料明细!$H:$H,物料明细!$B:$B,"硬件") -> 161.54001 | C28: 元/台 | D28: 物料明细 | Z28: 乌鲁木齐市
A29: 结构件 | B29: =SUMIFS(物料明细!$H:$H,物料明细!$B:$B,"结构件") -> 35.39823 | C29: 元/台 | D29: 物料明细 | Z29: 塔城地区/白杨市/新星市/哈密市/昆玉市/和田地区/北屯市/阿勒泰地区/克孜勒苏柯尔克孜自治州/双河市/博尔塔拉蒙古自治州/克拉玛依市/胡杨河市/石河子市/五家渠市/昌吉回族自治州/吐鲁番市/巴音郭楞蒙古自治州/铁门关市/阿克苏地区/阿拉尔市/图木舒克市/喀什地区/伊犁哈萨克自治州/可克达拉市
A30: 包装材料 | B30: =包装计算!$B$43 -> 24.745033 | C30: 元/台 | D30: 包装计算（自动） | Z30: 南京市/无锡市/苏州市/常州市
A31: 辅助材料 | B31: =SUMIFS(物料明细!$H:$H,物料明细!$B:$B,"辅助材料") -> 0 | C31: 元/台 | D31: 物料明细 | Z31: 镇江市/南通市/扬州市
A32: 加工费 | B32: =加工及工装!F13 -> 16.961333 | C32: 元/台 | D32: 加工及工装 | Z32: 盐城市/徐州市/淮安市/连云港市/泰州市/宿迁市
A33: 工装分摊 | B33: =加工及工装!H23 -> 32.42 | C33: 元/台 | D33: 加工及工装 | Z33: 天津市
A34: 运费 | B34: =运费计算!$B$33 | C34: 元/台 | D34: 运费计算（跨越费率） | Z34: 长春市
A35: 利润 | B35: =SUM(B28:B34)*0.15 -> 40.659691 | C35: 元/台 | D35: 工厂利润 | Z35: 吉林市
A36: 总成本未税 | B36: =SUM(B28:B35) -> 311.7243 | C36: 元/台 | D36: 自动汇总 | Z36: 延边朝鲜族自治州/四平市/通化市/白城市/辽源市/松原市/白山市
Z37: 银川市
A38: 五、自动报价结果 | Z38: 石嘴山市/吴忠市/固原市/中卫市
A39: 报价项目 | B39: 结果 | C39: 单位 | D39: 备注 | E39: 公式 | Z39: 石家庄市/廊坊市
A40: 目标毛利率 | B40: =参数!B4 -> 0.15 | C40: % | D40: 参数页可改 | Z40: 邯郸市/保定市/雄安新区/唐山市/沧州市/秦皇岛市
A41: 建议报价未税 | B41: =IFERROR(B36/(1-B40),0) -> 366.73447 | C41: 元/台 | D41: 总成本/(1-毛利率) | Z41: 张家口市/承德市/衡水市/邢台市
...

Sheet 物料明细
A1: 物料明细
A2: 序号 | B2: 物料分类 | C2: 物料编码 | D2: 物料名称规格 | E2: 单机用量 | F2: 未税单价 | G2: 损耗率 | H2: 金额 | I2: 是否客供 | J2: 备注
A3: 1 | B3: 硬件 | C3: HW001 | D3: 薄膜电容/30μF/1.1kV/P52.5×4/-40~105℃/MI | E3: 1 | F3: 11.504425 | G3: 0.02 | H3: =IF(I3="是",0,E3*F3*(1+G3)) -> 11.734514 | J3: 在线参考|含税→未税
A4: 2 | B4: 硬件 | C4: HW002 | D4: 片式瓷介电容/0603/1nF/10%/50V/X7R/SMT | E4: 22 | F4: 0.012389 | G4: 0.02 | H4: =IF(I4="是",0,E4*F4*(1+G4)) -> 0.27800916 | J4: 在线参考|含税→未税
A5: 3 | B5: 硬件 | C5: HW003 | D5: 片式瓷介电容/1206/10uF/10%/50V/X7R/SMT | E5: 6 | F5: 0.442478 | G5: 0.02 | H5: =IF(I5="是",0,E5*F5*(1+G5)) -> 2.7079654 | J5: 在线参考|含税→未税
A6: 4 | B6: 硬件 | C6: HW004 | D6: 片式瓷介电容/0603/1uF/10%/50V/X7R/SMT | E6: 11 | F6: 0.047788 | G6: 0.02 | H6: =IF(I6="是",0,E6*F6*(1+G6)) -> 0.53618136 | J6: 在线参考|含税→未税
A7: 5 | B7: 硬件 | C7: HW005 | D7: 片式瓷介电容/0603/100nF/10%/50V/X7R/SMT | E7: 31 | F7: 0.012389 | G7: 0.02 | H7: =IF(I7="是",0,E7*F7*(1+G7)) -> 0.39174018 | J7: 在线参考|含税→未税
A8: 6 | B8: 硬件 | C8: HW006 | D8: 片式瓷介电容/1206/1nF/10%/200V/X7R/SMT | E8: 2 | F8: 0.123894 | G8: 0.02 | H8: =IF(I8="是",0,E8*F8*(1+G8)) -> 0.25274376 | J8: 在线参考|含税→未税
A9: 7 | B9: 硬件 | C9: HW007 | D9: 薄膜电容-100nF -1000V | E9: 1 | F9: 0.568319 | G9: 0.02 | H9: =IF(I9="是",0,E9*F9*(1+G9)) -> 0.57968538 | J9: 在线参考|含税→未税
A10: 8 | B10: 硬件 | C10: HW008 | D10: 片式瓷介电容/0603/100pF/5%/50V/X7R/SMT | E10: 7 | F10: 0.012389 | G10: 0.02 | H10: =IF(I10="是",0,E10*F10*(1+G10)) -> 0.08845746 | J10: 在线参考|含税→未税
A11: 9 | B11: 硬件 | C11: HW009 | D11: 瓷介电容/CT81/2kV/1000P/K/AI | E11: 1 | F11: 0.10531 | G11: 0.02 | H11: =IF(I11="是",0,E11*F11*(1+G11)) -> 0.1074162 | J11: 在线参考|含税→未税
A12: 10 | B12: 硬件 | C12: HW010 | D12: 薄膜电容/聚丙烯/220nF/1000V/±10%/L13×H13×T7/P=10/d0.6/-40 ℃ ~ 105 ℃/MI | E12: 1 | F12: 0.434513 | G12: 0.02 | H12: =IF(I12="是",0,E12*F12*(1+G12)) -> 0.44320326 | J12: 在线参考|含税→未税
A13: 11 | B13: 硬件 | C13: HW011 | D13: 片式瓷介电容/0603/4.7uF/10%/16V/X7R/SMT | E13: 4 | F13: 0.065487 | G13: 0.02 | H13: =IF(I13="是",0,E13*F13*(1+G13)) -> 0.26718696 | J13: 在线参考|含税→未税
A14: 12 | B14: 硬件 | C14: HW012 | D14: 安规电容/4.7nF/400VAC/Y1/D12.0×T5.5/d0.65/P=10/编带/-40℃~125℃/MI | E14: 1 | F14: 0.142832 | G14: 0.02 | H14: =IF(I14="是",0,E14*F14*(1+G14)) -> 0.14568864 | J14: 在线参考|含税→未税
... A115: 113 | B115: 硬件 | C115: HW113 | D115: 立式杜邦针/PZ/4P | E115: 1 | F115: 0.132743 | G115: 0.02 | H115: =IF(I115="是",0,E115*F115*(1+G115)) -> 0.13539786 | J115: 主库型号|含税→未税
A116: 114 | B116: 结构件 | C116: STR114 | D116: 散热器-160*160 | E116: 1 | F116: =40/1.13 -> 35.39823 | G116: 0 | H116: =IF(I116="是",0,E116*F116*(1+G116)) -> 35.39823 | J116: 人工修订|含税→未税

Sheet 加工及工装
A1: 加工费及工装治具
A3: 一、加工费
A4: 类型 | B4: 工序名称 | C4: 数量/点数 | D4: 单价 | E4: 确认 | F4: 费用 | G4: 内部成本 | H4: 差异
A5: SMT | B5: 0402/0603贴片 | C5: 803 | D5: 0.006 | E5: 是 | F5: =IF(E5="是",IFERROR(C5*D5,0),0) -> 4.818 | H5: =IFERROR(F5-G5,0) -> 4.818
A6: AI | B6: 机插 | C6: 0 | D6: 0.0171 | E6: 是 | F6: =IF(E6="是",IFERROR(C6*D6,0),0) -> 0 | H6: =IFERROR(F6-G6,0) -> 0
A7: DIP | B7: DIP焊接 | C7: 67 | D7: 0.03 | E7: 是 | F7: =IF(E7="是",IFERROR(C7*D7,0),0) -> 2.01 | H7: =IFERROR(F7-G7,0) -> 2.01
A8: 组装 | B8: 装配人工 | C8: 2 | D8: =36/60 -> 0.6 | E8: 是 | F8: =IF(E8="是",IFERROR(C8*D8,0),0) -> 1.2 | H8: =IFERROR(F8-G8,0) -> 1.2
A9: 测试 | B9: FCT/ICT | C9: 2 | D9: =100/60 -> 1.6666667 | E9: 是 | F9: =IF(E9="是",IFERROR(C9*D9,0),0) -> 3.3333333 | H9: =IFERROR(F9-G9,0) -> 3.3333333
A10: 包装 | B10: 包装人工 | C10: 1 | D10: =36/60 -> 0.6 | E10: 是 | F10: =IF(E10="是",IFERROR(C10*D10,0),0) -> 0.6 | H10: =IFERROR(F10-G10,0) -> 0.6
A11: 物流 | B11: 物流费用 | C11: 1 | D11: =20/4 -> 5 | E11: 是 | F11: =IF(E11="是",IFERROR(C11*D11,0),0) -> 5 | H11: =IFERROR(F11-G11,0) -> 5
F12: =IF(E12="是",IFERROR(C12*D12,0),0) -> 0 | H12: =IFERROR(F12-G12,0) -> 0
E13: 加工费小计 | F13: =SUM(F5:F12) -> 16.961333 | G13: =SUM(G5:G12) -> 0
A16: 二、工装治具
A17: 类型 | B17: 治具名称 | C17: 数量 | D17: 单价 | E17: 总价 | F17: 确认 | G17: 分摊数量 | H17: 单台分摊
A18: 钢网 | B18: SMT钢网 | C18: 2 | D18: 210 | E18: =IFERROR(C18*D18,0) -> 420 | F18: 是 | G18: 1000 | H18: =IF(F18="是",IFERROR(E18/G18,0),0) -> 0.42
A19: 测试工装 | B19: FCT测试工装 | C19: 4 | D19: 6000 | E19: =IFERROR(C19*D19,0) -> 24000 | F19: 是 | G19: 1000 | H19: =IF(F19="是",IFERROR(E19/G19,0),0) -> 24
A20: 模具 | B20: 喷涂治具 | C20: 4 | D20: 2000 | E20: =IFERROR(C20*D20,0) -> 8000 | F20: 是 | G20: 1000 | H20: =IF(F20="是",IFERROR(E20/G20,0),0) -> 8
A21: 其他 | B21: 其他一次性费用 | C21: 0 | D21: 0 | E21: =IFERROR(C21*D21,0) -> 0 | F21: 是 | G21: 1000 | H21: =IF(F21="是",IFERROR(E21/G21,0),0) -> 0
E22: =IFERROR(C22*D22,0) -> 0 | H22: =IF(F22="是",IFERROR(E22/G22,0),0) -> 0
E23: =SUM(E18:E22) -> 32420 | H23: =SUM(H18:H22) -> 32.42

Sheet 参数
A1: 参数设置
A2: 参数项 | B2: 参数值 | C2: 说明
A3: 税率 | B3: 0.13 | C3: 增值税率，默认13%
A4: 目标毛利率 | B4: 0.15 | C4: 报价目标毛利率
A5: 默认损耗率 | B5: 0.02 | C5: 物料未填损耗率时使用
A6: 默认分摊数量 | B6: 1000 | C6: 工装治具费用默认分摊数量
A8: 二、包装与整托参数
A9: 参数项 | B9: 参数值 | C9: 单位 | D9: 说明
A10: 防静电气泡袋单价 | B10: 3 | C10: 元/㎡
A11: 气泡袋单边余量 | B11: 30 | C11: mm
A12: 干燥剂单价 | B12: 0.1 | C12: 元/袋
A13: 湿度指示卡单价 | B13: 0.3 | C13: 元/张
A14: EPE珍珠棉单价 | B14: 1800 | C14: 元/m³
A15: EPE珍珠棉密度 | B15: 22 | C15: kg/m³
A16: 单瓦楞3层纸板 | B16: 2 | C16: 元/㎡
A17: 双瓦楞5层纸板 | B17: 3.2 | C17: 元/㎡
A18: 重型7层纸板 | B18: 5 | C18: 元/㎡
A19: 双瓦楞纸板克重 | B19: 700 | C19: g/㎡
A20: 纸箱制箱加工费 | B20: 1.5 | C20: 元/个
A21: 材料损耗率 | B21: 0.05 | C21: 比例
... A32: 每托层数 | B32: 4 | C32: 层
A34: 三、物流参数
A35: 参数项 | B35: 参数值 | C35: 单位 | D35: 说明
A36: 体积重系数 | B36: 6000 | C36: ㎝³/kg
A37: 保费费率 | B37: 0.004 | C37: ‰即0.4%
A38: 保费最低收费 | B38: 5 | C38: 元/票
A39: 是否计保费 | B39: 否 | C39: 是/否
A41: 四、包装方案参数（小板/大板）
A42: 参数项 | B42: 参数值 | C42: 单位 | D42: 说明
A43: 防静电气泡袋克重 | B43: 60 | C43: g/㎡ | D43: 气泡袋面密度
A44: 隔板单价 | B44: 0.3 | C44: 元/件 | D44: 小板每件隔板
A45: 隔板克重 | B45: 20 | C45: g/件 | D45: 小板隔板重量

Sheet 包装计算
A1: 包装费计算（自动，按包装方案清单）
A3: 一、输入（自动取自报价汇总）
A4: 成品长(mm) | B4: =报价汇总!B13 -> 380
A5: 成品宽(mm) | B5: =报价汇总!B14 -> 320
A6: 成品高(mm) | B6: =报价汇总!B15 -> 150
A7: 每箱件数N | B7: =报价汇总!B17 -> 4
A8: 是否含整托 | B8: =报价汇总!B18 -> 是
A9: 包装方案(自动) | B9: =IF(报价汇总!B19="是","大板","小板") -> 大板
A11: 二、包装几何（自动）
A12: 成品最大边长(mm) | B12: =MAX(B4:B6) -> 380
A13: 缓冲厚度t(mm) | B13: =VLOOKUP($B$12,$A$58:$D$61,3,TRUE()) -> 25
A14: 箱内长(mm) | B14: =B4+2*B13+参数!$B$22 -> 440
A15: 箱内宽(mm) | B15: =B5+2*B13+参数!$B$22 -> 380
A16: 箱内高(mm) | B16: =B7*(B6+2*B13)+参数!$B$22 -> 810
A17: 单箱体积(㎝³) | B17: =B14*B15*B16/1000 -> 135432
A19: 三、内包装材料费（单件）
A20: 气泡袋长(mm) | B20: =B4+B6+2*参数!$B$11 -> 590
A21: 气泡袋宽(mm) | B21: =B5+B6+2*参数!$B$11 -> 530
A22: 气泡袋面积(㎡) | B22: =B20*B21/10^6 -> 0.3127
A23: 气泡袋费(元/件) | B23: =B22*参数!$B$10 -> 0.9381
A24: 隔板费(元/件) | B24: =IF($B$9="小板",IF(OR($B$7="",$B$7=0),0,参数!$B$44*MAX($B$7-1,0)/$B$7),0) -> 0
A25: EPE体积(㎥/件) | B25: =2*B13*(B4*B5+B4*B6+B5*B6)/10^9 -> 0.01133
A26: EPE费(元/件) | B26: =B25*参数!$B$14 -> 20.394
A27: 内包材料费(元/件) | B27: =IF($B$9="小板",B23+B24,B26) -> 20.394
A28: 纸箱用纸面积(㎡) | B28: =(B14+B15)*2*(B15+2*B16)/10^6*(1+参数!$B$21) -> 3.444
A29: 瓦楞类型 | B29: =VLOOKUP($B$12,$A$58:$D$61,4,TRUE()) -> 双瓦楞5层
A30: 纸板单价(元/㎡) | B30: =VLOOKUP(B29,$A$65:$B$67,2,FALSE()) -> 3.2
A31: 纸箱费(元/箱) | B31: =B28*B30+参数!$B$20 -> 12.5208
A32: 纸箱费(元/件) | B32: =IF(OR(B7="",B7=0),0,B31/B7) -> 3.1302
A33: 辅料费(元/件) | B33: =IF(OR(B7="",B7=0),0,(参数!$B$23+参数!$B$24)/B7) -> 0.0875
A34: 内包装单件费(元) | B34: =B27+B32+B33 -> 23.6117
A36: 四、整托分摊（可选，勾选含整托生效）
A37: 每箱占地(㎡) | B37: =B14*B15/10^6 -> 0.1672
A38: 每托件数(件) | B38: =IF(OR(B37="",B37=0),0,ROUNDDOWN(参数!$B$31/B37,0)*参数!$B$32) -> 24
A39: 每托包装费(元/托) | B39: =参数!$B$29+参数!$B$25/参数!$B$26+参数!$B$27*参数!$B$28+IF($B$9="大板",参数!$B$30,0) -> 27.2
A40: 整托分摊(元/件) | B40: =IF(OR(B38="",B38=0),0,B39/B38) -> 1.1333333
A41: 包装增重(kg/件) | B41: =IF(OR(B7="",B7=0),0,IF($B$9="小板",B22*参数!$B$43/1000,B25*参数!$B$15)+B28*参数!$B$19/1000/B7+IF($B$9="小板",参数!$B$45/1000*MAX($B$7-1,0)/$B$7,0)+0.005) -> 0.85696
A43: 包装费合计(元/件) | B43: =B34+IF($B$8="是",B40,0) -> 24.745033
A45: 五、包装方案清单对照（√=该方案包含）
A46: 包装物料 | B46: 单位 | C46: 单价(元) | D46: 小板 | E46: 大板
...

Sheet 跨越费率
A1: 跨越VIP运费费率（源自青岛国创VIP报价表，可按需改价）
A3: 产品 | B3: 目的省份 | C3: 目的地 | D3: 首重重量 | E3: 首重价格 | F3: 起重 | G3: 最低收费 | H3: 段1单价 | I3: 段2单价 | J3: 段3单价 | K3: 段4单价 | L3: 段5单价 | M3: 段6单价 | N3: 段7单价 | O3: 段8单价 | P3: 段9单价 | Q3: 匹配键
A4: 次日达 | B4: 福建省 | C4: 福州市/厦门市/泉州市 | D4: 1 | E4: 20 | F4: 30 | G4: 255 | H4: 8.1 | I4: 8.1 | J4: 8.1 | K4: 8.1 | L4: 7.2 | M4: 6.3 | N4: 6.3 | O4: 6.3 | P4: 6.3 | Q4: 次日达|福州市/厦门市/泉州市
A5: 次日达 | C5: 宁德市/莆田市/漳州市 | D5: 1 | E5: 20 | F5: 30 | G5: 255 | H5: 8.1 | I5: 8.1 | J5: 8.1 | K5: 8.1 | L5: 7.2 | M5: 6.3 | N5: 6.3 | O5: 6.3 | P5: 6.3 | Q5: 次日达|宁德市/莆田市/漳州市
A6: 次日达 | C6: 龙岩市/三明市/南平市 | D6: 1 | E6: 20 | F6: 30 | G6: 255 | H6: 8.1 | I6: 8.1 | J6: 8.1 | K6: 8.1 | L6: 7.2 | M6: 6.3 | N6: 6.3 | O6: 6.3 | P6: 6.3 | Q6: 次日达|龙岩市/三明市/南平市
A7: 次日达 | B7: 西藏自治区 | C7: 拉萨市 | D7: 1 | E7: 20 | F7: 30 | G7: 542 | H7: 18 | I7: 18 | J7: 18 | K7: 18 | L7: 18 | M7: 18 | N7: 18 | O7: 18 | P7: 18 | Q7: 次日达|拉萨市
A8: 次日达 | C8: 日喀则市/山南市/林芝市/昌都市/那曲市/阿里地区 | D8: 1 | E8: 25 | F8: 30 | G8: 678 | H8: 22.5 | I8: 22.5 | J8: 22.5 | K8: 22.5 | L8: 22.5 | M8: 22.5 | N8: 22.5 | O8: 22.5 | P8: 22.5 | Q8: 次日达|日喀则市/山南市/林芝市/昌都市/那曲市/阿里地区
A9: 次日达 | B9: 贵州省 | C9: 贵阳市/遵义市/安顺市 | D9: 1 | E9: 20 | F9: 30 | G9: 307 | H9: 9.9 | I9: 9.9 | J9: 9.9 | K9: 9 | L9: 9 | M9: 8.1 | N9: 8.1 | O9: 8.1 | P9: 8.1 | Q9: 次日达|贵阳市/遵义市/安顺市
A10: 次日达 | C10: 黔南布依族苗族自治州/黔东南苗族侗族自治州/铜仁市/毕节市/六盘水市/黔西南布依族苗族自治州 | D10: 1 | E10: 20 | F10: 30 | G10: 307 | H10: 9.9 | I10: 9.9 | J10: 9.9 | K10: 9 | L10: 9 | M10: 8.1 | N10: 8.1 | O10: 8.1 | P10: 8.1 | Q10: 次日达|黔南布依族苗族自治州/黔东南苗族侗族自治州/铜仁市/毕节市/六盘水市/黔西南布依族苗族自治州
A11: 次日达 | B11: 广东省 | C11: 广州市/深圳市/珠海市/中山市/东莞市 | D11: 1 | E11: 20 | F11: 15 | G11: 171 | H11: 10.8 | I11: 10.8 | J11: 10.8 | K11: 9.9 | L11: 9 | M11: 8.1 | N11: 8.1 | O11: 8.1 | P11: 8.1 | Q11: 次日达|广州市/深圳市/珠海市/中山市/东莞市
A12: 次日达 | C12: 江门市/惠州市/佛山市/肇庆市 | D12: 1 | E12: 20 | F12: 15 | G12: 171 | H12: 10.8 | I12: 10.8 | J12: 10.8 | K12: 9.9 | L12: 9 | M12: 8.1 | N12: 8.1 | O12: 8.1 | P12: 8.1 | Q12: 次日达|江门市/惠州市/佛山市/肇庆市
A13: 次日达 | C13: 汕尾市/阳江市/揭阳市/茂名市/韶关市/梅州市/汕头市/湛江市/河源市/清远市/云浮市/潮州市 | D13: 1 | E13: 20 | F13: 15 | G13: 171 | H13: 10.8 | I13: 10.8 | J13: 10.8 | K13: 9.9 | L13: 9 | M13: 8.1 | N13: 8.1 | O13: 8.1 | P13: 8.1 | Q13: 次日达|汕尾市/阳江市/揭阳市/茂名市/韶关市/梅州市/汕头市/湛江市/河源市/清远市/云浮市/潮州市
A14: 次日达 | B14: 湖北省 | C14: 武汉市/鄂州市 | D14: 1 | E14: 20 | F14: 30 | G14: 255 | H14: 8.1 | I14: 8.1 | J14: 8.1 | K14: 8.1 | L14: 7.2 | M14: 6.3 | N14: 6.3 | O14: 6.3 | P14: 6.3 | Q14: 次日达|武汉市/鄂州市
A15: 次日达 | C15: 襄阳市/孝感市/黄石市/荆州市/宜昌市/神农架林区/十堰市/随州市/荆门市 | D15: 1 | E15: 20 | F15: 30 | G15: 255 | H15: 8.1 | I15: 8.1 | J15: 8.1 | K15: 8.1 | L15: 7.2 | M15: 6.3 | N15: 6.3 | O15: 6.3 | P15: 6.3 | Q15: 次日达|襄阳市/孝感市/黄石市/荆州市/宜昌市/神农架林区/十堰市/随州市/荆门市
A16: 次日达 | C16: 黄冈市/咸宁市/恩施土家族苗族自治州/潜江市/仙桃市/天门市 | D16: 1 | E16: 20 | F16: 30 | G16: 307 | H16: 9.9 | I16: 9.9 | J16: 9.9 | K16: 9.9 | L16: 9 | M16: 8.1 | N16: 8.1 | O16: 8.1 | P16: 8.1 | Q16: 次日达|黄冈市/咸宁市/恩施土家族苗族自治州/潜江市/仙桃市/天门市
A17: 次日达 | B17: 湖南省 | C17: 株洲市/长沙市/湘潭市 | D17: 1 | E17: 20 | F17: 30 | G17: 255 | H17: 8.1 | I17: 8.1 | J17: 8.1 | K17: 8.1 | L17: 7.2 | M17: 6.3 | N17: 6.3 | O17: 6.3 | P17: 6.3 | Q17: 次日达|株洲市/长沙市/湘潭市
A18: 次日达 | C18: 益阳市 | D18: 1 | E18: 20 | F18: 30 | G18: 255 | H18: 8.1 | I18: 8.1 | J18: 8.1 | K18: 8.1 | L18: 7.2 | M18: 6.3 | N18: 6.3 | O18: 6.3 | P18: 6.3 | Q18: 次日达|益阳市
A19: 次日达 | C19: 岳阳市/衡阳市/郴州市/常德市/娄底市/邵阳市/湘西土家族苗族自治州/张家界市/怀化市/永州市 | D19: 1 | E19: 20 | F19: 30 | G19: 307 | H19: 9.9 | I19: 9.9 | J19: 9.9 | K19: 9.9 | L19: 9 | M19: 8.1 | N19: 8.1 | O19: 8.1 | P19: 8.1 | Q19: 次日达|岳阳市/衡阳市/郴州市/常德市/娄底市/邵阳市/湘西土家族苗族自治州/张家界市/怀化市/永州市
A20: 次日达 | B20: 重庆 | C20: 重庆市 | D20: 1 | E20: 20 | F20: 30 | G20: 255 | H20: 8.1 | I20: 8.1 | J20: 8.1 | K20: 8.1 | L20: 7.2 | M20: 7.2 | N20: 7.2 | O20: 7.2 | P20: 7.2 | Q20: 次日达|重庆市
A21: 次日达 | B21: 四川省 | C21: 成都市/资阳市/眉山市 | D21: 1 | E21: 20 | F21: 30 | G21: 255 | H21: 8.1 | I21: 8.1 | J21: 8.1 | K21: 8.1 | L21: 7.2 | M21: 7.2 | N21: 7.2 | O21: 7.2 | P21: 7.2 | Q21: 次日达|成都市/资阳市/眉山市
A22: 次日达 | C22: 绵阳市 | D22: 1 | E22: 20 | F22: 30 | G22: 255 | H22: 8.1 | I22: 8.1 | J22: 8.1 | K22: 8.1 | L22: 7.2 | M22: 7.2 | N22: 7.2 | O22: 7.2 | P22: 7.2 | Q22: 次日达|绵阳市
A23: 次日达 | C23: 自贡市/南充市/达州市/遂宁市/广安市/巴中市/泸州市/宜宾市/内江市/乐山市/雅安市/德阳市/广元市 | D23: 1 | E23: 20 | F23: 30 | G23: 307 | H23: 9.9 | I23: 9.9 | J23: 9.9 | K23: 9.9 | L23: 9 | M23: 9 | N23: 9 | O23: 9 | P23: 9 | Q23: 次日达|自贡市/南充市/达州市/遂宁市/广安市/巴中市/泸州市/宜宾市/内江市/乐山市/雅安市/德阳市/广元市
A24: 次日达 | C24: 攀枝花市/凉山彝族自治州/甘孜藏族自治州/阿坝藏族羌族自治州 | D24: 1 | E24: 20 | F24: 30 | G24: 385 | H24: 12.6 | I24: 12.6 | J24: 12.6 | K24: 12.6 | L24: 11.7 | M24: 11.7 | N24: 11.7 | O24: 11.7 | P24: 11.7 | Q24: 次日达|攀枝花市/凉山彝族自治州/甘孜藏族自治州/阿坝藏族羌族自治州
A25: 次日达 | B25: 安徽省 | C25: 合肥市/芜湖市/马鞍山市 | D25: 1 | E25: 20 | F25: 30 | G25: 255 | H25: 8.1 | I25: 8.1 | J25: 8.1 | K25: 8.1 | L25: 7.2 | M25: 6.3 | N25: 6.3 | O25: 6.3 | P25: 6.3 | Q25: 次日达|合肥市/芜湖市/马鞍山市
A26: 次日达 | C26: 滁州市/蚌埠市/六安市 | D26: 1 | E26: 20 | F26: 30 | G26: 281 | H26: 9 | I26: 9 | J26: 9 | K26: 9 | L26: 8.1 | M26: 7.2 | N26: 7.2 | O26: 7.2 | P26: 7.2 | Q26: 次日达|滁州市/蚌埠市/六安市
A27: 次日达 | C27: 淮南市/安庆市/宿州市/亳州市/阜阳市/黄山市/淮北市/铜陵市/宣城市/池州市 | D27: 1 | E27: 20 | F27: 30 | G27: 307 | H27: 9.9 | I27: 9.9 | J27: 9.9 | K27: 9.9 | L27: 9 | M27: 8.1 | N27: 8.1 | O27: 8.1 | P27: 8.1 | Q27: 次日达|淮南市/安庆市/宿州市/亳州市/阜阳市/黄山市/淮北市/铜陵市/宣城市/池州市
A28: 次日达 | B28: 新疆维吾尔自治区 | C28: 乌鲁木齐市 | D28: 1 | E28: 20 | F28: 30 | G28: 542 | H28: 18 | I28: 18 | J28: 18 | K28: 18 | L28: 18 | M28: 18 | N28: 18 | O28: 18 | P28: 18 | Q28: 次日达|乌鲁木齐市
A29: 次日达 | C29: 塔城地区/白杨市/新星市/哈密市/昆玉市/和田地区/北屯市/阿勒泰地区/克孜勒苏柯尔克孜自治州/双河市/博尔塔拉蒙古自治州/克拉玛依市/胡杨河市/石河子市/五家渠市/昌吉回族自治州/吐鲁番市/巴音郭楞蒙古自治州/铁门关市/阿克苏地区/阿拉尔市/图木舒克市/喀什地区/伊犁哈萨克自治州/可克达拉市 | D29: 1 | E29: 25 | F29: 30 | G29: 678 | H29: 22.5 | I29: 22.5 | J29: 22.5 | K29: 22.5 | L29: 22.5 | M29: 22.5 | N29: 22.5 | O29: 22.5 | P29: 22.5 | Q29: 次日达|塔城地区/白杨市/新星市/哈密市/昆玉市/和田地区/北屯市/阿勒泰地区/克孜勒苏柯尔克孜自治州/双河市/博尔塔拉蒙古自治州/克拉玛依市/胡杨河市/石河子市/五家渠市/昌吉回族自治州/吐鲁番市/巴音郭楞蒙古自治州/铁门关市/阿克苏地区/阿拉尔市/图木舒克市/喀什地区/伊犁哈萨克自治州/可克达拉市
A30: 次日达 | B30: 江苏省 | C30: 南京市/无锡市/苏州市/常州市 | D30: 1 | E30: 20 | F30: 15 | G30: 133 | H30: 8.1 | I30: 8.1 | J30: 8.1 | K30: 7.2 | L30: 6.3 | M30: 6.3 | N30: 6.3 | O30: 6.3 | P30: 6.3 | Q30: 次日达|南京市/无锡市/苏州市/常州市
A31: 次日达 | C31: 镇江市/南通市/扬州市 | D31: 1 | E31: 20 | F31: 15 | G31: 133 | H31: 8.1 | I31: 8.1 | J31: 8.1 | K31: 7.2 | L31: 6.3 | M31: 6.3 | N31: 6.3 | O31: 6.3 | P31: 6.3 | Q31: 次日达|镇江市/南通市/扬州市
A32: 次日达 | C32: 盐城市/徐州市/淮安市/连云港市/泰州市/宿迁市 | D32: 1 | E32: 20 | F32: 15 | G32: 133 | H32: 8.1 | I32: 8.1 | J32: 8.1 | K32: 7.2 | L32: 6.3 | M32: 6.3 | N32: 6.3 | O32: 6.3 | P32: 6.3 | Q32: 次日达|盐城市/徐州市/淮安市/连云港市/泰州市/宿迁市
A33: 次日达 | B33: 天津 | C33: 天津市 | D33: 1 | E33: 20 | F33: 20 | G33: 157 | H33: 7.2 | I33: 7.2 | J33: 7.2 | K33: 7.2 | L33: 6.3 | M33: 6.3 | N33: 6.3 | O33: 6.3 | P33: 6.3 | Q33: 次日达|天津市
A34: 次日达 | B34: 吉林省 | C34: 长春市 | D34: 1 | E34: 20 | F34: 30 | G34: 333 | H34: 10.8 | I34: 10.8 | J34: 10.8 | K34: 9.9 | L34: 9.9 | M34: 9 | N34: 9 | O34: 9 | P34: 9 | Q34: 次日达|长春市
A35: 次日达 | C35: 吉林市 | D35: 1 | E35: 20 | F35: 30 | G35: 359 | H35: 11.7 | I35: 11.7 | J35: 11.7 | K35: 10.8 | L35: 10.8 | M35: 9.9 | N35: 9.9 | O35: 9.9 | P35: 9.9 | Q35: 次日达|吉林市
A36: 次日达 | C36: 延边朝鲜族自治州/四平市/通化市/白城市/辽源市/松原市/白山市 | D36: 1 | E36: 20 | F36: 30 | G36: 412 | H36: 13.5 | I36: 13.5 | J36: 13.5 | K36: 12.6 | L36: 12.6 | M36: 11.7 | N36: 11.7 | O36: 11.7 | P36: 11.7 | Q36: 次日达|延边朝鲜族自治州/四平市/通化市/白城市/辽源市/松原市/白山市
A37: 次日达 | B37: 宁夏回族自治区 | C37: 银川市 | D37: 1 | E37: 20 | F37: 30 | G37: 490 | H37: 16.2 | I37: 16.2 | J37: 16.2 | K37: 14.4 | L37: 14.4 | M37: 14.4 | N37: 13.5 | O37: 13.5 | P37: 13.5 | Q37: 次日达|银川市
A38: 次日达 | C38: 石嘴山市/吴忠市/固原市/中卫市 | D38: 1 | E38: 20 | F38: 30 | G38: 542 | H38: 18 | I38: 18 | J38: 18 | K38: 16.2 | L38: 16.2 | M38: 16.2 | N38: 15.3 | O38: 15.3 | P38: 15.3 | Q38: 次日达|石嘴山市/吴忠市/固原市/中卫市
A39: 次日达 | B39: 河北省 | C39: 石家庄市/廊坊市 | D39: 1 | E39: 20 | F39: 30 | G39: 229 | H39: 7.2 | I39: 7.2 | J39: 7.2 | K39: 7.2 | L39: 7.2 | M39: 6.3 | N39: 6.3 | O39: 6.3 | P39: 6.3 | Q39: 次日达|石家庄市/廊坊市
A40: 次日达 | C40: 邯郸市/保定市/雄安新区/唐山市/沧州市/秦皇岛市 | D40: 1 | E40: 20 | F40: 30 | G40: 255 | H40: 8.1 | I40: 8.1 | J40: 8.1 | K40: 8.1 | L40: 8.1 | M40: 7.2 | N40: 7.2 | O40: 7.2 | P40: 7.2 | Q40: 次日达|邯郸市/保定市/雄安新区/唐山市/沧州市/秦皇岛市
A41: 次日达 | C41: 张家口市/承德市/衡水市/邢台市 | D41: 1 | E41: 20 | F41: 30 | G41: 281 | H41: 9 | I41: 9 | J41: 9 | K41: 9 | L41: 9 | M41: 8.1 | N41: 8.1 | O41: 8.1 | P41: 8.1 | Q41: 次日达|张家口市/承德市/衡水市/邢台市
...

Sheet 运费计算
A1: 运费计算（跨越费率，实重/体积重取大）
A3: 一、输入与费率定位（自动）
A4: 物流产品 | B4: =报价汇总!B21 -> 特惠普运
A5: 目的地 | B5: =报价汇总!B22 -> 宁波
A6: 每票件数M | B6: =报价汇总!B23 -> 50
A7: 单台毛重(kg) | B7: =IF(报价汇总!B16="","",报价汇总!B16+包装计算!$B$41) -> 4.85696
A8: 单箱体积(㎝³) | B8: =包装计算!$B$17 -> 135432
A9: 每箱件数N | B9: =报价汇总!B17 -> 4
A10: 箱数(票内) | B10: =IF(OR(B6="",B9="",B9=0),"",B6/B9) -> 12.5
A11: 匹配键 | B11: =IF(OR(B4="",B5=""),"",B4&"|"&B5) -> 特惠普运|宁波
A12: 费率行号 | B12: =IF(B11="","",IFERROR(MATCH(B11,跨越费率!$Q$4:$Q$300,0),""))
A14: 二、计费重量（自动）
A15: 单票实重(kg) | B15: =IF(OR(B7="",B6=""),"",B7*B6) -> 242.848
A16: 单票体积重(kg) | B16: =IF(OR(B8="",B10=""),"",B8*B10/参数!$B$36) -> 282.15
A17: 计费重量(kg) | B17: =IF(AND(ISNUMBER(B15),ISNUMBER(B16)),MAX(B15,B16),"") -> 282.15
A18: 起重(kg) | B18: =IF(B12="","",INDEX(跨越费率!$F$4:$F$300,B12))
A19: 计费重量起重后 | B19: =IF(OR(B17="",B18=""),"",MAX(B17,B18))
A21: 三、运费（自动）
A22: 首重重量 | B22: =IF(B12="","",INDEX(跨越费率!$D$4:$D$300,B12))
A23: 首重价格 | B23: =IF(B12="","",INDEX(跨越费率!$E$4:$E$300,B12))
A24: 段位置idx | B24: =IF(OR(B19="",B4=""),"",IF(B4="次日达",MATCH(B19,$B$26:$J$26,1),MATCH(B19,$B$27:$J$27,1)))
A25: 段单价 | B25: =IF(OR(B12="",B24=""),"",INDEX(跨越费率!$H$4:$P$300,B12,B24))
A26: 次日达段下限 | B26: 1 | C26: 10 | D26: 30 | E26: 50 | F26: 100 | G26: 300 | H26: 500 | I26: 1000 | J26: 2000
A27: 特惠段下限 | B27: 1 | C27: 50 | D27: 100 | E27: 200 | F27: 300 | G27: 500 | H27: 1000 | I27: 2000 | J27: 0
A28: 最低收费 | B28: =IF(B12="","",INDEX(跨越费率!$G$4:$G$300,B12))
A29: 单票运费 | B29: =IF(OR(B23="",B19="",B25="",B28=""),"",MAX(B23+(B19-B22)*B25,B28))
A30: 声明价值(元/票) | B30: =报价汇总!B24 -> 0
A31: 保费(可选) | B31: =IF(参数!$B$39="是",IF(NOT(ISNUMBER(B30)),"",MAX(参数!$B$37*B30,参数!$B$38)),0) -> 0
A32: 单票运费合计 | B32: =IF(OR(B29="",B31=""),"",B29+B31)
A33: 单台运费(元/件) | B33: =IF(OR(B32="",B6="",B6=0),"",B32/B6)
A35: 运费口径：计费重量=MAX(实重,体积重)；体积重=箱体积(㎝³)/体积系数；运费=首重价格+(计费重量-首重重量)×段单价，最低不低于最低收费。
A36: 目的地需与所选物流产品匹配：次日达与特惠普运的目的地划分不同，选错时本表运费显示空白。
